Workbook

Sheet Scenario
A1: Transactions | H1: Balances | M1: Monthly NR | N1: =10/1200 -> 0.0083333333 | P1: 10 | Q1: =P1/100 -> 0.1 | R1: =Q1/360 -> 0.00027777778
A2: PD | B2: ED | C2: Transaction | D2: Component | E2: Amount | F2: Entry | H2: UPB | I2: AIR | M2: Daily NR | N2: =R1 -> 0.00027777778
A3: 44592 | B3: =A3 -> 44592 | C3: Purchase | D3: UPB | E3: 100000 | F3: New | H3: =E3 -> 100000 | I3: 0
A4: 44592 | B4: =A4 -> 44592 | C4: Purchase | D4: Interest | E4: 100 | F4: New | H4: =E3 -> 100000 | I4: =E4 -> 100
A5: 44593 | B5: 44593 | C5: accrual | D5: Interest | E5: =H5*$N$2 -> 27.777778 | F5: New | H5: =H4 -> 100000 | I5: =I4+E5 -> 127.77778
A6: 44594 | B6: 44594 | C6: accrual | D6: Interest | E6: =H6*$N$2 -> 27.777778 | F6: New | H6: =H5 -> 100000 | I6: =I5+E6 -> 155.55556
A7: 44595 | B7: 44595 | C7: Remit | E7: 80 | F7: New | H7: =H6 -> 100000 | I7: =I6 -> 155.55556
A8: 44595 | B8: 44595 | C8: Payment | D8: UPB | E8: 0 | F8: New | H8: =H7+E8 -> 100000 | I8: =I7 -> 155.55556
A9: 44595 | B9: 44595 | C9: Payment | D9: Interest | E9: =-E7 -> -80 | F9: New | H9: =H7+E8 -> 100000 | I9: =I8+E9 -> 75.555556
A10: 44595 | B10: 44595 | C10: accrual | D10: Interest | E10: =H10*$N$2 -> 27.777778 | F10: New | H10: =H9 -> 100000 | I10: =E10+I9 -> 103.33333
A11: 44596 | B11: 44596 | C11: accrual | D11: Interest | E11: =ROUND(H10*N2,4) -> 27.7778 | F11: New | H11: =H10 -> 100000 | I11: =I10+E11 -> 131.11113
A12: 44597 | B12: 44597 | C12: Remit | E12: 275 | F12: New | H12: =H11 -> 100000 | I12: =I11 -> 131.11113
A13: 44597 | B13: 44597 | C13: Payment | D13: UPB | E13: =-(E12-I12) -> -143.88887 | F13: New | H13: =H12+E13 -> 99856.111 | I13: =I12 -> 131.11113
A14: 44597 | B14: 44597 | C14: Payment | D14: Interest | E14: =-I12 -> -131.11113 | F14: New | H14: =H13 -> 99856.111 | I14: =I13+E14 -> 0
A15: 44597 | B15: 44597 | C15: accrual | D15: Interest | E15: =H15*$N$2 -> 27.737809 | F15: New | H15: =H14 -> 99856.111 | I15: =E15 -> 27.737809
A16: 44598 | B16: 44598 | C16: Remit | E16: 350 | F16: New | H16: =H15 -> 99856.111 | I16: =I15 -> 27.737809
A17: 44598 | B17: 44598 | C17: Payment | D17: UPB | E17: =-(E16-I16) -> -322.26219 | F17: New | H17: =H16+E17 -> 99533.849 | I17: =I16 -> 27.737809
A18: 44598 | B18: 44598 | C18: Payment | D18: Interest | E18: =-I16 -> -27.737809 | F18: New | H18: =H17 -> 99533.849 | I18: =E18+I17 -> 0
A19: 44598 | B19: 44598 | C19: accrual | D19: Interest | E19: =H19*$N$2 -> 27.648291 | F19: New | H19: =H18 -> 99533.849 | I19: =E19 -> 27.648291
A20: 44599 | B20: 44599 | C20: accrual | D20: Interest | E20: =ROUND(H19*N2,4) -> 27.6483 | F20: New | H20: =H19 -> 99533.849 | I20: =I19+E20 -> 55.296591
A21: 44600 | B21: 44600 | C21: accrual | D21: Interest | E21: =E20 -> 27.6483 | F21: New | H21: =H20 -> 99533.849 | I21: =I20+E21 -> 82.944891
A22: 44601 | B22: 44595 | C22: accrual | D22: Interest | E22: =-E10 -> -27.777778 | F22: Reversal
A23: 44601 | B23: 44595 | C23: Remit | E23: =-E7 -> -80 | F23: Reversal
A24: 44601 | B24: 44595 | C24: Remit Reversal | E24: 30 | F24: New
A25: 44601 | B25: 44595 | C25: Payment | D25: UPB | E25: =-E8 -> 0 | F25: Reversal
A26: 44601 | B26: 44595 | C26: Payment | D26: Interest | E26: =-E9 -> 80 | F26: Reversal
A27: 44601 | B27: 44596 | C27: accrual | D27: Interest | E27: =-E11 -> -27.7778 | F27: Reversal
A28: 44601 | B28: 44597 | C28: accrual | D28: Interest | E28: =-E15 -> -27.737809 | F28: Reversal
A29: =A28 -> 44601 | B29: 44597 | C29: Remit | E29: =-E12 -> -275 | F29: Reversal
A30: =A29 -> 44601 | B30: 44597 | C30: Payment | D30: UPB | E30: =-E13 -> 143.88887 | F30: Reversal
A31: =A30 -> 44601 | B31: 44597 | C31: Payment | D31: Interest | E31: =-E14 -> 131.11113 | F31: Reversal
A32: 44601 | B32: 44598 | C32: accrual | D32: Interest | E32: =-E19 -> -27.648291 | F32: Reversal
A33: 44601 | B33: 44598 | C33: Remit | E33: =-E16 -> -350 | F33: Reversal
A34: 44601 | B34: 44598 | C34: Payment | D34: UPB | E34: =-E17 -> 322.26219 | F34: Reversal
A35: 44601 | B35: 44598 | C35: Payment | D35: Interest | E35: =-E18 -> 27.737809 | F35: Reversal
A36: 44601 | B36: 44599 | C36: accrual | D36: Interest | E36: =-E20 -> -27.6483 | F36: Reversal
A37: 44601 | B37: 44600 | C37: accrual | D37: Interest | E37: =-E21 -> -27.6483 | F37: Reversal | H37: =H21+E25+E34+E30 -> 100000 | I37: =I21+E26+E27+E28+E32+E35+E36+E37+E31+E22 -> 155.55556
A38: 44601 | B38: 44595 | C38: Payment | D38: Interest | E38: -50 | F38: Rebook | H38: =H37 -> 100000 | I38: =I37+E38 -> 105.55556
A39: 44601 | B39: 44595 | C39: accrual | D39: Interest | E39: =E40 -> 27.777778 | F39: Rebook | H39: =H37 -> 100000 | I39: =I38+E39 -> 133.33333
A40: 44601 | B40: 44596 | C40: accrual | D40: Interest | E40: =H37*N2 -> 27.777778 | F40: Rebook | H40: =H39 -> 100000 | I40: =I39+E40 -> 161.11111
...

Sheet PMT
A1: PostingDate | B1: EffectiveDate | C1: InstrumentId | D1: AttributeId | E1: TRANSACTIONS_AMOUNT_REMIT

Sheet INT_ACC
A1: PostingDate | B1: EffectiveDate | C1: InstrumentId | D1: AttributeId | E1: ATTRIBUTE_INTEREST_RATE_CURRENT | F1: BALANCES_ENDINGBALANCE_UNPAID_PRINCIPAL_BALANCE | G1: BALANCES_ENDINGBALANCE_ACCRUED_INTEREST_RECEIVABLE

Sheet PMT_RP
A1: PostingDate | B1: EffectiveDate | C1: InstrumentId | D1: AttributeId | E1: TRANSACTIONS_AMOUNT_REMIT | F1: BALANCES_ENDINGBALANCE_Unpaid_Principal_Balance | G1: BALANCES_ENDINGBALANCE_Accrued_Interest_Receivable

Sheet EXPECTED
A1: DAY1
A3: INTACC
A4: PostingDate | B4: EffectiveDate | C4: InstrumentId | D4: AttributeId | E4: ATTRIBUTES.INTEREST_RATE.CURRENT | F4: BALANCES.BEGINNINGBALANCE.Unpaid_Principal_Balance | G4: BALANCES.BEGINNINGBALANCE.Accrued_Interest_Receivable
A5: 44592 | B5: 44592 | C5: IDHJ-EGNY | D5: 1 | E5: 10 | F5: 100000 | G5: 100
A8: DAY2
A10: INTACC
A11: PostingDate | B11: EffectiveDate | C11: InstrumentId | D11: AttributeId | E11: ATTRIBUTES.INTEREST_RATE.CURRENT | F11: BALANCES.BEGINNINGBALANCE.Unpaid_Principal_Balance | G11: BALANCES.BEGINNINGBALANCE.Accrued_Interest_Receivable | J11: PostingDate | K11: TransactionDate | L11: InstrumentId | M11: Transactiontype | N11: Amount | O11: AttributeId
A12: 44593 | B12: 44593 | C12: IDHJ-EGNY | D12: 1 | E12: 10 | F12: 100000 | G12: 100 | J12: 44593 | K12: 44593 | L12: IDHJ-EGNY | M12: Servicing_Interest_Accrual | N12: 27.7778 | O12: 1
A15: DAY3
A17: INTACC
A18: PostingDate | B18: EffectiveDate | C18: InstrumentId | D18: AttributeId | E18: ATTRIBUTES.INTEREST_RATE.CURRENT | F18: BALANCES.BEGINNINGBALANCE.Unpaid_Principal_Balance | G18: BALANCES.BEGINNINGBALANCE.Accrued_Interest_Receivable | J18: PostingDate | K18: TransactionDate | L18: InstrumentId | M18: Transactiontype | N18: Amount | O18: AttributeId
A19: 44594 | B19: 44594 | C19: IDHJ-EGNY | D19: 1 | E19: 10 | F19: 100000 | G19: 127.7778 | J19: 44594 | K19: 44594 | L19: IDHJ-EGNY | M19: Servicing_Interest_Accrual | N19: 27.7778 | O19: 1
A22: DAY4
A24: INTACC
A25: PostingDate | B25: EffectiveDate | C25: InstrumentId | D25: AttributeId | E25: ATTRIBUTES.INTEREST_RATE.CURRENT | F25: BALANCES.BEGINNINGBALANCE.Unpaid_Principal_Balance | G25: BALANCES.BEGINNINGBALANCE.Accrued_Interest_Receivable | J25: PostingDate | K25: TransactionDate | L25: InstrumentId | M25: Transactiontype | N25: Amount | O25: AttributeId
A26: 44595 | B26: 44595 | C26: IDHJ-EGNY | D26: 1 | E26: 10 | F26: 100000 | G26: 155.5556 | J26: 44595 | K26: 44595 | L26: IDHJ-EGNY | M26: Servicing_Interest_Accrual | N26: 27.7778 | O26: 1
J27: 44595 | K27: 44595 | L27: IDHJ-EGNY | M27: Payment_Interest | N27: -80 | O27: 1
A28: PMT
A29: PostingDate | B29: EffectiveDate | C29: InstrumentId | D29: AttributeId | E29: TRANSACTIONS.AMOUNT.REMIT
A30: 44595 | B30: 44595 | C30: IDHJ-EGNY | D30: 1 | E30: 80
A33: DAY5
A35: INTACC
A36: PostingDate | B36: EffectiveDate | C36: InstrumentId | D36: AttributeId | E36: ATTRIBUTES.INTEREST_RATE.CURRENT | F36: BALANCES.BEGINNINGBALANCE.Unpaid_Principal_Balance | G36: BALANCES.BEGINNINGBALANCE.Accrued_Interest_Receivable | J36: PostingDate | K36: TransactionDate | L36: InstrumentId | M36: Transactiontype | N36: Amount | O36: AttributeId
A37: 44596 | B37: 44596 | C37: IDHJ-EGNY | D37: 1 | E37: 10 | F37: 100000 | G37: 103.3334 | J37: 44596 | K37: 44596 | L37: IDHJ-EGNY | M37: Servicing_Interest_Accrual | N37: 27.7778 | O37: 1
A40: DAY5
A42: INTACC
A43: PostingDate | B43: EffectiveDate | C43: InstrumentId | D43: AttributeId | E43: ATTRIBUTES.INTEREST_RATE.CURRENT | F43: BALANCES.BEGINNINGBALANCE.Unpaid_Principal_Balance | G43: BALANCES.BEGINNINGBALANCE.Accrued_Interest_Receivable | J43: PostingDate | K43: TransactionDate | L43: InstrumentId | M43: Transactiontype | N43: Amount | O43: AttributeId
A44: 44597 | B44: 44597 | C44: IDHJ-EGNY | D44: 1 | E44: 10 | F44: 100000 | G44: 131.1112 | J44: 44597 | K44: 44597 | L44: IDHJ-EGNY | M44: Servicing_Interest_Accrual | N44: 27.7378 | O44: 1
J45: 44597 | K45: 44597 | L45: IDHJ-EGNY | M45: Payment_Interest | N45: -131.1112 | O45: 1
A46: PMT | J46: 44597 | K46: 44597 | L46: IDHJ-EGNY | M46: Payment_UPB | N46: -143.8888 | O46: 1
A47: PostingDate | B47: EffectiveDate | C47: InstrumentId | D47: AttributeId | E47: TRANSACTIONS.AMOUNT.REMIT
A48: 44597 | B48: 44597 | C48: IDHJ-EGNY | D48: 1 | E48: 275
A51: DAY6
A53: INTACC
A54: PostingDate | B54: EffectiveDate | C54: InstrumentId | D54: AttributeId | E54: ATTRIBUTES.INTEREST_RATE.CURRENT | F54: BALANCES.BEGINNINGBALANCE.Unpaid_Principal_Balance | G54: BALANCES.BEGINNINGBALANCE.Accrued_Interest_Receivable | J54: PostingDate | K54: TransactionDate | L54: InstrumentId | M54: Transactiontype | N54: Amount | O54: AttributeId
A55: 44598 | B55: 44598 | C55: IDHJ-EGNY | D55: 1 | E55: 10 | F55: 99856.111 | G55: 27.7378 | J55: 44598 | K55: 44598 | L55: IDHJ-EGNY | M55: Servicing_Interest_Accrual | N55: 27.6483 | O55: 1
J56: 44598 | K56: 44598 | L56: IDHJ-EGNY | M56: Payment_UPB | N56: -322.2622 | O56: 1
A57: PMT | J57: 44598 | K57: 44598 | L57: IDHJ-EGNY | M57: Payment_Interest | N57: -27.7378 | O57: 1
A58: PostingDate | B58: EffectiveDate | C58: InstrumentId | D58: AttributeId | E58: TRANSACTIONS.AMOUNT.REMIT
A59: 44598 | B59: 44598 | C59: IDHJ-EGNY | D59: 1 | E59: 350
...

Sheet CALCULATION
A1: PAYMENT CALC
A2: Interest Rate | B2: =INT_ACC!E2/100 -> 0
A3: InstrumentId | B3: =INT_ACC!C2 -> 0
A4: PostingDate | B4: =IF(INT_ACC!A2="","",INT_ACC!A2)
A5: ReplayDate | B5: =IF(OR(MIN(PMT!$B$2:$B$13)=B4,MIN(PMT!$B$2:$B$13)=0),"",MIN(PMT!$B$2:$B$13))
A6: Row Posting
A8: S.No | B8: Effective Date | C8: Beg UPB | D8: Beg AIR | E8: Days | F8: Final Remit | G8: Interest Paid | H8: Principal Paid | I8: End UPB | J8: Accrual | K8: End AIR | L8: Helper Column
A9: 1 | B9: =IFERROR(IF(AND(A9=$B$6,B8<>$B$4),$B$4,IF(MATCH(PMT!B2,PMT!B$2:'PMT'!B$100,0)=ROW(PMT!B2)-ROW(PMT!B$2)+1,PMT!B2,"")),"") | C9: =IFERROR(IF(B9="","",IF(B5="",VLOOKUP(B9,INT_ACC!#REF!,5,FALSE),VLOOKUP(B9,PMT_RP!$B$2:$G$3,5,FALSE))),"") | D9: =IFERROR(IF(B9="","",IF(B5="",VLOOKUP(B9,INT_ACC!#REF!,6,FALSE),VLOOKUP(B9,PMT_RP!$B$2:$G$3,6,FALSE))),"") | E9: =IF(B9="","",IF(B10="",0,(B10-B9)-1)) | F9: =IF(B9="","",IF($B$5="",SUMIF(PMT!$B$2:$E$13,CALCULATION!B9,PMT!$E$2:$E$13),SUMIF(PMT_RP!$B$2:$E$10,CALCULATION!B9,PMT_RP!$E$2:$E$10))) | G9: =IF(B9="","",IF(F9<D9,F9,D9)) | H9: =IF(B9="","",F9-G9) | I9: =IFERROR(IF(B9="","",C9-H9),0) | J9: =IFERROR(IF(B9="","",(I9*$B$2)/360),0) | K9: =IFERROR(IF(B9="","",D9-G9+J9),0) | L9: =IF(G9<>"",ROW(),0) -> 0
A10: 2 | B10: =IFERROR(IF(AND(A10=$B$6,B9<>$B$4),$B$4,IF(MATCH(PMT_RP!B3,PMT_RP!B$2:'PMT_RP'!B$97,0)=ROW(PMT_RP!B3)-ROW(PMT_RP!B$2)+1,PMT_RP!B3,"")),"") | C10: =IF(B10="","",I9) | D10: =IF(B10="","",K9+(J9*E9)) | E10: =IF(B10="","",IF(B11="",0,(B11-B10)-1)) | F10: =IF(B10="","",IF($B$5="",SUMIF(PMT!$B$2:$E$13,CALCULATION!B10,PMT!$E$2:$E$13),SUMIF(PMT_RP!$B$2:$E$10,CALCULATION!B10,PMT_RP!$E$2:$E$10))) | G10: =IF(B10="","",IF(F10<D10,F10,D10)) | H10: =IF(B10="","",F10-G10) | I10: =IFERROR(IF(B10="","",C10-H10),0) | J10: =IFERROR(IF(B10="","",(I10*$B$2)/360),0) | K10: =IFERROR(IF(B10="","",D10-G10+J10),0) | L10: =IF(G10<>"",ROW(),0) -> 0
A11: 3 | B11: =IFERROR(IF(AND(A11=$B$6,B10<>$B$4),$B$4,IF(MATCH(PMT_RP!B4,PMT_RP!B$2:'PMT_RP'!B$97,0)=ROW(PMT_RP!B4)-ROW(PMT_RP!B$2)+1,PMT_RP!B4,"")),"") | C11: =IF(B11="","",I10) | D11: =IF(B11="","",K10+(J10*E10)) | E11: =IF(B11="","",IF(B12="",0,(B12-B11)-1)) | F11: =IF(B11="","",IF($B$5="",SUMIF(PMT!$B$2:$E$13,CALCULATION!B11,PMT!$E$2:$E$13),SUMIF(PMT_RP!$B$2:$E$10,CALCULATION!B11,PMT_RP!$E$2:$E$10))) | G11: =IF(B11="","",IF(F11<D11,F11,D11)) | H11: =IF(B11="","",F11-G11) | I11: =IFERROR(IF(B11="","",C11-H11),0) | J11: =IFERROR(IF(B11="","",(I11*$B$2)/360),0) | K11: =IFERROR(IF(B11="","",D11-G11+J11),0) | L11: =IF(G11<>"",ROW(),0) -> 0
A12: 4 | B12: =IFERROR(IF(AND(A12=$B$6,B11<>$B$4),$B$4,IF(MATCH(PMT_RP!B5,PMT_RP!B$2:'PMT_RP'!B$97,0)=ROW(PMT_RP!B5)-ROW(PMT_RP!B$2)+1,PMT_RP!B5,"")),"") | C12: =IF(B12="","",I11) | D12: =IF(B12="","",K11+(J11*E11)) | E12: =IF(B12="","",IF(B13="",0,(B13-B12)-1)) | F12: =IF(B12="","",IF($B$5="",SUMIF(PMT!$B$2:$E$13,CALCULATION!B12,PMT!$E$2:$E$13),SUMIF(PMT_RP!$B$2:$E$10,CALCULATION!B12,PMT_RP!$E$2:$E$10))) | G12: =IF(B12="","",IF(F12<D12,F12,D12)) | H12: =IF(B12="","",F12-G12) | I12: =IFERROR(IF(B12="","",C12-H12),0) | J12: =IFERROR(IF(B12="","",(I12*$B$2)/360),0) | K12: =IFERROR(IF(B12="","",D12-G12+J12),0) | L12: =IF(G12<>"",ROW(),0) -> 0
A13: 5 | B13: =IFERROR(IF(AND(A13=$B$6,B12<>$B$4),$B$4,IF(MATCH(PMT_RP!B6,PMT_RP!B$2:'PMT_RP'!B$97,0)=ROW(PMT_RP!B6)-ROW(PMT_RP!B$2)+1,PMT_RP!B6,"")),"") | C13: =IF(B13="","",I12) | D13: =IF(B13="","",K12+(J12*E12)) | E13: =IF(B13="","",IF(B14="",0,(B14-B13)-1)) | F13: =IF(B13="","",IF($B$5="",SUMIF(PMT!$B$2:$E$13,CALCULATION!B13,PMT!$E$2:$E$13),SUMIF(PMT_RP!$B$2:$E$10,CALCULATION!B13,PMT_RP!$E$2:$E$10))) | G13: =IF(B13="","",IF(F13<D13,F13,D13)) | H13: =IF(B13="","",F13-G13) | I13: =IFERROR(IF(B13="","",C13-H13),0) | J13: =IFERROR(IF(B13="","",(I13*$B$2)/360),0) | K13: =IFERROR(IF(B13="","",D13-G13+J13),0) | L13: =IF(G13<>"",ROW(),0) -> 0
A14: 6 | B14: =IFERROR(IF(AND(A14=$B$6,B13<>$B$4),$B$4,IF(MATCH(PMT_RP!B7,PMT_RP!B$2:'PMT_RP'!B$97,0)=ROW(PMT_RP!B7)-ROW(PMT_RP!B$2)+1,PMT_RP!B7,"")),"") | C14: =IF(B14="","",I13) | D14: =IF(B14="","",K13+(J13*E13)) | E14: =IF(B14="","",IF(B15="",0,(B15-B14)-1)) | F14: =IF(B14="","",IF($B$5="",SUMIF(PMT!$B$2:$E$13,CALCULATION!B14,PMT!$E$2:$E$13),SUMIF(PMT_RP!$B$2:$E$10,CALCULATION!B14,PMT_RP!$E$2:$E$10))) | G14: =IF(B14="","",IF(F14<D14,F14,D14)) | H14: =IF(B14="","",F14-G14) | I14: =IFERROR(IF(B14="","",C14-H14),0) | J14: =IFERROR(IF(B14="","",(I14*$B$2)/360),0) | K14: =IFERROR(IF(B14="","",D14-G14+J14),0) | L14: =IF(G14<>"",ROW(),0) -> 0
A15: 7 | B15: =IFERROR(IF(AND(A15=$B$6,B14<>$B$4),$B$4,IF(MATCH(PMT_RP!B8,PMT_RP!B$2:'PMT_RP'!B$97,0)=ROW(PMT_RP!B8)-ROW(PMT_RP!B$2)+1,PMT_RP!B8,"")),"") | C15: =IF(B15="","",I14) | D15: =IF(B15="","",K14+(J14*E14)) | E15: =IF(B15="","",IF(B16="",0,(B16-B15)-1)) | F15: =IF(B15="","",IF($B$5="",SUMIF(PMT!$B$2:$E$13,CALCULATION!B15,PMT!$E$2:$E$13),SUMIF(PMT_RP!$B$2:$E$10,CALCULATION!B15,PMT_RP!$E$2:$E$10))) | G15: =IF(B15="","",IF(F15<D15,F15,D15)) | H15: =IF(B15="","",F15-G15) | I15: =IFERROR(IF(B15="","",C15-H15),0) | J15: =IFERROR(IF(B15="","",(I15*$B$2)/360),0) | K15: =IFERROR(IF(B15="","",D15-G15+J15),0) | L15: =IF(G15<>"",ROW(),0) -> 0
A16: 8 | B16: =IFERROR(IF(AND(A16=$B$6,B15<>$B$4),$B$4,IF(MATCH(PMT_RP!B9,PMT_RP!B$2:'PMT_RP'!B$97,0)=ROW(PMT_RP!B9)-ROW(PMT_RP!B$2)+1,PMT_RP!B9,"")),"") | C16: =IF(B16="","",I15) | D16: =IF(B16="","",K15+(J15*E15)) | E16: =IF(B16="","",IF(B17="",0,(B17-B16)-1)) | F16: =IF(B16="","",IF($B$5="",SUMIF(PMT!$B$2:$E$13,CALCULATION!B16,PMT!$E$2:$E$13),SUMIF(PMT_RP!$B$2:$E$10,CALCULATION!B16,PMT_RP!$E$2:$E$10))) | G16: =IF(B16="","",IF(F16<D16,F16,D16)) | H16: =IF(B16="","",F16-G16) | I16: =IFERROR(IF(B16="","",C16-H16),0) | J16: =IFERROR(IF(B16="","",(I16*$B$2)/360),0) | K16: =IFERROR(IF(B16="","",D16-G16+J16),0) | L16: =IF(G16<>"",ROW(),0) -> 0 | M16: =IFERROR(IF(AND(A16=$B$6,B15<>$B$4),$B$4,IF(MATCH(PMT!B9,PMT!B$2:'PMT'!B$100,0)=ROW(PMT!B9)-ROW(PMT!B$2)+1,PMT!B9,"")),"") | N16: =IFERROR(SMALL($M$9:$M$12,A16),"")
A17: 9 | B17: =IFERROR(IF(AND(A17=$B$6,B16<>$B$4),$B$4,IF(MATCH(PMT_RP!B10,PMT_RP!B$2:'PMT_RP'!B$97,0)=ROW(PMT_RP!B10)-ROW(PMT_RP!B$2)+1,PMT_RP!B10,"")),"") | C17: =IF(B17="","",I16) | D17: =IF(B17="","",K16+(J16*E16)) | E17: =IF(B17="","",IF(B18="",0,(B18-B17)-1)) | F17: =IF(B17="","",IF($B$5="",SUMIF(PMT!$B$2:$E$13,CALCULATION!B17,PMT!$E$2:$E$13),SUMIF(PMT_RP!$B$2:$E$10,CALCULATION!B17,PMT_RP!$E$2:$E$10))) | G17: =IF(B17="","",IF(F17<D17,F17,D17)) | H17: =IF(B17="","",F17-G17) | I17: =IFERROR(IF(B17="","",C17-H17),0) | J17: =IFERROR(IF(B17="","",(I17*$B$2)/360),0) | K17: =IFERROR(IF(B17="","",D17-G17+J17),0) | L17: =IF(G17<>"",ROW(),0) -> 0 | M17: =IFERROR(IF(AND(A17=$B$6,B16<>$B$4),$B$4,IF(MATCH(PMT!B10,PMT!B$2:'PMT'!B$100,0)=ROW(PMT!B10)-ROW(PMT!B$2)+1,PMT!B10,"")),"") | N17: =IFERROR(SMALL($M$9:$M$12,A17),"")
A18: 10 | B18: =IFERROR(IF(AND(A18=$B$6,B17<>$B$4),$B$4,IF(MATCH(PMT_RP!B11,PMT_RP!B$2:'PMT_RP'!B$97,0)=ROW(PMT_RP!B11)-ROW(PMT_RP!B$2)+1,PMT_RP!B11,"")),"") | C18: =IF(B18="","",I17) | D18: =IF(B18="","",K17+(J17*E17)) | E18: =IF(B18="","",IF(B19="",0,(B19-B18)-1)) | F18: =IF(B18="","",IF($B$5="",SUMIF(PMT!$B$2:$E$13,CALCULATION!B18,PMT!$E$2:$E$13),SUMIF(PMT_RP!$B$2:$E$10,CALCULATION!B18,PMT_RP!$E$2:$E$10))) | G18: =IF(B18="","",IF(F18<D18,F18,D18)) | H18: =IF(B18="","",F18-G18) | I18: =IFERROR(IF(B18="","",C18-H18),0) | J18: =IFERROR(IF(B18="","",(I18*$B$2)/360),0) | K18: =IFERROR(IF(B18="","",D18-G18+J18),0) | L18: =IF(G18<>"",ROW(),0) -> 0 | M18: =IFERROR(IF(AND(A18=$B$6,B17<>$B$4),$B$4,IF(MATCH(PMT!B11,PMT!B$2:'PMT'!B$100,0)=ROW(PMT!B11)-ROW(PMT!B$2)+1,PMT!B11,"")),"") | N18: =IFERROR(SMALL($M$9:$M$12,A18),"")
A19: 11 | B19: =IFERROR(IF(AND(A19=$B$6,B18<>$B$4),$B$4,IF(MATCH(PMT_RP!B12,PMT_RP!B$2:'PMT_RP'!B$97,0)=ROW(PMT_RP!B12)-ROW(PMT_RP!B$2)+1,PMT_RP!B12,"")),"") | C19: =IF(B19="","",I18) | D19: =IF(B19="","",K18+(J18*E18)) | E19: =IF(B19="","",IF(B20="",0,(B20-B19)-1)) | F19: =IF(B19="","",IF($B$5="",SUMIF(PMT!$B$2:$E$13,CALCULATION!B19,PMT!$E$2:$E$13),SUMIF(PMT_RP!$B$2:$E$10,CALCULATION!B19,PMT_RP!$E$2:$E$10))) | G19: =IF(B19="","",IF(F19<D19,F19,D19)) | H19: =IF(B19="","",F19-G19) | I19: =IFERROR(IF(B19="","",C19-H19),0) | J19: =IFERROR(IF(B19="","",(I19*$B$2)/360),0) | K19: =IFERROR(IF(B19="","",D19-G19+J19),0) | L19: =IF(G19<>"",ROW(),0) -> 0 | M19: =IFERROR(IF(AND(A19=$B$6,B18<>$B$4),$B$4,IF(MATCH(PMT!B12,PMT!B$2:'PMT'!B$100,0)=ROW(PMT!B12)-ROW(PMT!B$2)+1,PMT!B12,"")),"") | N19: =IFERROR(SMALL($M$9:$M$12,A19),"")
A20: 12 | B20: =IFERROR(IF(AND(A20=$B$6,B19<>$B$4),$B$4,IF(MATCH(PMT_RP!B13,PMT_RP!B$2:'PMT_RP'!B$97,0)=ROW(PMT_RP!B13)-ROW(PMT_RP!B$2)+1,PMT_RP!B13,"")),"") | C20: =IF(B20="","",I19) | D20: =IF(B20="","",K19+(J19*E19)) | E20: =IF(B20="","",IF(B21="",0,(B21-B20)-1)) | F20: =IF(B20="","",IF($B$5="",SUMIF(PMT!$B$2:$E$13,CALCULATION!B20,PMT!$E$2:$E$13),SUMIF(PMT_RP!$B$2:$E$10,CALCULATION!B20,PMT_RP!$E$2:$E$10))) | G20: =IF(B20="","",IF(F20<D20,F20,D20)) | H20: =IF(B20="","",F20-G20) | I20: =IFERROR(IF(B20="","",C20-H20),0) | J20: =IFERROR(IF(B20="","",(I20*$B$2)/360),0) | K20: =IFERROR(IF(B20="","",D20-G20+J20),0) | L20: =IF(G20<>"",ROW(),0) -> 0 | M20: =IFERROR(IF(AND(A20=$B$6,B19<>$B$4),$B$4,IF(MATCH(PMT!B13,PMT!B$2:'PMT'!B$100,0)=ROW(PMT!B13)-ROW(PMT!B$2)+1,PMT!B13,"")),"") | N20: =IFERROR(SMALL($M$9:$M$12,A20),"")
G21: =IF( MAX(L9:L20) = 0, 0, INDEX(G9:G20, MATCH(MAX(L9:L20), L9:L20, 0)) ) -> 0 | H21: =IF( MAX(L9:L20) = 0, 0, INDEX(H9:H20, MATCH(MAX(L9:L20), L9:L20, 0)) ) -> 0 | I21: =IF( MAX(L9:L20) = 0, 0, INDEX(I9:I20, MATCH(MAX(L9:L20), L9:L20, 0)) ) -> 0 | K21: =IF( MAX(L9:L20) = 0, 0, INDEX(K9:K20, MATCH(MAX(L9:L20), L9:L20, 0)) ) -> 0
A24: ACCRUAL CALC
A25: S.No | B25: Effective Date | C25: Beg UPB | D25: Beg AIR | E25: Days | F25: Final Remit | G25: Interest Paid | H25: Principal Paid | I25: End UPB | J25: Accrual | K25: End AIR
A26: 1 | B26: =IF(INT_ACC!B2<>"","",INT_ACC!B2) -> 0 | C26: =INT_ACC!F2 -> 0 | D26: =INT_ACC!G2 -> 0 | E26: =IF(B26="","",IF(B27="",0,(B27-B26)-1)) -> 0 | F26: 0 | G26: =G21 -> 0 | H26: =H21 -> 0 | I26: =C26-H26 -> 0 | J26: =IF(B26="",0,(I26*$B$2)/360) -> 0 | K26: =D26+J26-G26 -> 0
A28: AIR Transactions
A29: Interest Accrual | B29: =J26 -> 0
A30: Interest Adjustment | B30: =IF(C9="",0,K21-K26) -> 0
A31: Interest Payment | B31: =G21 -> 0
A34: UPB Transactions
A35: Principal Payment | B35: =H21 -> 0
A36: Principal Adjustment | B36: =IF(C9="",0,I21-I26) -> 0
A38: Transactions
A39: PostingDate | B39: TransactionDate | C39: InstrumentId | D39: Transactiontype | E39: Amount | F39: AttributeId
A40: =B4 | B40: =A40 | C40: =IF(A40="","",$B$3) | D40: =IF(A40="","","Servicing_Interest_Accrual") | E40: =IF(A40="","",ROUND(B29,4)) | F40: =IF(A40="","","1")
A41: =IF(ROUND(B30,4)=0,"",$B$4) | B41: =IF(A41="","",A41) | C41: =IF(A41="","",$B$3) | D41: =IF(A41="","","Interest_Adjustment") | E41: =IF(A41="","",ROUND(B30,4)) | F41: =IF(A41="","","1")
A42: =IF(ROUND(B31,4)=0,"",$B$4) | B42: =IF(A42="","",A42) | C42: =IF(A42="","",$B$3) | D42: =IF(A42="","","Payment_Interest") | E42: =IF(A42="","",ROUND(B31,4)*-1) | F42: =IF(A42="","","1")
A43: =IF(ROUND(B35,4)=0,"",$B$4) | B43: =IF(A43="","",A43) | C43: =IF(A43="","",$B$3) | D43: =IF(A43="","","Payment_UPB") | E43: =IF(A43="","",ROUND(B35,4)*-1) | F43: =IF(A43="","","1")
A44: =IF(ROUND(B36,4)=0,"",$B$4) | B44: =IF(A44="","",A44) | C44: =IF(A44="","",$B$3) | D44: =IF(A44="","","Principal_Adjustment") | E44: =IF(A44="","",ROUND(B36,4)) | F44: =IF(A44="","","1")

Sheet Sample Data
A1: Replay Scenario | J1: PostingDate | K1: TransactionDate | L1: InstrumentId | M1: Transactiontype | N1: Amount | O1: AttributeId
A2: PMT_RP
A3: 45697 | B3: 45691 | C3: IDHJ-EGNY | D3: 1 | E3: 50 | F3: 100000 | G3: 155.55556 | J3: 45697 | K3: 45697 | L3: IDHJ-EGNY | M3: Servicing_Interest_Accrual | N3: 27.6483 | O3: 1
A4: 45697 | B4: 45693 | C4: IDHJ-EGNY | D4: 1 | E4: 275 | F4: 100000 | G4: 131.11111 | J4: 45697 | K4: 45697 | L4: IDHJ-EGNY | M4: Interest_Adjustment | N4: 0.0333 | O4: 1
A5: 45697 | B5: 45694 | C5: IDHJ-EGNY | D5: 1 | E5: 350 | F5: 99856.111 | G5: 27.648291 | J5: 45697 | K5: 45697 | L5: IDHJ-EGNY | M5: Principal_Adjustment | N5: 30.0083 | O5: 1
A6: 45697 | B6: 45697 | C6: IDHJ-EGNY | D6: 1 | E6: 0 | F6: 99533.849 | G6: 82.944874
A9: INT_ACC
A10: 45697 | B10: 45697 | C10: IDHJ-EGNY | D10: 1 | E10: 10 | F10: 99533.849 | G10: 82.944874
A13: PMT
A14: 45697 | B14: 45691 | C14: IDHJ-EGNY | D14: 1 | E14: -30
A16: OUT OF ORDER
A17: PMT_RP
A18: 45697 | B18: 45691 | C18: IDHJ-EGNY | D18: 1 | E18: 50 | F18: 100000 | G18: 155.55556 | J18: 45697 | K18: 45697 | L18: IDHJ-EGNY | M18: Servicing_Interest_Accrual | N18: 27.7778 | O18: 1
A19: 45697 | B19: 45697 | C19: IDHJ-EGNY | D19: 1 | E19: 0 | F19: 100000 | G19: 322.22222 | J19: 45697 | K19: 45697 | L19: IDHJ-EGNY | M19: Interest_Adjustment | N19: -50 | O19: 1
A22: INT_ACC
A23: 45697 | B23: 45697 | C23: IDHJ-EGNY | D23: 1 | E23: 10 | F23: 100000 | G23: 322.22222
A26: PMT
A27: 45697 | B27: 45691 | C27: IDHJ-EGNY | D27: 1 | E27: 50
A30: IN ORDER
A33: INT_ACC
A34: 45697 | B34: 45697 | C34: IDHJ-EGNY | D34: 1 | E34: 10 | F34: 100000 | G34: 322.22222 | J34: 45697 | K34: 45697 | L34: IDHJ-EGNY | M34: Servicing_Interest_Accrual | N34: 27.7562 | O34: 1
J36: 45697 | K36: 45697 | L36: IDHJ-EGNY | M36: Payment_Interest | N36: -322.2222 | O36: 1
A37: PMT | J37: 45697 | K37: 45697 | L37: IDHJ-EGNY | M37: Payment_UPB | N37: -77.7778 | O37: 1
A38: 45697 | B38: 45697 | C38: IDHJ-EGNY | D38: 1 | E38: 400

Sheet Events
A1: INT_ACC
A3: Trigger Type
A4: ON MODEL EXECUTION
A6: Source Mapping
A7: Balances | B7: BEGINNINGBALANCE | C7: UPB,AIR
A8: Attribute | B8: NoteRate | C8: Current
A11: PMT
A13: Trigger Type | B13: Trigger Source
A14: ON TRANSACTION POST | B14: Remit
A17: Source Mapping
A18: Transactions | B18: Amount | C18: Remit
A20: PMT_RP
A21: Trigger Type | B21: Trigger Source
A22: ON REPLAY | B22: Remit
A24: Source Mapping
A25: Balances | B25: BEGINNINGBALANCE | C25: UPB,AIR
A26: Transactions | B26: Amount | C26: Remit

Sheet o_Transaction
A1: PostingDate | B1: TransactionDate | C1: InstrumentId | D1: Transactiontype | E1: Amount | F1: AttributeId
A2: =CALCULATION!A40 | B2: =CALCULATION!B40 | C2: =CALCULATION!C40 | D2: =CALCULATION!D40 | E2: =CALCULATION!E40 | F2: =CALCULATION!F40
A3: =CALCULATION!A41 | B3: =CALCULATION!B41 | C3: =CALCULATION!C41 | D3: =CALCULATION!D41 | E3: =CALCULATION!E41 | F3: =CALCULATION!F41
A4: =CALCULATION!A42 | B4: =CALCULATION!B42 | C4: =CALCULATION!C42 | D4: =CALCULATION!D42 | E4: =CALCULATION!E42 | F4: =CALCULATION!F42
A5: =CALCULATION!A43 | B5: =CALCULATION!B43 | C5: =CALCULATION!C43 | D5: =CALCULATION!D43 | E5: =CALCULATION!E43 | F5: =CALCULATION!F43
A6: =CALCULATION!A44 | B6: =CALCULATION!B44 | C6: =CALCULATION!C44 | D6: =CALCULATION!D44 | E6: =CALCULATION!E44 | F6: =CALCULATION!F44

Sheet Example_worsheet_check
Q1: 0.1
A5: Principal | H5: Interest | P5: Principal | W5: Interest
A6: PostingDate | B6: Metric | C6: BeginningBalance | D6: Remit | E6: Activity | F6: EndingBalance | H6: PostingDate | I6: Metric | J6: BeginningBalance | K6: Activity | L6: Interest Payment | M6: EndingBalance | P6: PostingDate | Q6: Metric | R6: BeginningBalance | S6: Remit | T6: Activity | U6: EndingBalance | W6: PostingDate | X6: Metric | Y6: BeginningBalance | Z6: Activity | AA6: Interest Payment | AB6: EndingBalance
A7: 44592 | B7: UPB | C7: 0 | E7: 100000 | F7: =E7 -> 100000 | H7: 44592 | I7: AIR | J7: 0 | K7: 100 | M7: 100 | P7: 44592 | Q7: UPB | R7: 0 | T7: 100000 | U7: =T7 -> 100000 | W7: 44592 | X7: AIR | Y7: 0 | Z7: 100 | AB7: 100
A8: 44593 | B8: UPB | C8: =F7 -> 100000 | E8: 0 | F8: =F7 -> 100000 | H8: 44593 | I8: AIR | J8: =M7 -> 100 | K8: =(F8*$Q$1)/360 -> 27.777778 | M8: =J8+K8 -> 127.77778 | P8: 44593 | Q8: UPB | R8: =U7 -> 100000 | T8: 0 | U8: =U7 -> 100000 | W8: 44593 | X8: AIR | Y8: =AB7 -> 100 | Z8: =(U8*$Q$1)/360 -> 27.777778 | AB8: =Y8+Z8 -> 127.77778
A9: 44594 | B9: UPB | C9: =F8 -> 100000 | E9: 0 | F9: =C9+E9 -> 100000 | H9: 44594 | I9: AIR | J9: =M8 -> 127.77778 | K9: =(F9*$Q$1)/360 -> 27.777778 | M9: =J9+K9 -> 155.55556 | P9: 44594 | Q9: UPB | R9: =U8 -> 100000 | T9: 0 | U9: =R9+T9 -> 100000 | W9: 44594 | X9: AIR | Y9: =AB8 -> 127.77778 | Z9: =(U9*$Q$1)/360 -> 27.777778 | AB9: =Y9+Z9 -> 155.55556
A10: 44595 | B10: UPB | C10: =F9 -> 100000 | E10: 0 | F10: =C10+E10 -> 100000 | H10: 44595 | I10: AIR | J10: =M9 -> 155.55556 | K10: =+(F10*$Q$1/360) -> 27.777778 | L10: 0 | M10: =J10+K10+L10 -> 183.33333 | P10: 44595 | Q10: UPB | R10: =U9 -> 100000 | S10: 0 | T10: 0 | U10: =R10+T10 -> 100000 | W10: 44595 | X10: AIR | Y10: =AB9 -> 155.55556 | Z10: =(U10*$Q$1/360) -> 27.777778 | AA10: =-S10 -> 0 | AB10: =Y10+Z10+AA10 -> 183.33333
A11: 44596 | B11: UPB | C11: =F10 -> 100000 | E11: 0 | F11: =C11+E11 -> 100000 | H11: 44596 | I11: AIR | J11: =M10 -> 183.33333 | K11: =(F11*$Q$1)/360 -> 27.777778 | M11: =J11+K11+L11 -> 211.11111 | P11: 44596 | Q11: UPB | R11: =U10 -> 100000 | T11: 0 | U11: =R11+T11 -> 100000 | W11: 44596 | X11: AIR | Y11: =AB10 -> 183.33333 | Z11: =(U11*$Q$1)/360 -> 27.777778 | AB11: =Y11+Z11+AA11 -> 211.11111
A12: 44597 | B12: UPB | C12: =F11 -> 100000 | E12: 0 | F12: =C12+E12 -> 100000 | H12: 44597 | I12: AIR | J12: =M11 -> 211.11111 | K12: =+(F12*$Q$1/360) -> 27.777778 | L12: 0 | M12: =J12+K12+L12 -> 238.88889 | P12: 44597 | Q12: UPB | R12: =U11 -> 100000 | S12: 0 | T12: 0 | U12: =R12+T12 -> 100000 | W12: 44597 | X12: AIR | Y12: =AB11 -> 211.11111 | Z12: =+(U12*$Q$1/360) -> 27.777778 | AA12: 0 | AB12: =Y12+Z12+AA12 -> 238.88889
A13: 44598 | B13: UPB | C13: =F12 -> 100000 | E13: 0 | F13: =C13+E13 -> 100000 | H13: 44598 | I13: AIR | J13: =M12 -> 238.88889 | K13: =(F13*$Q$1/360) -> 27.777778 | L13: 0 | M13: =J13+K13+L13 -> 266.66667 | P13: 44598 | Q13: UPB | R13: =U12 -> 100000 | S13: 0 | T13: 0 | U13: =R13+T13 -> 100000 | W13: 44598 | X13: AIR | Y13: =AB12 -> 238.88889 | Z13: =(U13*$Q$1/360) -> 27.777778 | AA13: 0 | AB13: =Y13+Z13+AA13 -> 266.66667
A14: 44599 | B14: UPB | C14: =F13 -> 100000 | E14: 0 | F14: =C14+E14 -> 100000 | H14: 44599 | I14: AIR | J14: =M13 -> 266.66667 | K14: =(F14*$Q$1)/360 -> 27.777778 | M14: =J14+K14+L14 -> 294.44444 | P14: 44599 | Q14: UPB | R14: =U13 -> 100000 | T14: 0 | U14: =R14+T14 -> 100000 | W14: 44599 | X14: AIR | Y14: =AB13 -> 266.66667 | Z14: =(U14*$Q$1)/360 -> 27.777778 | AB14: =Y14+Z14+AA14 -> 294.44444
A15: 44600 | B15: UPB | C15: =F14 -> 100000 | E15: 0 | F15: =C15+E15 -> 100000 | H15: 44600 | I15: AIR | J15: =M14 -> 294.44444 | K15: =(F15*$Q$1)/360 -> 27.777778 | M15: =J15+K15+L15 -> 322.22222 | P15: 44600 | Q15: UPB | R15: =U14 -> 100000 | T15: 0 | U15: =R15+T15 -> 100000 | W15: 44600 | X15: AIR | Y15: =AB14 -> 294.44444 | Z15: =(U15*$Q$1)/360 -> 27.777778 | AB15: =Y15+Z15+AA15 -> 322.22222
A16: 44601 | B16: UPB | C16: =F15 -> 100000 | E16: 0 | F16: =C16+E16 -> 100000 | H16: 44601 | I16: AIR | J16: =M15 -> 322.22222 | K16: 0 | M16: =J16+K16+L16 -> 322.22222 | P16: 44601 | Q16: UPB | R16: =U15 -> 100000 | S16: 400 | T16: =-(S16+AA16) -> -77.777778 | U16: =R16+T16 -> 99922.222 | W16: 44601 | X16: AIR | Y16: =AB15 -> 322.22222 | Z16: =(U16*$Q$1)/360 -> 27.756173 | AA16: =-AB15 -> -322.22222 | AB16: =Y16+Z16+AA16 -> 27.756173
AB17: =AB16-M16 -> -294.46605
AA18: =AB16-M16 -> -294.46605
Z19: =J16 -> 322.22222
Z20: =Z16 -> 27.756173
Z21: =SUM(Z19:Z20) -> 349.9784
