Workbook

Sheet xxJOB
A1: ExecutionDate

Sheet LD
A1: PostingDate | B1: EffectiveDate | C1: InstrumentId | D1: AttributeId | E1: ATTRIBUTE_BORROWER_CURRENT | F1: ATTRIBUTE_CONTRACT_RATE_CURRENT | G1: ATTRIBUTE_ORIGINATION_DATE_CURRENT | H1: ATTRIBUTE_MATURITY_DATE_CURRENT | I1: ATTRIBUTE_RISK_LEVEL_AT_ORIGINATION_CURRENT | J1: ATTRIBUTE_LATEST_RISK_LEVEL_CURRENT | K1: ATTRIBUTE_ORIGINAL_LOAN_AMOUNT_CURRENT | L1: ATTRIBUTE_CURRENT_LOAN_BALANCE_CURRENT | M1: ATTRIBUTE_COLLATERAL_VALUE_CURRENT | N1: ATTRIBUTE_DAYS_PAST_DUE_CURRENT | O1: BALANCES_ENDINGBALANCE_ECL

Sheet xxRL
A1: RiskLevel | B1: Name | C1: AnnualPD
A2: Risk Level 1 | B2: Low | C2: 0.005
A3: Risk Level 2 | B3: Medium | C3: 0.03
A4: Risk Level 3 | B4: High | C4: 0.1
A5: Risk Level 4 | B5: Default | C5: 1

Sheet xxCOL
A1: CollateralHaircut | B1: CollateralRecoveryFees
A2: 0.3 | B2: 0.05

Sheet Calculation
A1: EstimationDate | B1: =LD!A2 -> 0
A3: Loan Detail
A5: Loan ID | B5: Attributeid | C5: Borrower | D5: Contract Rate | E5: Origination Date | F5: Maturity Date | G5: Risk Level at Origination | H5: Latest Risk Level | I5: Original Loan Amount | J5: Current Loan Balance | K5: Collateral Value | L5: Days Past Due | M5: ECL Balance
A6: =LD!C2 -> 0 | B6: =LD!D2 -> 0 | C6: =LD!E2 -> 0 | D6: =LD!F2 -> 0 | E6: =LD!G2 -> 0 | F6: =LD!H2 -> 0 | G6: =LD!I2 -> 0 | H6: =LD!J2 -> 0 | ... M6: =LD!O2 -> 0
A8: Risk Level
A9: Level | B9: Name | C9: AnnualPD
A10: Risk Level 1 | B10: Low | C10: =VLOOKUP(B10,xxRL!$B$2:$C$5,2,FALSE) -> 0.005
A11: Risk Level 2 | B11: Medium | C11: =VLOOKUP(B11,xxRL!$B$2:$C$5,2,FALSE) -> 0.03
A12: Risk Level 3 | B12: High | C12: =VLOOKUP(B12,xxRL!$B$2:$C$5,2,FALSE) -> 0.1
A13: Risk Level 4 | B13: Default | C13: =VLOOKUP(B13,xxRL!$B$2:$C$5,2,FALSE) -> 1
A15: Collateral Recovery
A16: CollateralHaircut | B16: CollateralRecoveryFees
A17: =xxCOL!A2 -> 0.3 | B17: =xxCOL!B2 -> 0.05
A19: Transactions
A20: PostingDate | B20: TransactionDate | C20: InstrumentId | D20: Transactiontype | E20: Amount | F20: AttributeId
A21: =IF(A6=0,"",B1) | B21: =A21 | C21: =IF(A6=0,"",A6) | D21: =IF(A6=0,"","EXPECTED_CREDIT_LOSS") | E21: =IF(A6=0,"",B31) | F21: =IF(A6=0,"",B6)
A23: Expected Credit Loss Calculation ( All Stages)
A25: Stage | B25: Formula | C25: Explanation | E25: Stage 3 Calculation - cash-shortfall method (collateral only
A26: Total ECL Stage 1 | B26: =SUM(K40:K51) -> 0 | C26: Use 12-month PD only (assuming period 1 is 12 months; adjust if monthly) | E26: Shortfall | F26: =J6-IFERROR($K$6*(1-$A$17-$B$17),0) -> 0
A27: Total ECL Stage 2 | B27: =ROUND(SUM(K40:K102),4) -> 0 | C27: Sum discounted losses over all periods | E27: Years To Recovery | F27: =ROUND(IF((F6-B1)<0,0,F6-B1)/365,6) -> 0
A28: Total ECL Stage 3 | B28: =F29 -> 0 | C28: Cash-shortfall method (collateral only), discounted to reporting date using EIR | E28: Discount Factor | F28: =ROUND(1/(1+D6)^F27,6) -> 1
A29: Stage Wise ECL | B29: =IF(B1>F6,0,IF($D$35="Stage 1",B26,IF($D$35="Stage 2",B27,B28))) -> 0 | C29: Choose based on IFRS 9 Stage | E29: ECL Stage 3 (Discounted Shortfall) | F29: =F26*F28 -> 0
A30: Prior ECL | B30: =M6 -> 0 | C30: Prior Period ECL
A31: Final ECL | B31: =B29-B30 -> 0 | C31: Increase or Decrease on Re-estimation
A33: Calculate Risk Movement & Stage
A34: Risk Level Number at Origination | B34: Current Risk Level Number | C34: Risk Level Movement | D34: IFRS 9 Stage | E34: Annual PD
A35: =IF(G6="Low",1,IF(G6="Medium",2,IF(G6="High",3,4))) -> 4 | B35: =IF(H6="Low",1,IF(H6="Medium",2,IF(H6="High",3,4))) -> 4 | C35: =B35-A35 -> 0 | D35: =IF(AND(L6<31,C35<2),"Stage 1",IF(AND(L6<91,C35<3),"Stage 2","Stage 3")) -> Stage 1 | E35: =IFERROR(VLOOKUP(H6,$B$10:$C$13,2,FALSE),0) -> 0
A37: Create Time Buckets Table (Monthly Periods)
A39: Month Number | B39: Period End Date | C39: Years to Period | D39: Discount Factor | E39: Expected Collateral Recovery | F39: Exposure at Default (EAD) | G39: Cummulative PD | H39: Periodic Probability of Default (PD) | I39: Loss Given Default (LGD) | J39: Expected Credit Loss (ECL) | K39: Discounted Expected Loss
A40: 1 | B40: =IFERROR(EOMONTH($B$1, A40),0) -> 59 | C40: =ROUND(MAX(0, (B40 - $B$1)/365),5) -> 0.16164 | D40: =ROUND(1 / (1 + $D$6) ^ C40,6) -> 1 | E40: =IFERROR($K$6*(1-$A$17-$B$17),0) -> 0 | F40: =IF(B40 > $F$6, 0, $J$6) -> 0 | G40: =ROUND(1 - (1 - $E$35) ^ C40,10) -> 0 | H40: =IF(A40=1,G40,G40-G39) -> 0 | I40: =ROUND(IF(F40=0, 1, 1 - (E40) / F40),4) -> 1 | J40: =ROUND(F40 * H40 * I40,4) -> 0 | K40: =ROUND(J40 * D40,4) -> 0
A41: =A40+1 -> 2 | B41: =IFERROR(EOMONTH($B$1, A41),0) -> 91 | C41: =ROUND(MAX(0, (B41 - $B$1)/365),4) -> 0.2493 | D41: =ROUND(1 / (1 + $D$6) ^ C41,6) -> 1 | E41: =IFERROR($K$6*(1-$A$17-$B$17),0) -> 0 | F41: =IF(B41 > $F$6, 0, $J$6) -> 0 | G41: =ROUND(1 - (1 - $E$35) ^ C41,6) -> 0 | H41: =IF(A41=1,G41,G41-G40) -> 0 | I41: =ROUND(IF(F41=0, 1, 1 - (E41) / F41),4) -> 1 | J41: =ROUND(F41 * H41 * I41,4) -> 0 | K41: =ROUND(J41 * D41,4) -> 0
A42: =A41+1 -> 3 | B42: =IFERROR(EOMONTH($B$1, A42),0) -> 121 | C42: =ROUND(MAX(0, (B42 - $B$1)/365),4) -> 0.3315 | D42: =ROUND(1 / (1 + $D$6) ^ C42,6) -> 1 | E42: =IFERROR($K$6*(1-$A$17-$B$17),0) -> 0 | F42: =IF(B42 > $F$6, 0, $J$6) -> 0 | G42: =ROUND(1 - (1 - $E$35) ^ C42,6) -> 0 | H42: =IF(A42=1,G42,G42-G41) -> 0 | I42: =ROUND(IF(F42=0, 1, 1 - (E42) / F42),4) -> 1 | J42: =ROUND(F42 * H42 * I42,4) -> 0 | K42: =ROUND(J42 * D42,4) -> 0
A43: =A42+1 -> 4 | B43: =IFERROR(EOMONTH($B$1, A43),0) -> 152 | C43: =ROUND(MAX(0, (B43 - $B$1)/365),4) -> 0.4164 | D43: =ROUND(1 / (1 + $D$6) ^ C43,6) -> 1 | E43: =IFERROR($K$6*(1-$A$17-$B$17),0) -> 0 | F43: =IF(B43 > $F$6, 0, $J$6) -> 0 | G43: =ROUND(1 - (1 - $E$35) ^ C43,6) -> 0 | H43: =IF(A43=1,G43,G43-G42) -> 0 | I43: =ROUND(IF(F43=0, 1, 1 - (E43) / F43),4) -> 1 | J43: =ROUND(F43 * H43 * I43,4) -> 0 | K43: =ROUND(J43 * D43,4) -> 0
A44: =A43+1 -> 5 | B44: =IFERROR(EOMONTH($B$1, A44),0) -> 182 | C44: =ROUND(MAX(0, (B44 - $B$1)/365),4) -> 0.4986 | D44: =ROUND(1 / (1 + $D$6) ^ C44,6) -> 1 | E44: =IFERROR($K$6*(1-$A$17-$B$17),0) -> 0 | F44: =IF(B44 > $F$6, 0, $J$6) -> 0 | G44: =ROUND(1 - (1 - $E$35) ^ C44,6) -> 0 | H44: =IF(A44=1,G44,G44-G43) -> 0 | I44: =ROUND(IF(F44=0, 1, 1 - (E44) / F44),4) -> 1 | J44: =ROUND(F44 * H44 * I44,4) -> 0 | K44: =ROUND(J44 * D44,4) -> 0
A45: =A44+1 -> 6 | B45: =IFERROR(EOMONTH($B$1, A45),0) -> 213 | C45: =ROUND(MAX(0, (B45 - $B$1)/365),4) -> 0.5836 | D45: =ROUND(1 / (1 + $D$6) ^ C45,6) -> 1 | E45: =IFERROR($K$6*(1-$A$17-$B$17),0) -> 0 | F45: =IF(B45 > $F$6, 0, $J$6) -> 0 | G45: =ROUND(1 - (1 - $E$35) ^ C45,6) -> 0 | H45: =IF(A45=1,G45,G45-G44) -> 0 | I45: =ROUND(IF(F45=0, 1, 1 - (E45) / F45),4) -> 1 | J45: =ROUND(F45 * H45 * I45,4) -> 0 | K45: =ROUND(J45 * D45,4) -> 0
A46: =A45+1 -> 7 | B46: =IFERROR(EOMONTH($B$1, A46),0) -> 244 | C46: =ROUND(MAX(0, (B46 - $B$1)/365),4) -> 0.6685 | D46: =ROUND(1 / (1 + $D$6) ^ C46,6) -> 1 | E46: =IFERROR($K$6*(1-$A$17-$B$17),0) -> 0 | F46: =IF(B46 > $F$6, 0, $J$6) -> 0 | G46: =ROUND(1 - (1 - $E$35) ^ C46,6) -> 0 | H46: =IF(A46=1,G46,G46-G45) -> 0 | I46: =ROUND(IF(F46=0, 1, 1 - (E46) / F46),4) -> 1 | J46: =ROUND(F46 * H46 * I46,4) -> 0 | K46: =ROUND(J46 * D46,4) -> 0
A47: =A46+1 -> 8 | B47: =IFERROR(EOMONTH($B$1, A47),0) -> 274 | C47: =ROUND(MAX(0, (B47 - $B$1)/365),4) -> 0.7507 | D47: =ROUND(1 / (1 + $D$6) ^ C47,6) -> 1 | E47: =IFERROR($K$6*(1-$A$17-$B$17),0) -> 0 | F47: =IF(B47 > $F$6, 0, $J$6) -> 0 | G47: =ROUND(1 - (1 - $E$35) ^ C47,6) -> 0 | H47: =IF(A47=1,G47,G47-G46) -> 0 | I47: =ROUND(IF(F47=0, 1, 1 - (E47) / F47),4) -> 1 | J47: =ROUND(F47 * H47 * I47,4) -> 0 | K47: =ROUND(J47 * D47,4) -> 0
A48: =A47+1 -> 9 | B48: =IFERROR(EOMONTH($B$1, A48),0) -> 305 | C48: =ROUND(MAX(0, (B48 - $B$1)/365),4) -> 0.8356 | D48: =ROUND(1 / (1 + $D$6) ^ C48,6) -> 1 | E48: =IFERROR($K$6*(1-$A$17-$B$17),0) -> 0 | F48: =IF(B48 > $F$6, 0, $J$6) -> 0 | G48: =ROUND(1 - (1 - $E$35) ^ C48,6) -> 0 | H48: =IF(A48=1,G48,G48-G47) -> 0 | I48: =ROUND(IF(F48=0, 1, 1 - (E48) / F48),4) -> 1 | J48: =ROUND(F48 * H48 * I48,4) -> 0 | K48: =ROUND(J48 * D48,4) -> 0
A49: =A48+1 -> 10 | B49: =IFERROR(EOMONTH($B$1, A49),0) -> 335 | C49: =ROUND(MAX(0, (B49 - $B$1)/365),4) -> 0.9178 | D49: =ROUND(1 / (1 + $D$6) ^ C49,6) -> 1 | E49: =IFERROR($K$6*(1-$A$17-$B$17),0) -> 0 | F49: =IF(B49 > $F$6, 0, $J$6) -> 0 | G49: =ROUND(1 - (1 - $E$35) ^ C49,6) -> 0 | H49: =IF(A49=1,G49,G49-G48) -> 0 | I49: =ROUND(IF(F49=0, 1, 1 - (E49) / F49),4) -> 1 | J49: =ROUND(F49 * H49 * I49,4) -> 0 | K49: =ROUND(J49 * D49,4) -> 0
A50: =A49+1 -> 11 | B50: =IFERROR(EOMONTH($B$1, A50),0) -> 366 | C50: =ROUND(MAX(0, (B50 - $B$1)/365),4) -> 1.0027 | D50: =ROUND(1 / (1 + $D$6) ^ C50,6) -> 1 | E50: =IFERROR($K$6*(1-$A$17-$B$17),0) -> 0 | F50: =IF(B50 > $F$6, 0, $J$6) -> 0 | G50: =ROUND(1 - (1 - $E$35) ^ C50,6) -> 0 | H50: =IF(A50=1,G50,G50-G49) -> 0 | I50: =ROUND(IF(F50=0, 1, 1 - (E50) / F50),4) -> 1 | J50: =ROUND(F50 * H50 * I50,4) -> 0 | K50: =ROUND(J50 * D50,4) -> 0
...

Sheet o_Transaction
A1: PostingDate | B1: TransactionDate | C1: InstrumentId | D1: TransactionName | E1: Amount | F1: AttributeId
A2: =Calculation!A21 | B2: =Calculation!B21 | C2: =Calculation!C21 | D2: =Calculation!D21 | E2: =Calculation!E21 | F2: =Calculation!F21

Sheet EXPECTED
A1: Loan ID | B1: Borrower | C1: Contract Rate | D1: Origination Date | E1: Maturity Date | F1: Risk Level at Origination | G1: Latest Risk Level | H1: Original Loan Amount | I1: Current Loan Balance | J1: Collateral Value | K1: Days Past Due | L1: Days to Maturity | M1: Months to Maturity | N1: Years to Maturity | O1: Avg Discount Factor for Stage 2 | P1: Risk Level Number at Origination | Q1: Current Risk Level Number | R1: Risk Level Movement | S1: Expected Collateral Recovery | T1: IFRS 9 Stage | U1: Annual PD | V1: PD for Period | W1: Loss Given Default | X1: Expected Credit Loss (ECL)
A2: L001 | B2: Alpha Ltd. | C2: 0.045 | D2: 44197 | E2: 46023 | F2: Low | G2: Low | H2: 500000 | I2: 300000 | J2: 200000 | K2: 0 | L2: 93 | M2: 3 | N2: 0.25479452 | O2: 0.9944 | P2: 1 | Q2: 1 | R2: 0 | S2: 130000 | T2: Stage 1 | U2: 0.005 | V2: 0.001276353 | W2: 0.56666667 | X2: 216.98
A3: L002 | B3: Beta Corp | C3: 0.06 | D3: 44621 | E3: 46447 | F3: Medium | G3: Medium | H3: 750000 | I3: 750000 | J3: 300000 | K3: 25 | L3: 517 | M3: 17 | N3: 1.4164384 | O3: 0.9604 | P3: 2 | Q3: 2 | R3: 0 | S3: 195000 | T3: Stage 1 | U3: 0.03 | V3: 0.03 | W3: 0.74 | X3: 16650
A4: L003 | B4: Gamma Ltd | C4: 0.052 | D4: 43983 | E4: 45809 | F4: Low | G4: Medium | H4: 250000 | I4: 100000 | J4: 80000 | K4: 40 | L4: 0 | M4: 0 | N4: 0 | O4: 1 | P4: 1 | Q4: 2 | R4: 1 | S4: 52000 | T4: Stage 2 | U4: 0.03 | V4: 0.03 | W4: 0.48 | X4: 1440
A5: L004 | B5: Delta PLC | C5: 0.07 | D5: 43466 | E5: 45292 | F5: Medium | G5: High | H5: 2000000 | I5: 1000000 | J5: 400000 | K5: 65 | L5: 0 | M5: 0 | N5: 0 | O5: 1 | P5: 2 | Q5: 3 | R5: 1 | S5: 260000 | T5: Stage 2 | U5: 0.1 | V5: 0.1 | W5: 0.74 | X5: 74000
A6: L005 | B6: Epsilon Ltd | C6: 0.04 | D6: 45047 | E6: 46874 | F6: Low | G6: Low | H6: 150000 | I6: 135000 | J6: 70000 | K6: 0 | L6: 944 | M6: 31 | N6: 2.5863014 | O6: 0.9518 | P6: 1 | Q6: 1 | R6: 0 | S6: 45500 | T6: Stage 1 | U6: 0.005 | V6: 0.005 | W6: 0.66296296 | X6: 447.5
A7: L006 | B7: Zeta Corp | C7: 0.08 | D7: 44075 | E7: 45901 | F7: High | G7: Default | H7: 800000 | I7: 600000 | J7: 200000 | K7: 120 | L7: 0 | M7: 0 | N7: 0 | O7: 1 | P7: 3 | Q7: 4 | R7: 1 | S7: 130000 | T7: Stage 3 | U7: 1 | V7: 1 | W7: 0.78333333 | X7: 470000
A8: L007 | B8: Eta Ltd | C8: 0.055 | D8: 43191 | E8: 45017 | F8: Medium | G8: Default | H8: 400000 | I8: 50000 | J8: 30000 | K8: 95 | L8: 0 | M8: 0 | N8: 0 | O8: 1 | P8: 2 | Q8: 4 | R8: 2 | S8: 19500 | T8: Stage 3 | U8: 1 | V8: 1 | W8: 0.61 | X8: 30500
A13: ExtimationDate | B13: RiskLevel | C13: Name | D13: AnnualPD
A14: 45930 | B14: Risk Level 1 | C14: Low | D14: 0.005
A15: 45930 | B15: Risk Level 2 | C15: Medium | D15: 0.03
A16: 45930 | B16: Risk Level 3 | C16: High | D16: 0.1
A17: 45930 | B17: Risk Level 4 | C17: Default | D17: 1
A20: EstimationDate | B20: CollateralHaircut | C20: CollateralRecoveryFees
A21: 45930 | B21: 0.3 | C21: 0.05

Sheet Sheet1
A1: Label | B1: Value / Example | C1: Notes
A2: Loan ID | B2: L001 | C2: Unique loan identifier | F2: Loan ID | G2: L001
A3: Origination Date | B3: 44197 | C3: Format as Date | F3: Borrower | G3: Alpha Ltd.
A4: Maturity Date | B4: 46023 | C4: Format as Date | F4: Contract Rate | G4: 0.045
A5: Reporting Date | B5: 45930 | C5: Calculation “as of” date | F5: Origination Date | G5: 44197 | J5: Stage | K5: Formula | L5: Explanation
A6: Contract Rate (EIR) | B6: 0.045 | C6: Effective Interest Rate (8%) | F6: Maturity Date | G6: 46023 | J6: Total ECL Stage 1 | K6: =ROUND($B$7 * (1 - (1 - $B$14) ^ 1) * F20,4) -> 850.05 | L6: Use 12-month PD only (assuming period 1 is 12 months; adjust if monthly)
A7: Current Loan Balance | B7: 300000 | C7: Exposure at Reporting Date | F7: Risk Level at Origination | G7: Low | J7: Total ECL Stage 2 & 3 | K7: =ROUND(SUM(I20:I43),4) -> 425.5935 | L7: Sum discounted losses over all periods (2 years here)
A8: Collateral Value | B8: 200000 | C8: Market value of collateral | F8: Latest Risk Level | G8: Low | J8: Final ECL | K8: =IF(B18="Stage 1",K6, K7) -> 850.05 | L8: Choose based on IFRS 9 Stage
A9: Collateral Haircut | B9: 0.3 | C9: 30% haircut | F9: Original Loan Amount | G9: 500000
A10: Collateral Recovery Fees | B10: 0.05 | C10: 5% recovery cost | F10: Current Loan Balance | G10: 300000
A11: Days Past Due | B11: 0 | C11: Days loan is overdue | F11: Collateral Value | G11: 200000
A12: Risk Level at Origination | B12: Low | C12: Text (Low, Medium, High) | F12: Days Past Due | G12: 0
A13: Current Risk Level | B13: Low | C13: Text (Low, Medium, High)
A14: Annual PD (Current Risk) | B14: 0.005 | C14: Lookup PD based on current risk rating
A15: Risk Level Number (Origination) | B15: =IF(B12="Low",1,IF(B12="Medium",2,IF(B12="High",3,4))) -> 1 | C15: Numeric risk level at origination | D15: Calculate Risk Movement & Stage
A16: Risk Level Number (Current) | B16: =IF(B13="Low",1,IF(B13="Medium",2,IF(B13="High",3,4))) -> 1 | C16: Numeric risk level currently
A17: Risk Movement | B17: =B16 - B15 -> 0 | C17: Change in risk level number
A18: IFRS 9 Stage | B18: =IF(AND(B11<31,B17<2),"Stage 1",IF(AND(B11<91,B17<3),"Stage 2","Stage 3")) -> Stage 1 | C18: Stage based on days past due and risk movement | D18: Create Time Buckets Table (Monthly Periods)
A19: Month Number | B19: Period End Date | C19: Years to Maturity | D19: Calculate Exposure at Default (EAD) | E19: Calculate Periodic Probability of Default (PD) | F19: Calculate Loss Given Default (LGD) | G19: Calculate Discount Factor | H19: Expected Loss (EL) | I19: Discounted Expected Loss
A20: 1 | B20: =EOMONTH($B$5, A20) -> 45961 | C20: =ROUND(MAX(0, (B20 - $B$5)/365),4) -> 0.0849 | D20: =IF(B20 > $B$4, 0, $B$7) -> 300000 | E20: =ROUND(1 - (1 - $B$14) ^ C20,6) -> 0.000425 | F20: =ROUND(IF(D20=0, 1, 1 - (($B$8 * (1 - $B$9 - $B$10)) / D20)),4) -> 0.5667 | G20: =ROUND(1 / (1 + $B$6) ^ C20,6) -> 0.99627 | H20: =ROUND(D20 * E20 * F20,4) -> 72.2543 | I20: =ROUND(H20 * G20,4) -> 71.9848
A21: =A20+1 -> 2 | B21: =EOMONTH($B$5, A21) -> 45991 | C21: =ROUND(MAX(0, (B21 - $B$5)/365),4) -> 0.1671 | D21: =IF(B21 > $B$4, 0, $B$7) -> 300000 | E21: =ROUND(1 - (1 - $B$14) ^ C21,6) -> 0.000837 | F21: =ROUND(IF(D21=0, 1, 1 - (($B$8 * (1 - $B$9 - $B$10)) / D21)),4) -> 0.5667 | G21: =ROUND(1 / (1 + $B$6) ^ C21,6) -> 0.992672 | H21: =ROUND(D21 * E21 * F21,4) -> 142.2984 | I21: =ROUND(H21 * G21,4) -> 141.2556
A22: =A21+1 -> 3 | B22: =EOMONTH($B$5, A22) -> 46022 | C22: =ROUND(MAX(0, (B22 - $B$5)/365),4) -> 0.2521 | D22: =IF(B22 > $B$4, 0, $B$7) -> 300000 | E22: =ROUND(1 - (1 - $B$14) ^ C22,6) -> 0.001263 | F22: =ROUND(IF(D22=0, 1, 1 - (($B$8 * (1 - $B$9 - $B$10)) / D22)),4) -> 0.5667 | G22: =ROUND(1 / (1 + $B$6) ^ C22,6) -> 0.988965 | H22: =ROUND(D22 * E22 * F22,4) -> 214.7226 | I22: =ROUND(H22 * G22,4) -> 212.3531
A23: =A22+1 -> 4 | B23: =EOMONTH($B$5, A23) -> 46053 | C23: =ROUND(MAX(0, (B23 - $B$5)/365),4) -> 0.337 | D23: =IF(B23 > $B$4, 0, $B$7) -> 0 | E23: =ROUND(1 - (1 - $B$14) ^ C23,6) -> 0.001688 | F23: =ROUND(IF(D23=0, 1, 1 - (($B$8 * (1 - $B$9 - $B$10)) / D23)),4) -> 1 | G23: =ROUND(1 / (1 + $B$6) ^ C23,6) -> 0.985276 | H23: =ROUND(D23 * E23 * F23,4) -> 0 | I23: =ROUND(H23 * G23,4) -> 0
