Workbook

Sheet ECF
A1: PostingDate | B1: EffectiveDate | C1: InstrumentId | D1: Attributeid | E1: MeasurementType | F1: StartDate | G1: ExpectedCF

Sheet EOD
A1: PostingDate | B1: EffectiveDate | C1: Instrumentid | D1: AttributeId | E1: Attribute_OriginationDate_Current | F1: Attribute_LoanAmount_Current | G1: Attribute_Term_Current | H1: Attribute_NoteRate_Current | I1: Balances_EndingBalance_UPB | J1: Balances_EndingBalance_impairment

Sheet Calc_InterestAccrualSchedule
B2: Loan Detail | F2: Present Value Contractual CF | G2: Present Value Expected CF | H2: Impairment | K2: Prior Impairment | O2: ALL Transactions
B3: UPB | C3: =IF(C6=C7,EOD!F2,EOD!I2) -> 0 | F3: =SUM(J16:J65) -> 0 | G3: =SUM(K16:K65) -> 0 | H3: =SUM(L16:L65) -> 0 | K3: =EOD!J2 -> 0 | O3: IMPAIRMENT_GAIN | P3: =IF(H3>0,H3,0) -> 0
B4: Origination Amount | C4: =EOD!F2 -> 0 | O4: ORIGINATION_PRINCIPAL | P4: =IF(C6=C7,EOD!F2,0) -> 0
B5: Term | C5: =EOD!G2 -> 0 | F5: NPV CCF | G5: NPV ECF | H5: Impairment | K5: Net Impaiment | O5: INTEREST_ACCRUAL | P5: =IF(C6=C7,0,D16) -> 0
B6: Origination Date | C6: =EOD!E2 -> 0 | F6: =NPV(C9,E16:E65) -> #NUM! | G6: =NPV(C9,F16:F65) -> 0 | H6: =G6-F6 -> #NUM! | K6: =H3-K3 -> 0 | O6: IMPAIRMENT_LOSS | P6: =IF(K6<0,K6,0) -> 0
B7: PostingDate | C7: =EOD!A2 -> 0
B8: NoteRate | C8: =EOD!H2/100 -> 0 | F8: Difference
B9: Monthly Rate | C9: =C8/12 -> 0 | F9: =F6-F3 -> #NUM! | G9: =G6-G3 -> 0 | H9: =H6-H3 -> #NUM!
B10: PMT | C10: =PMT(C9,C5,-C4) -> #NUM!
B11: First Month | C11: =MONTH(C7-C6) -> 1
B12: InstrumentId | C12: =EOD!C2 -> 0
B13: AttributeID | C13: =EOD!D2 -> 0
A15: Month | B15: PostingDate | C15: OpeningBalance | D15: InterestAccrued | E15: ContractualCF | F15: ExpectedCF | G15: PrincipalPayment | H15: ClosingBalance | I15: DF | J15: PV_CCF | K15: PV_ECF | L15: Impairment | O15: Transactions
A16: =C11 -> 1 | B16: =C7 -> 0 | C16: =C3 -> 0 | D16: =IF(A16="","",C16*Calc_InterestAccrualSchedule!$C$9) -> 0 | E16: =IF(A16="","",IF(A16=$C$5,H15+D16,$C$10)) -> #NUM! | F16: =IFERROR(VLOOKUP(B16,ECF!$F$2:$G$12,2),"") | G16: =IFERROR(E16-D16,"") | H16: =IFERROR(C16+D16-E16,"") | I16: =IFERROR(ROUND(1/(1+Calc_InterestAccrualSchedule!$C$9)^A16,5),"") -> 1 | J16: =IFERROR(E16*I16,"") | K16: =IFERROR(F16*I16,"") | L16: =IFERROR(K16-J16,"") | O16: PostingDate | P16: TransactionDate | Q16: InstrumentId | R16: Transactiontype | S16: Amount | T16: AttributeId
A17: =IFERROR(IF(A16+1>$C$5,"",A16+1),"") | B17: =IF(A17="","",EOMONTH(B16,1)) | C17: =IF(A17<>"",H16,"") | D17: =IF(A17="","",C17*Calc_InterestAccrualSchedule!$C$9) | E17: =IF(A17="","",IF(A17=$C$5,H16+D17,$C$10)) | F17: =IFERROR(VLOOKUP(B17,ECF!$F$2:$G$12,2),"") | G17: =IFERROR(E17-D17,"") | H17: =IFERROR(C17+D17-E17,"") | I17: =IFERROR(ROUND(1/(1+Calc_InterestAccrualSchedule!$C$9)^A17,5),"") | J17: =IFERROR(E17*I17,"") | K17: =IFERROR(F17*I17,"") | L17: =IFERROR(K17-J17,"") | O17: =IF(C12=0,"",$C$7) | P17: =O17 | Q17: =IF(C12=0,"",$C$12) | R17: =IF(C12=0,"",O3) | S17: =IF(C12=0,"",ROUND(P3,4)) | T17: =IF(C12=0,"",$C$13)
A18: =IFERROR(IF(A17+1>$C$5,"",A17+1),"") | B18: =IF(A18="","",EOMONTH(B17,1)) | C18: =IF(A18<>"",H17,"") | D18: =IF(A18="","",C18*Calc_InterestAccrualSchedule!$C$9) | E18: =IF(A18="","",IF(A18=$C$5,H17+D18,$C$10)) | F18: =IFERROR(VLOOKUP(B18,ECF!$F$2:$G$12,2),"") | G18: =IFERROR(E18-D18,"") | H18: =IFERROR(C18+D18-E18,"") | I18: =IFERROR(ROUND(1/(1+Calc_InterestAccrualSchedule!$C$9)^A18,5),"") | J18: =IFERROR(E18*I18,"") | K18: =IFERROR(F18*I18,"") | L18: =IFERROR(K18-J18,"") | O18: =IF(C12=0,"",$C$7) | P18: =O18 | Q18: =IF(C12=0,"",$C$12) | R18: =IF(C12=0,"",O4) | S18: =IF(C12=0,"",ROUND(P4,4)) | T18: =IF(C12=0,"",$C$13)
A19: =IFERROR(IF(A18+1>$C$5,"",A18+1),"") | B19: =IF(A19="","",EOMONTH(B18,1)) | C19: =IF(A19<>"",H18,"") | D19: =IF(A19="","",C19*Calc_InterestAccrualSchedule!$C$9) | E19: =IF(A19="","",IF(A19=$C$5,H18+D19,$C$10)) | F19: =IFERROR(VLOOKUP(B19,ECF!$F$2:$G$12,2),"") | G19: =IFERROR(E19-D19,"") | H19: =IFERROR(C19+D19-E19,"") | I19: =IFERROR(ROUND(1/(1+Calc_InterestAccrualSchedule!$C$9)^A19,5),"") | J19: =IFERROR(E19*I19,"") | K19: =IFERROR(F19*I19,"") | L19: =IFERROR(K19-J19,"") | O19: =IF(C12=0,"",$C$7) | P19: =O19 | Q19: =IF(C12=0,"",$C$12) | R19: =IF(C12=0,"",O5) | S19: =IF(C12=0,"",ROUND(P5,4)) | T19: =IF(C12=0,"",$C$13)
A20: =IFERROR(IF(A19+1>$C$5,"",A19+1),"") | B20: =IF(A20="","",EOMONTH(B19,1)) | C20: =IF(A20<>"",H19,"") | D20: =IF(A20="","",C20*Calc_InterestAccrualSchedule!$C$9) | E20: =IF(A20="","",IF(A20=$C$5,H19+D20,$C$10)) | F20: =IFERROR(VLOOKUP(B20,ECF!$F$2:$G$12,2),"") | G20: =IFERROR(E20-D20,"") | H20: =IFERROR(C20+D20-E20,"") | I20: =IFERROR(ROUND(1/(1+Calc_InterestAccrualSchedule!$C$9)^A20,5),"") | J20: =IFERROR(E20*I20,"") | K20: =IFERROR(F20*I20,"") | L20: =IFERROR(K20-J20,"") | O20: =IF(C12=0,"",$C$7) | P20: =O20 | Q20: =IF(C12=0,"",$C$12) | R20: =IF(C12=0,"",O6) | S20: =IF(C12=0,"",ROUND(P6,4)) | T20: =IF(C12=0,"",$C$13)
A21: =IFERROR(IF(A20+1>$C$5,"",A20+1),"") | B21: =IF(A21="","",EOMONTH(B20,1)) | C21: =IF(A21<>"",H20,"") | D21: =IF(A21="","",C21*Calc_InterestAccrualSchedule!$C$9) | E21: =IF(A21="","",IF(A21=$C$5,H20+D21,$C$10)) | F21: =IFERROR(VLOOKUP(B21,ECF!$F$2:$G$12,2),"") | G21: =IFERROR(E21-D21,"") | H21: =IFERROR(C21+D21-E21,"") | I21: =IFERROR(ROUND(1/(1+Calc_InterestAccrualSchedule!$C$9)^A21,5),"") | J21: =IFERROR(E21*I21,"") | K21: =IFERROR(F21*I21,"") | L21: =IFERROR(K21-J21,"")
A22: =IFERROR(IF(A21+1>$C$5,"",A21+1),"") | B22: =IF(A22="","",EOMONTH(B21,1)) | C22: =IF(A22<>"",H21,"") | D22: =IF(A22="","",C22*Calc_InterestAccrualSchedule!$C$9) | E22: =IF(A22="","",IF(A22=$C$5,H21+D22,$C$10)) | F22: =IFERROR(VLOOKUP(B22,ECF!$F$2:$G$12,2),"") | G22: =IFERROR(E22-D22,"") | H22: =IFERROR(C22+D22-E22,"") | I22: =IFERROR(ROUND(1/(1+Calc_InterestAccrualSchedule!$C$9)^A22,5),"") | J22: =IFERROR(E22*I22,"") | K22: =IFERROR(F22*I22,"") | L22: =IFERROR(K22-J22,"")
A23: =IFERROR(IF(A22+1>$C$5,"",A22+1),"") | B23: =IF(A23="","",EOMONTH(B22,1)) | C23: =IF(A23<>"",H22,"") | D23: =IF(A23="","",C23*Calc_InterestAccrualSchedule!$C$9) | E23: =IF(A23="","",IF(A23=$C$5,H22+D23,$C$10)) | F23: =IFERROR(VLOOKUP(B23,ECF!$F$2:$G$12,2),"") | G23: =IFERROR(E23-D23,"") | H23: =IFERROR(C23+D23-E23,"") | I23: =IFERROR(ROUND(1/(1+Calc_InterestAccrualSchedule!$C$9)^A23,5),"") | J23: =IFERROR(E23*I23,"") | K23: =IFERROR(F23*I23,"") | L23: =IFERROR(K23-J23,"")
A24: =IFERROR(IF(A23+1>$C$5,"",A23+1),"") | B24: =IF(A24="","",EOMONTH(B23,1)) | C24: =IF(A24<>"",H23,"") | D24: =IF(A24="","",C24*Calc_InterestAccrualSchedule!$C$9) | E24: =IF(A24="","",IF(A24=$C$5,H23+D24,$C$10)) | F24: =IFERROR(VLOOKUP(B24,ECF!$F$2:$G$12,2),"") | G24: =IFERROR(E24-D24,"") | H24: =IFERROR(C24+D24-E24,"") | I24: =IFERROR(ROUND(1/(1+Calc_InterestAccrualSchedule!$C$9)^A24,5),"") | J24: =IFERROR(E24*I24,"") | K24: =IFERROR(F24*I24,"") | L24: =IFERROR(K24-J24,"")
A25: =IFERROR(IF(A24+1>$C$5,"",A24+1),"") | B25: =IF(A25="","",EOMONTH(B24,1)) | C25: =IF(A25<>"",H24,"") | D25: =IF(A25="","",C25*Calc_InterestAccrualSchedule!$C$9) | E25: =IF(A25="","",IF(A25=$C$5,H24+D25,$C$10)) | F25: =IFERROR(VLOOKUP(B25,ECF!$F$2:$G$12,2),"") | G25: =IFERROR(E25-D25,"") | H25: =IFERROR(C25+D25-E25,"") | I25: =IFERROR(ROUND(1/(1+Calc_InterestAccrualSchedule!$C$9)^A25,5),"") | J25: =IFERROR(E25*I25,"") | K25: =IFERROR(F25*I25,"") | L25: =IFERROR(K25-J25,"")
A26: =IFERROR(IF(A25+1>$C$5,"",A25+1),"") | B26: =IF(A26="","",EOMONTH(B25,1)) | C26: =IF(A26<>"",H25,"") | D26: =IF(A26="","",C26*Calc_InterestAccrualSchedule!$C$9) | E26: =IF(A26="","",IF(A26=$C$5,H25+D26,$C$10)) | F26: =IFERROR(VLOOKUP(B26,ECF!$F$2:$G$12,2),"") | G26: =IFERROR(E26-D26,"") | H26: =IFERROR(C26+D26-E26,"") | I26: =IFERROR(ROUND(1/(1+Calc_InterestAccrualSchedule!$C$9)^A26,5),"") | J26: =IFERROR(E26*I26,"") | K26: =IFERROR(F26*I26,"") | L26: =IFERROR(K26-J26,"")
A27: =IFERROR(IF(A26+1>$C$5,"",A26+1),"") | B27: =IF(A27="","",EOMONTH(B26,1)) | C27: =IF(A27<>"",H26,"") | D27: =IF(A27="","",C27*Calc_InterestAccrualSchedule!$C$9) | E27: =IF(A27="","",IF(A27=$C$5,H26+D27,$C$10)) | F27: =IFERROR(VLOOKUP(B27,ECF!$F$2:$G$12,2),"") | G27: =IFERROR(E27-D27,"") | H27: =IFERROR(C27+D27-E27,"") | I27: =IFERROR(ROUND(1/(1+Calc_InterestAccrualSchedule!$C$9)^A27,5),"") | J27: =IFERROR(E27*I27,"") | K27: =IFERROR(F27*I27,"") | L27: =IFERROR(K27-J27,"")
A28: =IFERROR(IF(A27+1>$C$5,"",A27+1),"") | B28: =IF(A28="","",EOMONTH(B27,1)) | C28: =IF(A28<>"",H27,"") | D28: =IF(A28="","",C28*Calc_InterestAccrualSchedule!$C$9) | E28: =IF(A28="","",IF(A28=$C$5,H27+D28,$C$10)) | F28: =IFERROR(VLOOKUP(B28,ECF!$F$2:$G$12,2),"") | G28: =IFERROR(E28-D28,"") | H28: =IFERROR(C28+D28-E28,"") | I28: =IFERROR(ROUND(1/(1+Calc_InterestAccrualSchedule!$C$9)^A28,5),"") | J28: =IFERROR(E28*I28,"") | K28: =IFERROR(F28*I28,"") | L28: =IFERROR(K28-J28,"")
A29: =IFERROR(IF(A28+1>$C$5,"",A28+1),"") | B29: =IF(A29="","",EOMONTH(B28,1)) | C29: =IF(A29<>"",H28,"") | D29: =IF(A29="","",C29*Calc_InterestAccrualSchedule!$C$9) | E29: =IF(A29="","",IF(A29=$C$5,H28+D29,$C$10)) | F29: =IFERROR(VLOOKUP(B29,ECF!$F$2:$G$12,2),"") | G29: =IFERROR(E29-D29,"") | H29: =IFERROR(C29+D29-E29,"") | I29: =IFERROR(ROUND(1/(1+Calc_InterestAccrualSchedule!$C$9)^A29,5),"") | J29: =IFERROR(E29*I29,"") | K29: =IFERROR(F29*I29,"") | L29: =IFERROR(K29-J29,"")
A30: =IFERROR(IF(A29+1>$C$5,"",A29+1),"") | B30: =IF(A30="","",EOMONTH(B29,1)) | C30: =IF(A30<>"",H29,"") | D30: =IF(A30="","",C30*Calc_InterestAccrualSchedule!$C$9) | E30: =IF(A30="","",IF(A30=$C$5,H29+D30,$C$10)) | F30: =IFERROR(VLOOKUP(B30,ECF!$F$2:$G$12,2),"") | G30: =IFERROR(E30-D30,"") | H30: =IFERROR(C30+D30-E30,"") | I30: =IFERROR(ROUND(1/(1+Calc_InterestAccrualSchedule!$C$9)^A30,5),"") | J30: =IFERROR(E30*I30,"") | K30: =IFERROR(F30*I30,"") | L30: =IFERROR(K30-J30,"")
A31: =IFERROR(IF(A30+1>$C$5,"",A30+1),"") | B31: =IF(A31="","",EOMONTH(B30,1)) | C31: =IF(A31<>"",H30,"") | D31: =IF(A31="","",C31*Calc_InterestAccrualSchedule!$C$9) | E31: =IF(A31="","",IF(A31=$C$5,H30+D31,$C$10)) | F31: =IFERROR(VLOOKUP(B31,ECF!$F$2:$G$12,2),"") | G31: =IFERROR(E31-D31,"") | H31: =IFERROR(C31+D31-E31,"") | I31: =IFERROR(ROUND(1/(1+Calc_InterestAccrualSchedule!$C$9)^A31,5),"") | J31: =IFERROR(E31*I31,"") | K31: =IFERROR(F31*I31,"") | L31: =IFERROR(K31-J31,"")
A32: =IFERROR(IF(A31+1>$C$5,"",A31+1),"") | B32: =IF(A32="","",EOMONTH(B31,1)) | C32: =IF(A32<>"",H31,"") | D32: =IF(A32="","",C32*Calc_InterestAccrualSchedule!$C$9) | E32: =IF(A32="","",IF(A32=$C$5,H31+D32,$C$10)) | F32: =IFERROR(VLOOKUP(B32,ECF!$F$2:$G$12,2),"") | G32: =IFERROR(E32-D32,"") | H32: =IFERROR(C32+D32-E32,"") | I32: =IFERROR(ROUND(1/(1+Calc_InterestAccrualSchedule!$C$9)^A32,5),"") | J32: =IFERROR(E32*I32,"") | K32: =IFERROR(F32*I32,"") | L32: =IFERROR(K32-J32,"")
... A65: =IFERROR(IF(A64+1>$C$5,"",A64+1),"") | B65: =IF(A65="","",EOMONTH(B64,1)) | C65: =IF(A65<>"",H64,"") | D65: =IF(A65="","",C65*Calc_InterestAccrualSchedule!$C$9) | E65: =IF(A65="","",IF(A65=$C$5,H64+D65,$C$10)) | F65: =IFERROR(VLOOKUP(B65,ECF!$F$2:$G$12,2),"") | G65: =IFERROR(E65-D65,"") | H65: =IFERROR(C65+D65-E65,"") | I65: =IFERROR(ROUND(1/(1+Calc_InterestAccrualSchedule!$C$9)^A65,5),"") | J65: =IFERROR(E65*I65,"") | K65: =IFERROR(F65*I65,"") | L65: =IFERROR(K65-J65,"")

Sheet o_Transaction
A1: PostingDate | B1: TransactionDate | C1: InstrumentId | D1: TransactionName | E1: Amount | F1: AttributeId
A2: =Calc_InterestAccrualSchedule!O17 | B2: =Calc_InterestAccrualSchedule!P17 | C2: =Calc_InterestAccrualSchedule!Q17 | D2: =Calc_InterestAccrualSchedule!R17 | E2: =Calc_InterestAccrualSchedule!S17 | F2: =Calc_InterestAccrualSchedule!T17
A3: =Calc_InterestAccrualSchedule!O18 | B3: =Calc_InterestAccrualSchedule!P18 | C3: =Calc_InterestAccrualSchedule!Q18 | D3: =Calc_InterestAccrualSchedule!R18 | E3: =Calc_InterestAccrualSchedule!S18 | F3: =Calc_InterestAccrualSchedule!T18
A4: =Calc_InterestAccrualSchedule!O19 | B4: =Calc_InterestAccrualSchedule!P19 | C4: =Calc_InterestAccrualSchedule!Q19 | D4: =Calc_InterestAccrualSchedule!R19 | E4: =Calc_InterestAccrualSchedule!S19 | F4: =Calc_InterestAccrualSchedule!T19
A5: =Calc_InterestAccrualSchedule!O20 | B5: =Calc_InterestAccrualSchedule!P20 | C5: =Calc_InterestAccrualSchedule!Q20 | D5: =Calc_InterestAccrualSchedule!R20 | E5: =Calc_InterestAccrualSchedule!S20 | F5: =Calc_InterestAccrualSchedule!T20

Sheet EXPECTED_INP
A1: 45688
V3: PostingDate | W3: TransactionDate | X3: InstrumentId | Y3: TransactionName | Z3: Amount | AA3: AttributeId
V4: 45688 | W4: 45688 | X4: LN-1001 | Y4: IMPAIRMENT_GAIN | Z4: 0 | AA4: 1
V5: 45688 | W5: 45688 | X5: LN-1001 | Y5: ORIGINATION_PRINCIPAL | Z5: 12000 | AA5: 1
V6: 45688 | W6: 45688 | X6: LN-1001 | Y6: INTEREST_ACCRUAL | Z6: 0 | AA6: 1
V7: 45688 | W7: 45688 | X7: LN-1001 | Y7: IMPAIRMENT_LOSS | Z7: 0 | AA7: 1
A8: ECF
A9: PostingDate | B9: EffectiveDate | C9: InstrumentId | D9: Attributeid | E9: ImpairmentType | F9: StartDate | G9: ExpectedCF
A11: EOD
A12: PostingDate | B12: EffectiveDate | C12: Instrumentid | D12: AttributeId | E12: Attribute_OriginationDate_Current | F12: Attribute_LoanAmount_Current | G12: Attribute_Term_Current | H12: Attribute_NoteRate_Current | I12: Balances_UPB_EndingBalance | J12: Balances_Impairment_EndingBalance
A13: 45688 | B13: 45688 | C13: LN-1001 | D13: 1 | E13: 45688 | F13: 12000 | G13: 12 | H13: 6
A17: 45716
V18: PostingDate | W18: TransactionDate | X18: InstrumentId | Y18: TransactionName | Z18: Amount | AA18: AttributeId
A19: EOD | V19: 45716 | W19: 45716 | X19: LN-1001 | Y19: IMPAIRMENT_GAIN | Z19: 0 | AA19: 1
A20: PostingDate | B20: EffectiveDate | C20: Instrumentid | D20: AttributeId | E20: Attribute_OriginationDate_Current | F20: Attribute_LoanAmount_Current | G20: Attribute_Term_Current | H20: Attribute_NoteRate_Current | I20: Balances_UPB_EndingBalance | J20: Balances_Impairment_EndingBalance | V20: 45716 | W20: 45716 | X20: LN-1001 | Y20: ORIGINATION_PRINCIPAL | Z20: 0 | AA20: 1
A21: 45716 | B21: 45716 | C21: LN-1001 | D21: 1 | E21: 45688 | F21: 12000 | G21: 12 | H21: 6 | I21: 12000 | V21: 45716 | W21: 45716 | X21: LN-1001 | Y21: INTEREST_ACCRUAL | Z21: 60 | AA21: 1
V22: 45716 | W22: 45716 | X22: LN-1001 | Y22: IMPAIRMENT_LOSS | Z22: -3065.4515 | AA22: 1
A23: ECF
A24: PostingDate | B24: EffectiveDate | C24: InstrumentId | D24: Attributeid | E24: ImpairmentType | F24: StartDate | G24: ExpectedCF
A25: 45716 | B25: 45716 | C25: LN-1001 | D25: 1 | E25: CF | F25: 45716 | G25: 1030
A26: 45716 | B26: 45716 | C26: LN-1001 | D26: 1 | E26: CF | F26: 45747 | G26: 1030 | Z26: =ROUND(Z22,4) -> -3065.4515
A27: 45716 | B27: 45716 | C27: LN-1001 | D27: 1 | E27: CF | F27: 45777 | G27: 1030
A28: 45716 | B28: 45716 | C28: LN-1001 | D28: 1 | E28: CF | F28: 45808 | G28: 1030
A29: 45716 | B29: 45716 | C29: LN-1001 | D29: 1 | E29: CF | F29: 45838 | G29: 1030
A30: 45716 | B30: 45716 | C30: LN-1001 | D30: 1 | E30: CF | F30: 45869 | G30: 1030
A31: 45716 | B31: 45716 | C31: LN-1001 | D31: 1 | E31: CF | F31: 45900 | G31: 500
A32: 45716 | B32: 45716 | C32: LN-1001 | D32: 1 | E32: CF | F32: 45930 | G32: 500
A33: 45716 | B33: 45716 | C33: LN-1001 | D33: 1 | E33: CF | F33: 45961 | G33: 500
A34: 45716 | B34: 45716 | C34: LN-1001 | D34: 1 | E34: CF | F34: 45991 | G34: 500
A35: 45716 | B35: 45716 | C35: LN-1001 | D35: 1 | E35: CF | F35: 46022 | G35: 500
A36: 45716 | B36: 45716 | C36: LN-1001 | D36: 1 | E36: CF | F36: 46053 | G36: 500
A41: 45747
A43: EOD | V43: Interest Payment | W43: Principal Payment
A44: PostingDate | B44: EffectiveDate | C44: Instrumentid | D44: AttributeId | E44: Attribute_OriginationDate_Current | F44: Attribute_LoanAmount_Current | G44: Attribute_Term_Current | H44: Attribute_NoteRate_Current | I44: Balances_UPB_EndingBalance | J44: Balances_Impairment_EndingBalance | V44: 60 | W44: 970
A45: 45747 | B45: 45747 | C45: LN-1001 | D45: 1 | E45: 45688 | F45: 12000 | G45: 12 | H45: 6 | I45: 11030 | J45: -3065.4515
A47: ECF
A48: PostingDate | B48: EffectiveDate | C48: InstrumentId | D48: Attributeid | E48: ImpairmentType | F48: StartDate | G48: ExpectedCF | V48: PostingDate | W48: TransactionDate | X48: InstrumentId | Y48: TransactionName | Z48: Amount | AA48: AttributeId
A49: 45747 | B49: 45747 | C49: LN-1001 | D49: 1 | E49: CF | F49: 45747 | G49: 1030 | V49: 45747 | W49: 45747 | X49: LN-1001 | Y49: IMPAIRMENT_GAIN | Z49: 0 | AA49: 1
A50: 45747 | B50: 45747 | C50: LN-1001 | D50: 1 | E50: CF | F50: 45777 | G50: 1030 | V50: 45747 | W50: 45747 | X50: LN-1001 | Y50: ORIGINATION_PRINCIPAL | Z50: 0 | AA50: 1
A51: 45747 | B51: 45747 | C51: LN-1001 | D51: 1 | E51: CF | F51: 45808 | G51: 1030 | V51: 45747 | W51: 45747 | X51: LN-1001 | Y51: INTEREST_ACCRUAL | Z51: 55.15 | AA51: 1
...
