Workbook

Sheet ORIG
A1: PostingDate | B1: EffectiveDate | C1: InstrumentId | D1: AttributeId | E1: ATTRIBUTE_LOAN_AMOUNT_CURRENT | F1: ATTRIBUTE_INTEREST_RECEIVABLE_CONSUMER_CURRENT | G1: BALANCES_ENDINGBALANCE_UNPAID_PRINCIPAL_BALANCE | H1: BALANCES_ENDINGBALANCE_ACCRUED_INTEREST_RECEIVABLE

Sheet PMT
A1: PostingDate | B1: EffectiveDate | C1: InstrumentId | D1: AttributeId | E1: TRANSACTIONS_AMOUNT_Interest_Adjustment | F1: TRANSACTIONS_AMOUNT_Payment_Interest | G1: TRANSACTIONS_AMOUNT_Payment_UPB

Sheet INT_ACC
A1: PostingDate | B1: EffectiveDate | C1: InstrumentId | D1: AttributeId | E1: ATTRIBUTE_INTEREST_RATE_CURRENT | F1: BALANCES_ENDINGBALANCE_Servicing_Interest_Accrual | G1: BALANCES_BEGINNINGBALANCE_Servicing_Interest_Accrual | H1: BALANCES_ACTIVITY_Servicing_Interest_Accrual

Sheet RC
A1: PostingDate | B1: EffectiveDate | C1: InstrumentId | D1: AttributeId | E1: ATTRIBUTE_INTEREST_RATE_CURRENT | F1: ATTRIBUTE_INTEREST_RATE_PRIOR | G1: ATTRIBUTE_INTEREST_RATE_FIRST | H1: ATTRIBUTE_LOAN_TERM_CURRENT | I1: ATTRIBUTE_LOAN_TERM_PRIOR | J1: ATTRIBUTE_LOAN_STATUS_CURRENT | K1: ATTRIBUTE_LOAN_STATUS_PRIOR

Sheet CALC
A1: INSTRUMENT ADD
A3: TRANSACTIONS
A4: PostingDate | B4: EffectiveDate | C4: InstrumentId | D4: AttributeId | E4: TransactionName | F4: Amount | H4: Trans
A5: =IF(ORIG!A2="","",ORIG!A2) | B5: =IF(A5="","",A5) | C5: =IF(B5="","",ORIG!$C$2) | D5: =IF(C5="","",ORIG!$D$2) | E5: =IF(D5="","",H5) | F5: =IF(E5="","",ORIG!E2) | H5: ATT_LA_CUR
A6: =IF(A5="","",A5) | B6: =IF(A6="","",A6) | C6: =IF(B6="","",ORIG!$C$2) | D6: =IF(C6="","",ORIG!$D$2) | E6: =IF(D6="","",H6) | F6: =IF(E6="","",ORIG!F2) | H6: ATT_IRC_CUR
A7: =IF(A6="","",A6) | B7: =IF(A7="","",A7) | C7: =IF(B7="","",ORIG!$C$2) | D7: =IF(C7="","",ORIG!$D$2) | E7: =IF(D7="","",H7) | F7: =IF(E7="","",ORIG!G2) | H7: BAL_EB_UPB
A8: =IF(A7="","",A7) | B8: =IF(A8="","",A8) | C8: =IF(B8="","",ORIG!$C$2) | D8: =IF(C8="","",ORIG!$D$2) | E8: =IF(D8="","",H8) | F8: =IF(E8="","",ORIG!H2) | H8: BAL_EB_AIR
A9: =IF(A8="","",A8) | B9: =IF(A9="","",A9) | C9: =IF(B9="","",ORIG!$C$3) | D9: =IF(C9="","",ORIG!$D$3) | E9: =IF(D9="","",H9) | F9: =IF(E9="","",ORIG!E3) | H9: ATT_LA_CUR
A10: =IF(A9="","",A9) | B10: =IF(A10="","",A10) | C10: =IF(B10="","",ORIG!$C$3) | D10: =IF(C10="","",ORIG!$D$3) | E10: =IF(D10="","",H10) | F10: =IF(E10="","",ORIG!F3) | H10: ATT_IRC_CUR
A11: =IF(A10="","",A10) | B11: =IF(A11="","",A11) | C11: =IF(B11="","",ORIG!$C$3) | D11: =IF(C11="","",ORIG!$D$3) | E11: =IF(D11="","",H11) | F11: =IF(E11="","",ORIG!G3) | H11: BAL_EB_UPB
A12: =IF(A11="","",A11) | B12: =IF(A12="","",A12) | C12: =IF(B12="","",ORIG!$C$3) | D12: =IF(C12="","",ORIG!$D$3) | E12: =IF(D12="","",H12) | F12: =IF(E12="","",ORIG!H3) | H12: BAL_EB_AIR
A14: MODEL EXECUTION
A15: TRANSACTIONS
A16: PostingDate | B16: EffectiveDate | C16: InstrumentId | D16: AttributeId | E16: TransactionName | F16: Amount | H16: Trans
A17: =IF(INT_ACC!A2="","",INT_ACC!A2) | B17: =IF(A17="","",A17) | C17: =IF(B17="","",INT_ACC!$C$2) | D17: =IF(C17="","",INT_ACC!$D$2) | E17: =IF(D17="","",H17) | F17: =IF(E17="","",INT_ACC!E2) | H17: ATT_IR_CUR
A18: =IF(A17="","",A17) | B18: =IF(A18="","",A18) | C18: =IF(B18="","",INT_ACC!$C$2) | D18: =IF(C18="","",INT_ACC!$D$2) | E18: =IF(D18="","",H18) | F18: =IF(E18="","",INT_ACC!F2) | H18: BAL_EB_SIA
A19: =IF(A18="","",A18) | B19: =IF(A19="","",A19) | C19: =IF(B19="","",INT_ACC!$C$2) | D19: =IF(C19="","",INT_ACC!$D$2) | E19: =IF(D19="","",H19) | F19: =IF(E19="","",INT_ACC!G2) | H19: BAL_BB_SIA
A20: =IF(A19="","",A19) | B20: =IF(A20="","",A20) | C20: =IF(B20="","",INT_ACC!$C$2) | D20: =IF(C20="","",INT_ACC!$D$2) | E20: =IF(D20="","",H20) | F20: =IF(E20="","",INT_ACC!H2) | H20: BAL_ACT_SIA
A21: =IF(A20="","",A20) | B21: =IF(A21="","",A21) | C21: =IF(B21="","",INT_ACC!$C$3) | D21: =IF(C21="","",INT_ACC!$D$3) | E21: =IF(D21="","",H21) | F21: =IF(E21="","",INT_ACC!E3) | H21: ATT_IR_CUR
A22: =IF(A21="","",A21) | B22: =IF(A22="","",A22) | C22: =IF(B22="","",INT_ACC!$C$3) | D22: =IF(C22="","",INT_ACC!$D$3) | E22: =IF(D22="","",H22) | F22: =IF(E22="","",INT_ACC!F3) | H22: BAL_EB_SIA
A23: =IF(A22="","",A22) | B23: =IF(A23="","",A23) | C23: =IF(B23="","",INT_ACC!$C$3) | D23: =IF(C23="","",INT_ACC!$D$3) | E23: =IF(D23="","",H23) | F23: =IF(E23="","",INT_ACC!G3) | H23: BAL_BB_SIA
A24: =IF(A23="","",A23) | B24: =IF(A24="","",A24) | C24: =IF(B24="","",INT_ACC!$C$3) | D24: =IF(C24="","",INT_ACC!$D$3) | E24: =IF(D24="","",H24) | F24: =IF(E24="","",INT_ACC!H3) | H24: BAL_ACT_SIA
A26: ON TRANSACTION POST
A27: TRANSACTIONS
A28: PostingDate | B28: EffectiveDate | C28: InstrumentId | D28: AttributeId | E28: TransactionName | F28: Amount | H28: Trans
A29: =IF(PMT!A2="","",PMT!A2) | B29: =IF(A29="","",A29) | C29: =IF(B17="","",PMT!$C$2) | D29: =IF(C29="","",PMT!D4) | E29: =IF(D29="","",H29) | F29: =IF(E29="","",PMT!E4) | H29: TRANX_AM_IA
A30: =IF(A29="","",A29) | B30: =IF(A30="","",A30) | C30: =IF(B18="","",PMT!$C$2) | D30: =IF(C30="","",PMT!D8) | E30: =IF(D30="","",H30) | F30: =IF(E30="","",PMT!E8) | H30: TRANX_AM_IA
A31: =IF(A30="","",A30) | B31: =IF(A31="","",A31) | C31: =IF(B19="","",PMT!$C$2) | D31: =IF(C31="","",PMT!D3) | E31: =IF(D31="","",H31) | F31: =IF(E31="","",PMT!F3) | H31: TRANX_AM_PINT
A32: =IF(A31="","",A31) | B32: =IF(A32="","",A32) | C32: =IF(B20="","",PMT!$C$2) | D32: =IF(C32="","",PMT!D7) | E32: =IF(D32="","",H32) | F32: =IF(E32="","",PMT!F7) | H32: TRANX_AM_PINT
A33: =IF(A32="","",A32) | B33: =IF(A33="","",A33) | C33: =IF(B21="","",PMT!$C$2) | D33: =IF(C33="","",PMT!D2) | E33: =IF(D33="","",H33) | F33: =IF(E33="","",PMT!G2) | H33: TRANX_AM_PUPB
A34: =IF(A33="","",A33) | B34: =IF(A34="","",A34) | C34: =IF(B22="","",PMT!$C$2) | D34: =IF(C34="","",PMT!D3) | E34: =IF(D34="","",H34) | F34: =IF(E34="","",PMT!G3) | H34: TRANX_AM_PUPB
A35: =IF(A34="","",A34) | B35: =IF(A35="","",A35) | C35: =IF(B23="","",PMT!$C$2) | D35: =IF(C35="","",PMT!D5) | E35: =IF(D35="","",H35) | F35: =IF(E35="","",PMT!G5) | H35: TRANX_AM_PUPB
A36: =IF(A35="","",A35) | B36: =IF(A36="","",A36) | C36: =IF(B24="","",PMT!$C$2) | D36: =IF(C36="","",PMT!D6) | E36: =IF(D36="","",H36) | F36: =IF(E36="","",PMT!G6) | H36: TRANX_AM_PUPB
A38: ON ATTRIBUTE CHANGE
A39: TRANSACTIONS
A40: PostingDate | B40: EffectiveDate | C40: InstrumentId | D40: AttributeId | E40: TransactionName | F40: Amount | H40: Trans
A41: =IF('RC'!A2="","",'RC'!A2) | B41: =IF(A41="","",A41) | C41: =IF(B41="","",'RC'!$C$2) | D41: =IF(C41="","",'RC'!$D$2) | E41: =IF(D41="","",H41) | F41: =IF(E41="","",'RC'!E2) | H41: ATT_IR_CUR
A42: =IF(A41="","",A41) | B42: =IF(A42="","",A42) | C42: =IF(B42="","",'RC'!$C$2) | D42: =IF(C42="","",'RC'!$D$2) | E42: =IF(D42="","",H42) | F42: =IF(E41="","",'RC'!F2) | H42: ATT_IR_PR
A43: =IF(A42="","",A42) | B43: =IF(A43="","",A43) | C43: =IF(B43="","",'RC'!$C$2) | D43: =IF(C43="","",'RC'!$D$2) | E43: =IF(D43="","",H43) | F43: =IF(E41="","",'RC'!G2) | H43: ATT_IR_FIR
A44: =IF(A43="","",A43) | B44: =IF(A44="","",A44) | C44: =IF(B44="","",'RC'!$C$2) | D44: =IF(C44="","",'RC'!$D$2) | E44: =IF(D44="","",H44) | F44: =IF(E41="","",'RC'!H2) | H44: ATT_LT_CUR
...

Sheet o_Transaction
A1: PostingDate | B1: TransactionDate | C1: InstrumentId | D1: TransactionName | E1: Amount | F1: AttributeId
A2: =CALC!A5 | B2: =CALC!B5 | C2: =CALC!C5 | D2: =CALC!E5 | E2: =CALC!F5 | F2: =CALC!D5
A3: =CALC!A6 | B3: =CALC!B6 | C3: =CALC!C6 | D3: =CALC!E6 | E3: =CALC!F6 | F3: =CALC!D6
A4: =CALC!A7 | B4: =CALC!B7 | C4: =CALC!C7 | D4: =CALC!E7 | E4: =CALC!F7 | F4: =CALC!D7
A5: =CALC!A8 | B5: =CALC!B8 | C5: =CALC!C8 | D5: =CALC!E8 | E5: =CALC!F8 | F5: =CALC!D8
A6: =CALC!A9 | B6: =CALC!B9 | C6: =CALC!C9 | D6: =CALC!E9 | E6: =CALC!F9 | F6: =CALC!D9
A7: =CALC!A10 | B7: =CALC!B10 | C7: =CALC!C10 | D7: =CALC!E10 | E7: =CALC!F10 | F7: =CALC!D10
A8: =CALC!A11 | B8: =CALC!B11 | C8: =CALC!C11 | D8: =CALC!E11 | E8: =CALC!F11 | F8: =CALC!D11
A9: =CALC!A12 | B9: =CALC!B12 | C9: =CALC!C12 | D9: =CALC!E12 | E9: =CALC!F12 | F9: =CALC!D12
A10: =CALC!A17 | B10: =CALC!B17 | C10: =CALC!C17 | D10: =CALC!E17 | E10: =CALC!F17 | F10: =CALC!D17
A11: =CALC!A18 | B11: =CALC!B18 | C11: =CALC!C18 | D11: =CALC!E18 | E11: =CALC!F18 | F11: =CALC!D18
A12: =CALC!A19 | B12: =CALC!B19 | C12: =CALC!C19 | D12: =CALC!E19 | E12: =CALC!F19 | F12: =CALC!D19
A13: =CALC!A20 | B13: =CALC!B20 | C13: =CALC!C20 | D13: =CALC!E20 | E13: =CALC!F20 | F13: =CALC!D20
A14: =CALC!A21 | B14: =CALC!B21 | C14: =CALC!C21 | D14: =CALC!E21 | E14: =CALC!F21 | F14: =CALC!D21
A15: =CALC!A22 | B15: =CALC!B22 | C15: =CALC!C22 | D15: =CALC!E22 | E15: =CALC!F22 | F15: =CALC!D22
A16: =CALC!A23 | B16: =CALC!B23 | C16: =CALC!C23 | D16: =CALC!E23 | E16: =CALC!F23 | F16: =CALC!D23
A17: =CALC!A24 | B17: =CALC!B24 | C17: =CALC!C24 | D17: =CALC!E24 | E17: =CALC!F24 | F17: =CALC!D24
A18: =CALC!A29 | B18: =CALC!B29 | C18: =CALC!C29 | D18: =CALC!E29 | E18: =CALC!F29 | F18: =CALC!D29
A19: =CALC!A30 | B19: =CALC!B30 | C19: =CALC!C30 | D19: =CALC!E30 | E19: =CALC!F30 | F19: =CALC!D30
A20: =CALC!A31 | B20: =CALC!B31 | C20: =CALC!C31 | D20: =CALC!E31 | E20: =CALC!F31 | F20: =CALC!D31
A21: =CALC!A32 | B21: =CALC!B32 | C21: =CALC!C32 | D21: =CALC!E32 | E21: =CALC!F32 | F21: =CALC!D32
A22: =CALC!A33 | B22: =CALC!B33 | C22: =CALC!C33 | D22: =CALC!E33 | E22: =CALC!F33 | F22: =CALC!D33
A23: =CALC!A34 | B23: =CALC!B34 | C23: =CALC!C34 | D23: =CALC!E34 | E23: =CALC!F34 | F23: =CALC!D34
A24: =CALC!A35 | B24: =CALC!B35 | C24: =CALC!C35 | D24: =CALC!E35 | E24: =CALC!F35 | F24: =CALC!D35
A25: =CALC!A36 | B25: =CALC!B36 | C25: =CALC!C36 | D25: =CALC!E36 | E25: =CALC!F36 | F25: =CALC!D36
A26: =CALC!A41 | B26: =CALC!B41 | C26: =CALC!C41 | D26: =CALC!E41 | E26: =CALC!F41 | F26: =CALC!D41
A27: =CALC!A42 | B27: =CALC!B42 | C27: =CALC!C42 | D27: =CALC!E42 | E27: =CALC!F42 | F27: =CALC!D42
A28: =CALC!A43 | B28: =CALC!B43 | C28: =CALC!C43 | D28: =CALC!E43 | E28: =CALC!F43 | F28: =CALC!D43
A29: =CALC!A44 | B29: =CALC!B44 | C29: =CALC!C44 | D29: =CALC!E44 | E29: =CALC!F44 | F29: =CALC!D44
A30: =CALC!A45 | B30: =CALC!B45 | C30: =CALC!C45 | D30: =CALC!E45 | E30: =CALC!F45 | F30: =CALC!D45
A31: =CALC!A46 | B31: =CALC!B46 | C31: =CALC!C46 | D31: =CALC!E46 | E31: =CALC!F46 | F31: =CALC!D46
A32: =CALC!A47 | B32: =CALC!B47 | C32: =CALC!C47 | D32: =CALC!E47 | E32: =CALC!F47 | F32: =CALC!D47
A33: =CALC!A48 | B33: =CALC!B48 | C33: =CALC!C48 | D33: =CALC!E48 | E33: =CALC!F48 | F33: =CALC!D48
A34: =CALC!A49 | B34: =CALC!B49 | C34: =CALC!C49 | D34: =CALC!E49 | E34: =CALC!F49 | F34: =CALC!D49
A35: =CALC!A50 | B35: =CALC!B50 | C35: =CALC!C50 | D35: =CALC!E50 | E35: =CALC!F50 | F35: =CALC!D50
A36: =CALC!A51 | B36: =CALC!B51 | C36: =CALC!C51 | D36: =CALC!E51 | E36: =CALC!F51 | F36: =CALC!D51
A37: =CALC!A52 | B37: =CALC!B52 | C37: =CALC!C52 | D37: =CALC!E52 | E37: =CALC!F52 | F37: =CALC!D52
... A39: =CALC!A54 | B39: =CALC!B54 | C39: =CALC!C54 | D39: =CALC!E54 | E39: =CALC!F54 | F39: =CALC!D54

Sheet Expected1
A1: OUTPUT
A2: PostingDate | B2: TransactionDate | C2: InstrumentId | D2: TransactionName | E2: Amount | F2: AttributeId
A3: 44592 | B3: 44592 | C3: LOAN1 | D3: ATT_LA_CUR | E3: 100000 | F3: 1.0
A4: 44592 | B4: 44592 | C4: LOAN1 | D4: ATT_IRC_CUR | E4: 100 | F4: 1.0
A5: 44592 | B5: 44592 | C5: LOAN1 | D5: BAL_EB_UPB | E5: 100000 | F5: 1.0
A6: 44592 | B6: 44592 | C6: LOAN1 | D6: BAL_EB_AIR | E6: 150 | F6: 1.0
A7: 44592 | B7: 44592 | C7: LOAN1 | D7: ATT_LA_CUR | E7: 150000 | F7: 2.0
A8: 44592 | B8: 44592 | C8: LOAN1 | D8: ATT_IRC_CUR | E8: 200 | F8: 2.0
A9: 44592 | B9: 44592 | C9: LOAN1 | D9: BAL_EB_UPB | E9: 150000 | F9: 2.0
A10: 44592 | B10: 44592 | C10: LOAN1 | D10: BAL_EB_AIR | E10: 240 | F10: 2.0
A11: 44592 | B11: 44592 | C11: LOAN1 | D11: ATT_IR_CUR | E11: 10 | F11: 1.0
A12: 44592 | B12: 44592 | C12: LOAN1 | D12: BAL_EB_SIA | E12: 50 | F12: 1.0
A13: 44592 | B13: 44592 | C13: LOAN1 | D13: BAL_BB_SIA | E13: 0 | F13: 1.0
A14: 44592 | B14: 44592 | C14: LOAN1 | D14: BAL_ACT_SIA | E14: 50 | F14: 1.0
... A18: 44592 | B18: 44592 | C18: LOAN1 | D18: BAL_ACT_SIA | E18: 40 | F18: 2.0
A20: ORIG
A21: PostingDate | B21: EffectiveDate | C21: InstrumentId | D21: AttributeId | E21: ATTRIBUTE_LOAN_AMOUNT_CURRENT | F21: ATTRIBUTE_INTEREST_RECEIVABLE_CONSUMER_CURRENT | G21: BALANCES_ENDINGBALANCE_UNPAID_PRINCIPAL_BALANCE | H21: BALANCES_ENDINGBALANCE_ACCRUED_INTEREST_RECEIVABLE
A22: 44592 | B22: 44592 | C22: LOAN1 | D22: 1.0 | E22: 100000 | F22: 100 | G22: 100000 | H22: 150
A23: 44592 | B23: 44592 | C23: LOAN1 | D23: 2.0 | E23: 150000 | F23: 200 | G23: 150000 | H23: 240
A25: INT_ACC
A26: PostingDate | B26: EffectiveDate | C26: InstrumentId | D26: AttributeId | E26: ATTRIBUTE_INTEREST_RATE_CURRENT | F26: BALANCES_ENDINGBALANCE_Servicing_Interest_Accrual | G26: BALANCES_BEGINNINGBALANCE_Servicing_Interest_Accrual | H26: BALANCES_ACTIVITY_Servicing_Interest_Accrual
A27: 44592 | B27: 44592 | C27: LOAN1 | D27: 1.0 | E27: 10 | F27: 50 | G27: 0 | H27: 50
A28: 44592 | B28: 44592 | C28: LOAN1 | D28: 2.0 | E28: 8 | F28: 40 | G28: 0 | H28: 40
A32: OUTPUT Day2
A33: PostingDate | B33: TransactionDate | C33: InstrumentId | D33: TransactionName | E33: Amount | F33: AttributeId
A34: 44595 | B34: 44595 | C34: LOAN1 | D34: ATT_IR_CUR | E34: 20 | F34: 1.0
A35: 44595 | B35: 44595 | C35: LOAN1 | D35: BAL_EB_SIA | E35: 50 | F35: 1.0
A36: 44595 | B36: 44595 | C36: LOAN1 | D36: BAL_BB_SIA | E36: 50 | F36: 1.0
A37: 44595 | B37: 44595 | C37: LOAN1 | D37: BAL_ACT_SIA | E37: 0 | F37: 1.0
A38: 44595 | B38: 44595 | C38: LOAN1 | D38: ATT_IR_CUR | E38: 18 | F38: 2.0
A39: 44595 | B39: 44595 | C39: LOAN1 | D39: BAL_EB_SIA | E39: 40 | F39: 2.0
A40: 44595 | B40: 44595 | C40: LOAN1 | D40: BAL_BB_SIA | E40: 40 | F40: 2.0
A41: 44595 | B41: 44595 | C41: LOAN1 | D41: BAL_ACT_SIA | E41: 0 | F41: 2.0
A42: 44595 | B42: 44595 | C42: LOAN1 | D42: TRANX_AM_IA | E42: 1500 | F42: 1.0
A43: 44595 | B43: 44595 | C43: LOAN1 | D43: TRANX_AM_IA | E43: 2000 | F43: 2.0
A44: 44595 | B44: 44595 | C44: LOAN1 | D44: TRANX_AM_PINT | E44: 1100 | F44: 1.0
A45: 44595 | B45: 44595 | C45: LOAN1 | D45: TRANX_AM_PINT | E45: 2100 | F45: 2.0
... A63: 44595 | B63: 44595 | C63: LOAN1 | D63: ATT_LS_PR | E63: 4 | F63: 2.0
A66: PMT
A67: PostingDate | B67: EffectiveDate | C67: InstrumentId | D67: AttributeId | E67: TRANSACTIONS_AMOUNT_Interest_Adjustment | F67: TRANSACTIONS_AMOUNT_Payment_Interest | G67: TRANSACTIONS_AMOUNT_Payment_UPB
...
