Workbook

Sheet TRANX
A1: PostingDate | B1: EffectiveDate | C1: InstrumentId | D1: AttributeId | E1: TRANSACTIONS_AMOUNT_REMIT | F1: TRANSACTIONS_AMOUNT_DRAW

Sheet EOD
A1: PostingDate | B1: EffectiveDate | C1: InstrumentId | D1: AttributeId | E1: ATTRIBUTE_INTEREST_RATE_CURRENT | F1: BALANCES_BEGINNINGBALANCE_UNPAID_PRINCIPAL_BALANCE | G1: BALANCES_BEGINNINGBALANCE_ACCRUED_INTEREST_RECEIVABLE

Sheet REPLAY
A1: PostingDate | B1: EffectiveDate | C1: InstrumentId | D1: AttributeId | E1: TRANSACTIONS_AMOUNT_REMIT | F1: TRANSACTIONS_AMOUNT_DRAW | G1: BALANCES_BEGINNINGBALANCE_Unpaid_Principal_Balance | H1: BALANCES_BEGINNINGBALANCE_Accrued_Interest_Receivable

Sheet EXPECTED
A1: INPUT
A3: REPLAY EVENT
A5: Posting Date | B5: Effective Date | C5: InstrumentId | D5: AttributeId | E5: TRANSACTIONS_AMOUNT_REMIT | F5: TRANSACTIONS_AMOUNT_DRAW | G5: BALANCES_BEGINNINGBALANCE_Unpaid_Principal_Balance | H5: BALANCES_BEGINNINGBALANCE_Accrued_Interest_Receivable
A6: 44712 | B6: 44614 | C6: L1 | D6: 1 | E6: 400 | G6: 100000 | H6: 100
A7: 44712 | B7: 44635 | C7: L1 | D7: 1 | E7: 1500
A8: 44712 | B8: 44645 | C8: L1 | D8: 1 | F8: 7000
A9: 44712 | B9: 44671 | C9: L1 | D9: 1 | E9: 2000
A10: 44712 | B10: 44712 | C10: L1 | D10: 1
A12: PMT
A14: Posting Date | B14: Effective Date | C14: InstrumentId | D14: AttributeId | E14: TRANSACTIONS_AMOUNT_REMIT | F14: TRANSACTIONS_AMOUNT_DRAW
A15: 44651 | B15: 44635 | C15: L1 | D15: 1 | E15: 1500
A16: 44651 | B16: 44645 | C16: L1 | D16: 1 | F16: 7000
A17: 44681 | B17: 44671 | C17: L1 | D17: 1 | E17: 2000
A18: 44712 | B18: 44614 | C18: L1 | D18: 1 | E18: 400
A20: INT_ACC
A22: Posting Date | B22: Effective Date | C22: InstrumentId | D22: AttributeId | E22: ATTRIBUTE_INTEREST_RATE_CURRENT | F22: BALANCES_BEGINNINGBALANCE_Unpaid_Principal_Balance | G22: BALANCES_BEGINNINGBALANCE_Accrued_Interest_Receivable
A23: 44620 | B23: 44620 | C23: L1 | D23: 1 | E23: 10 | F23: 100000 | G23: 100
A24: 44651 | B24: 44651 | C24: L1 | D24: 1 | E24: 10 | F24: 100000 | G24: 877.7778
A25: 44681 | B25: 44681 | C25: L1 | D25: 1 | E25: 10 | F25: 106766.67 | G25: 484.7315
A26: 44712 | B26: 44712 | C26: L1 | D26: 1 | E26: 10 | F26: 105814.89 | G26: 323.3233
A29: OUTPUT
A32: PostingDate | B32: TransactionDate | C32: InstrumentId | D32: TransactionName | E32: Amount | F32: AttributeId
A33: 20220131 | B33: 20220131 | C33: IDHJ-EGNY | D33: PURCHASE_INTEREST | E33: 100 | F33: 1
A34: 20220131 | B34: 20220131 | C34: IDHJ-EGNY | D34: PURCHASE_UPB | E34: 100000 | F34: 1
A35: 20220228 | B35: 20220228 | C35: IDHJ-EGNY | D35: SERVICING_INTEREST_ACCRUAL | E35: 777.7778 | F35: 1
A36: 20220331 | B36: 20220325 | C36: IDHJ-EGNY | D36: DRAW | E36: 7000 | F36: 1
A37: 20220331 | B37: 20220315 | C37: IDHJ-EGNY | D37: PAYMENT_INTEREST | E37: -1266.6667 | F37: 1
A38: 20220331 | B38: 20220315 | C38: IDHJ-EGNY | D38: PAYMENT_UPB | E38: -233.3333 | F38: 1
A39: 20220331 | B39: 20220315 | C39: IDHJ-EGNY | D39: REMIT | E39: 1500 | F39: 1
A40: 20220331 | B40: 20220331 | C40: IDHJ-EGNY | D40: SERVICING_INTEREST_ACCRUAL | E40: 873.6204 | F40: 1
A41: 20220430 | B41: 20220420 | C41: IDHJ-EGNY | D41: PAYMENT_INTEREST | E41: -1048.2222 | F41: 1
A42: 20220430 | B42: 20220420 | C42: IDHJ-EGNY | D42: PAYMENT_UPB | E42: -951.7778 | F42: 1
A43: 20220430 | B43: 20220420 | C43: IDHJ-EGNY | D43: REMIT | E43: 1500 | F43: 1
A44: 20220430 | B44: 20220430 | C44: IDHJ-EGNY | D44: SERVICING_INTEREST_ACCRUAL | E44: 886.814 | F44: 1
... A48: 20220531 | B48: 20220531 | C48: IDHJ-EGNY | D48: SERVICING_INTEREST_ACCRUAL | E48: 907.7049 | F48: 1

Sheet Scenario
A1: Transactions | H1: Balances | M1: Monthly NR | N1: =10/1200 -> 0.0083333333 | P1: 10 | Q1: =P1/100 -> 0.1 | R1: =Q1/360 -> 0.00027777778
A2: PD | B2: ED | C2: Transaction | D2: Component | E2: Amount | F2: Entry | G2: Days | H2: UPB | I2: AIR | K2: Round | M2: Daily NR | N2: =R1 -> 0.00027777778
A3: 44592 | B3: =A3 -> 44592 | C3: Purchase | D3: UPB | E3: 100000 | F3: New | H3: =E3 -> 100000 | I3: 0 | K3: =ROUND(E3,4) -> 100000
A4: 44592 | B4: =A4 -> 44592 | C4: Purchase | D4: Interest | E4: 100 | F4: New | H4: =E3 -> 100000 | I4: =E4 -> 100 | K4: =ROUND(E4,4) -> 100
A5: 44620 | B5: 44620 | C5: accrual | D5: Interest | E5: =H5*$N$2*G5 -> 777.77778 | F5: New | G5: =A5-A4 -> 28 | H5: =H4 -> 100000 | I5: =I4+E5 -> 877.77778 | K5: =ROUND(E5,4) -> 777.7778
A6: 44651 | B6: 44634 | C6: accrual | D6: Interest | E6: =H6*$N$2*G6 -> 388.88889 | F6: New | G6: =B6-B5 -> 14 | H6: =H5 -> 100000 | I6: =I5+E6 -> 1266.6667 | K6: =ROUND(E6,4) -> 388.8889
A7: 44651 | B7: 44635 | C7: Remit | E7: 1500 | F7: New | H7: =H5 -> 100000 | I7: =I6 -> 1266.6667 | K7: =ROUND(E7,4) -> 1500
A8: 44651 | B8: 44635 | C8: Payment | D8: UPB | E8: =-(E9+E7) -> -233.33333 | F8: New | H8: =H7+E8 -> 99766.667 | I8: =I7 -> 1266.6667 | K8: =ROUND(E8,4) -> -233.3333
A9: 44651 | B9: 44635 | C9: Payment | D9: Interest | E9: =-MIN(I7,E7) -> -1266.6667 | F9: New | H9: =H8 -> 99766.667 | I9: =I8+E9 -> 0 | K9: =ROUND(E9,4) -> -1266.6667
A10: 44651 | B10: 44644 | C10: accrual | D10: Interest | E10: =H10*$N$2*G10 -> 277.12963 | F10: New | G10: =B11-B9 -> 10 | H10: =H9 -> 99766.667 | I10: =E10+I9 -> 277.12963 | K10: =ROUND(E10,4) -> 277.1296
A11: 44651 | B11: 44645 | C11: Draw | D11: UPB | E11: 7000 | F11: New | H11: =H10+E11 -> 106766.67 | I11: =I10 -> 277.12963 | K11: =ROUND(E11,4) -> 7000
A12: 44651 | B12: 44651 | C12: accrual | D12: Interest | E12: =H12*N2*G12 -> 207.60185 | F12: New | G12: =B12-B11+1 -> 7 | H12: =H11 -> 106766.67 | I12: =E12+I11 -> 484.73148 | K12: =ROUND(E12,4) -> 207.6019
A13: 44681 | B13: 44670 | C13: accrual | D13: Interest | E13: =H13*N2*G13 -> 563.49074 | F13: New | G13: =B13-B12 -> 19 | H13: =H12 -> 106766.67 | I13: =I12+E13 -> 1048.2222 | K13: =ROUND(E13,4) -> 563.4907
A14: 44681 | B14: 44671 | C14: Remit | E14: 2000 | F14: New | H14: =H13 -> 106766.67 | I14: =I13 -> 1048.2222 | K14: =ROUND(E14,4) -> 2000
A15: 44681 | B15: 44671 | C15: Payment | D15: UPB | E15: =-(E16+E14) -> -951.77778 | F15: New | H15: =H14+E15 -> 105814.89 | I15: =I14 -> 1048.2222 | K15: =ROUND(E15,4) -> -951.7778
A16: 44681 | B16: 44671 | C16: Payment | D16: Interest | E16: =-I15 -> -1048.2222 | F16: New | H16: =H15 -> 105814.89 | I16: =I15+E16 -> 0 | K16: =ROUND(E16,4) -> -1048.2222
A17: 44681 | B17: 44681 | C17: accrual | D17: Interest | E17: =H17*N2*G17 -> 323.32327 | F17: New | G17: 11 | H17: =H16 -> 105814.89 | I17: =I16+E17 -> 323.32327 | K17: =ROUND(E17,4) -> 323.3233
A18: 44712 | B18: 44614 | C18: Remit | E18: 400 | F18: New | G18: 21 | H18: =H5 -> 100000 | I18: =I4+(H18*N2*G18) -> 683.33333 | K18: =ROUND(E18,4) -> 400
A19: 44712 | B19: 44614 | C19: Payment | D19: UPB | E19: 0 | F19: New | H19: =H18 -> 100000 | I19: 0 | K19: =ROUND(E19,4) -> 0
A20: 44712 | B20: 44614 | C20: Payment | D20: Interest | E20: =-MIN(E18,I18) -> -400 | F20: New | H20: =H19 -> 100000 | I20: =I18+E20 -> 283.33333 | K20: =ROUND(E20,4) -> -400
A21: 44712 | B21: 44620 | C21: accrual | D21: Interest | E21: =H21*N2*G21 -> 194.44444 | F21: New | G21: 7 | H21: =H20 -> 100000 | I21: =I20+E21 -> 477.77778 | K21: =ROUND(E21,4) -> 194.4444
A22: 44712 | B22: 44634 | C22: accrual | D22: Interest | E22: =H22*$N$2*G22 -> 388.88889 | G22: 14 | H22: =H21 -> 100000 | I22: =I21+E22 -> 866.66667 | K22: =ROUND(E22,4) -> 388.8889
A23: 44712 | B23: 44635 | C23: Remit | E23: =E7 -> 1500 | H23: =H22 -> 100000 | I23: =I22 -> 866.66667 | K23: =ROUND(E23,4) -> 1500
A24: 44712 | B24: 44635 | C24: Payment | D24: UPB | E24: =-(E25+E23) -> -633.33333 | H24: =H23+E24 -> 99366.667 | I24: =I23 -> 866.66667 | K24: =ROUND(E24,4) -> -633.3333
A25: 44712 | B25: 44635 | C25: Payment | D25: Interest | E25: =-I24 -> -866.66667 | H25: =H24 -> 99366.667 | I25: =I24+E25 -> 0 | K25: =ROUND(E25,4) -> -866.6667
A26: 44712 | B26: 44644 | C26: accrual | D26: Interest | E26: =H26*$N$2*G26 -> 276.01852 | G26: 10 | H26: =H25 -> 99366.667 | I26: =I25+E26 -> 276.01852 | K26: =ROUND(E26,4) -> 276.0185
A27: 44712 | B27: 44645 | C27: Draw | D27: UPB | E27: =E11 -> 7000 | H27: =H26+E27 -> 106366.67 | I27: =I26 -> 276.01852 | K27: =ROUND(E27,4) -> 7000
A28: 44712 | B28: 44651 | C28: accrual | D28: Interest | E28: =H28*$N$2*G28 -> 206.82407 | G28: 7 | H28: =H27 -> 106366.67 | I28: =I27+E28 -> 482.84259 | K28: =ROUND(E28,4) -> 206.8241
A29: 44712 | B29: 44670 | C29: accrual | D29: Interest | E29: =H29*$N$2*G29 -> 561.37963 | G29: 19 | H29: =H28 -> 106366.67 | I29: =I28+E29 -> 1044.2222 | K29: =ROUND(E29,4) -> 561.3796
A30: 44712 | B30: 44671 | C30: Remit | E30: =E14 -> 2000 | H30: =H29 -> 106366.67 | I30: =I29 -> 1044.2222 | K30: =ROUND(E30,4) -> 2000
A31: 44712 | B31: 44671 | C31: Payment | D31: UPB | E31: =-(E32+E30) -> -955.77778 | H31: =H30+E31 -> 105410.89 | I31: =I30 -> 1044.2222 | K31: =ROUND(E31,4) -> -955.7778
A32: 44712 | B32: 44671 | C32: Payment | D32: Interest | E32: =-I30 -> -1044.2222 | H32: =H31 -> 105410.89 | I32: =I31+E32 -> 0 | K32: =ROUND(E32,4) -> -1044.2222
A33: 44712 | B33: 44681 | C33: accrual | D33: Interest | E33: =H33*$N$2*G33 -> 322.08883 | G33: 11 | H33: =H32 -> 105410.89 | I33: =I32+E33 -> 322.08883 | K33: =ROUND(E33,4) -> 322.0888
A34: 44712 | B34: 44712 | C34: accrual | D34: Interest | E34: =H34*$N$2*G34 -> 907.70488 | G34: =B34-B33 -> 31 | H34: =H33 -> 105410.89 | I34: =I33+E34 -> 1229.7937 | K34: =ROUND(E34,4) -> 907.7049
A35: 44712 | B35: 44712 | C35: Adjustment | D35: UPB | E35: =H34-H17 -> -404 | K35: =ROUND(E35,4) -> -404
A36: 44712 | B36: 44712 | C36: Adjustment | D36: Accrual | E36: =I33-I17 -> -1.2344444 | K36: =ROUND(E36,4) -> -1.2344

Sheet CALCULATION
A1: Calculation
A2: Interest Rate | B2: =EOD!E2/100 -> 0
A3: InstrumentId | B3: =EOD!C2 -> 0
A4: Per Day Interest
A5: PostingDate | B5: =IF(EOD!A2="","",EOD!A2)
A6: Earliest Transaction Date | B6: =IF(MIN(REPLAY!B2:B42)=0,"",MIN(REPLAY!B2:B42))
A7: Count | B7: =IF(B6<>"",COUNT(REPLAY!A2:A29)+1,IF(TRANX!A2<>"",COUNT(TRANX!B2:B29),0)) -> 0
A8: Attribute ID | B8: =EOD!D2 -> 0
A10: REPLAY
A11: S.No | B11: Effective Date | C11: Accrual Break Date | D11: Accrual Break Days | E11: Effective End Days | F11: Beg UPB | G11: Adjustment Beg Air | H11: Beg AIR | I11: Draw | J11: Final Remit | K11: Interest Paid | L11: Principal Paid | M11: End UPB | N11: Accrual | O11: End AIR | P11: Helper Column
A12: 0 | B12: =IFERROR(IF(A12=0,EOMONTH($B$6,-1)+1,0),0) -> 0 | C12: =B13 | D12: =IF(B12="","",IF(B13="",1,(B13-B12))) -> 1 | E12: =IFERROR(DAY(B12),"") -> 0 | F12: =IFERROR(IF(B12="","",VLOOKUP($B$6,REPLAY!$B$2:$H$3,6,FALSE)),"") | G12: =IFERROR(IF(OR($B$13="",A12<>1),0,((F12*$B$2)/360)*D11),0) -> 0 | H12: =IFERROR(IF(B12="","",IF(B5="","",VLOOKUP($B$6,REPLAY!$B$2:$H$3,7,FALSE)+G12)),"") | I12: =IF(B12="","",SUMIF(REPLAY!$B$2:$F12,B12,REPLAY!$F$2:$F$13)) -> 0 | J12: =IF(B12="","",SUMIF(REPLAY!$B$2:$E$13,B12,REPLAY!$E$2:$E$13)) -> 0 | K12: =IF(B12="","",MIN(J12,H12)) -> 0 | L12: =IF(B12="","",MAX(J12-K12,0)) -> 0 | M12: =IFERROR(IF(B12="","",F12-L12+I12),0) -> 0 | N12: =IFERROR(IF($B$13="","",(M12*$B$2)/360),0) | O12: =IFERROR(IF(B12="","",H12-K12+(N12*D12)),0) -> 0 | P12: =IF(K12<>"",ROW(),0) -> 12 | S12: =O12+N12 -> #VALUE!
A13: 1 | B13: =IF(A13>$B$7,"",IF(A13=$B$7,EOMONTH($B$5,-1),REPLAY!B2)) | C13: =B14 | D13: =IF(B13="","",IF(B14="",1,(B14-B13))) | E13: =IFERROR(DAY(B13),"") | F13: =IFERROR(IF(B13="","",VLOOKUP(B13,REPLAY!$B$2:$H$3,6,FALSE)),"") | G13: =IFERROR(IF(OR($B$13="",A13<>1),0,((F13*$B$2)/360)*D12),0) -> 0 | H13: =IFERROR(IF(B13="","",IF(B6="","",VLOOKUP(B13,REPLAY!$B$2:$H$3,7,FALSE)+G13)),"") | I13: =IF(B13="","",SUMIF(REPLAY!$B$2:$F13,B13,REPLAY!$F$2:$F$13)) | J13: =IF(B13="","",SUMIF(REPLAY!$B$2:$E$13,B13,REPLAY!$E$2:$E$13)) | K13: =IF(B13="","",MIN(J13,H13)) | L13: =IF(B13="","",MAX(J13-K13,0)) | M13: =IFERROR(IF(B13="","",F13-L13+I13),0) | N13: =IFERROR(IF($B$13="","",(M13*$B$2)/360),0) | O13: =IFERROR(IF(B13="","",H13-K13+(N13*D13)),0) | P13: =IF(K13<>"",ROW(),0) -> 0
A14: 2 | B14: =IF(A14>$B$7,"",IF(A14=$B$7,EOMONTH($B$5,-1),REPLAY!B3)) | C14: =B15 | D14: =IF(B14="","",IF(B15="",1,(B15-B14))) | E14: =IFERROR(DAY(B14),"") | F14: =IF(B14="","",M13) | G14: =IFERROR(IF(OR($B$13="",A14<>1),0,((F14*$B$2)/360)*D13),0) -> 0 | H14: =IF(B14="","",O13) | I14: =IF(B14="","",SUMIF(REPLAY!$B$2:$EF14,B14,REPLAY!$F$2:$F$13)) | J14: =IF(B14="","",SUMIF(REPLAY!$B$2:$E$13,B14,REPLAY!$E$2:$E$13)) | K14: =IF(B14="","",MIN(J14,H14)) | L14: =IF(B14="","",MAX(J14-K14,0)) | M14: =IFERROR(IF(B14="","",F14-L14+I14),0) | N14: =IFERROR(IF(B14="","",(M14*$B$2)/360),0) | O14: =IFERROR(IF(B14="","",H14-K14+(N14*D14)),0) | P14: =IF(K14<>"",ROW(),0) -> 0
A15: 3 | B15: =IF(A15>$B$7,"",IF(A15=$B$7,EOMONTH($B$5,-1),REPLAY!B4)) | C15: =B16 | D15: =IF(B15="","",IF(B16="",1,(B16-B15))) | E15: =IFERROR(DAY(B15),"") | F15: =IF(B15="","",M14) | G15: =IFERROR(IF(OR($B$13="",A15<>1),0,((F15*$B$2)/360)*D14),0) -> 0 | H15: =IF(B15="","",O14) | I15: =IF(B15="","",SUMIF(REPLAY!$B$2:$EF15,B15,REPLAY!$F$2:$F$13)) | J15: =IF(B15="","",SUMIF(REPLAY!$B$2:$E$13,B15,REPLAY!$E$2:$E$13)) | K15: =IF(B15="","",MIN(J15,H15)) | L15: =IF(B15="","",MAX(J15-K15,0)) | M15: =IFERROR(IF(B15="","",F15-L15+I15),0) | N15: =IFERROR(IF(B15="","",(M15*$B$2)/360),0) | O15: =IFERROR(IF(B15="","",H15-K15+(N15*D15)),0) | P15: =IF(K15<>"",ROW(),0) -> 0
A16: 4 | B16: =IF(A16>$B$7,"",IF(A16=$B$7,EOMONTH($B$5,-1),REPLAY!B5)) | C16: =B17 | D16: =IF(B16="","",IF(B17="",1,(B17-B16))) | E16: =IFERROR(DAY(B16),"") | F16: =IF(B16="","",M15) | G16: =IFERROR(IF(OR($B$13="",A16<>1),0,((F16*$B$2)/360)*D15),0) -> 0 | H16: =IF(B16="","",O15) | I16: =IF(B16="","",SUMIF(REPLAY!$B$2:$EF16,B16,REPLAY!$F$2:$F$13)) | J16: =IF(B16="","",SUMIF(REPLAY!$B$2:$E$13,B16,REPLAY!$E$2:$E$13)) | K16: =IF(B16="","",MIN(J16,H16)) | L16: =IF(B16="","",MAX(J16-K16,0)) | M16: =IFERROR(IF(B16="","",F16-L16+I16),0) | N16: =IFERROR(IF(B16="","",(M16*$B$2)/360),0) | O16: =IFERROR(IF(B16="","",H16-K16+(N16*D16)),0) | P16: =IF(K16<>"",ROW(),0) -> 0
A17: 5 | B17: =IF(A17>$B$7,"",IF(A17=$B$7,EOMONTH($B$5,-1),REPLAY!B6)) | C17: =B18 | D17: =IF(B17="","",IF(B18="",1,(B18-B17))) | E17: =IFERROR(DAY(B17),"") | F17: =IF(B17="","",M16) | G17: =IFERROR(IF(OR($B$13="",A17<>1),0,((F17*$B$2)/360)*D16),0) -> 0 | H17: =IF(B17="","",O16) | I17: =IF(B17="","",SUMIF(REPLAY!$B$2:$EF17,B17,REPLAY!$F$2:$F$13)) | J17: =IF(B17="","",SUMIF(REPLAY!$B$2:$E$13,B17,REPLAY!$E$2:$E$13)) | K17: =IF(B17="","",MIN(J17,H17)) | L17: =IF(B17="","",MAX(J17-K17,0)) | M17: =IFERROR(IF(B17="","",F17-L17+I17),0) | N17: =IFERROR(IF(B17="","",(M17*$B$2)/360),0) | O17: =IFERROR(IF(B17="","",H17-K17+(N17*D17)),0) | P17: =IF(K17<>"",ROW(),0) -> 0
A18: 6 | B18: =IF(A18>$B$7,"",IF(A18=$B$7,EOMONTH($B$5,-1),REPLAY!B7)) | C18: =IFERROR(IF(MONTH(B18)<MONTH(B19),EOMONTH(B18,0),B19),B18) | D18: =IF(B18="","",IF(B19="",1,(B19-B18))) | E18: =IFERROR(DAY(B18),"") | F18: =IF(B18="","",M17) | G18: =IFERROR(IF(OR($B$13="",A18<>1),0,((F18*$B$2)/360)*D17),0) -> 0 | H18: =IF(B18="","",O17) | I18: =IF(B18="","",SUMIF(REPLAY!$B$2:$EF18,B18,REPLAY!$F$2:$F$13)) | J18: =IF(B18="","",SUMIF(REPLAY!$B$2:$E$13,B18,REPLAY!$E$2:$E$13)) | K18: =IF(B18="","",MIN(J18,H18)) | L18: =IF(B18="","",MAX(J18-K18,0)) | M18: =IFERROR(IF(B18="","",F18-L18+I18),0) | N18: =IFERROR(IF(B18="","",(M18*$B$2)/360),0) | O18: =IFERROR(IF(B18="","",H18-K18+(N18*D18)),0) | P18: =IF(K18<>"",ROW(),0) -> 0
A19: 7 | B19: =IF(A19>$B$7,"",IF(A19=$B$7,EOMONTH($B$5,-1),REPLAY!B8)) | C19: =IFERROR(IF(MONTH(B19)<MONTH(B20),EOMONTH(B19,0),B20),B19) | D19: =IF(B19="","",IF(B20="",1,(B20-B19))) | E19: =IFERROR(DAY(B19),"") | F19: =IF(B19="","",M18) | G19: =IFERROR(IF(OR($B$13="",A19<>1),0,((F19*$B$2)/360)*D18),0) -> 0 | H19: =IF(B19="","",O18) | I19: =IF(B19="","",SUMIF(REPLAY!$B$2:$EF19,B19,REPLAY!$F$2:$F$13)) | J19: =IF(B19="","",SUMIF(REPLAY!$B$2:$E$13,B19,REPLAY!$E$2:$E$13)) | K19: =IF(B19="","",MIN(J19,H19)) | L19: =IF(B19="","",MAX(J19-K19,0)) | M19: =IFERROR(IF(B19="","",F19-L19+I19),0) | N19: =IFERROR(IF(B19="","",(M19*$B$2)/360),0) | O19: =IFERROR(IF(B19="","",H19-K19+(N19*D19)),0) | P19: =IF(K19<>"",ROW(),0) -> 0
A20: 8 | B20: =IF(A20>$B$7,"",IF(A20=$B$7,EOMONTH($B$5,-1),REPLAY!B9)) | C20: =IFERROR(IF(MONTH(B20)<MONTH(B21),EOMONTH(B20,0),B21),B20) | D20: =IF(B20="","",IF(B21="",1,(B21-B20))) | E20: =IFERROR(DAY(B20),"") | F20: =IF(B20="","",M19) | G20: =IFERROR(IF(OR($B$13="",A20<>1),0,((F20*$B$2)/360)*D19),0) -> 0 | H20: =IF(B20="","",O19) | I20: =IF(B20="","",SUMIF(REPLAY!$B$2:$EF20,B20,REPLAY!$F$2:$F$13)) | J20: =IF(B20="","",SUMIF(REPLAY!$B$2:$E$13,B20,REPLAY!$E$2:$E$13)) | K20: =IF(B20="","",MIN(J20,H20)) | L20: =IF(B20="","",MAX(J20-K20,0)) | M20: =IFERROR(IF(B20="","",F20-L20+I20),0) | N20: =IFERROR(IF(B20="","",(M20*$B$2)/360),0) | O20: =IFERROR(IF(B20="","",H20-K20+(N20*D20)),0) | P20: =IF(K20<>"",ROW(),0) -> 0
A21: 9 | B21: =IF(A21>$B$7,"",IF(A21=$B$7,EOMONTH($B$5,-1),REPLAY!B10)) | C21: =IFERROR(IF(MONTH(B21)<MONTH(B22),EOMONTH(B21,0),B22),B21) | D21: =IF(B21="","",IF(B22="",1,(B22-B21))) | E21: =IFERROR(DAY(B21),"") | F21: =IF(B21="","",M20) | G21: =IFERROR(IF(OR($B$13="",A21<>1),0,((F21*$B$2)/360)*D20),0) -> 0 | H21: =IF(B21="","",O20) | I21: =IF(B21="","",SUMIF(REPLAY!$B$2:$EF21,B21,REPLAY!$F$2:$F$13)) | J21: =IF(B21="","",SUMIF(REPLAY!$B$2:$E$13,B21,REPLAY!$E$2:$E$13)) | K21: =IF(B21="","",MIN(J21,H21)) | L21: =IF(B21="","",MAX(J21-K21,0)) | M21: =IFERROR(IF(B21="","",F21-L21+I21),0) | N21: =IFERROR(IF(B21="","",(M21*$B$2)/360),0) | O21: =IFERROR(IF(B21="","",H21-K21+(N21*D21)),0) | P21: =IF(K21<>"",ROW(),0) -> 0
A22: 10 | B22: =IF(A22>$B$7,"",IF(A22=$B$7,EOMONTH($B$5,-1),REPLAY!B11)) | C22: =IFERROR(IF(MONTH(B22)<MONTH(B23),EOMONTH(B22,0),B23),B22) | D22: =IF(B22="","",IF(B23="",1,(B23-B22))) | E22: =IFERROR(DAY(B22),"") | F22: =IF(B22="","",M21) | G22: =IFERROR(IF(OR($B$13="",A22<>1),0,((F22*$B$2)/360)*D21),0) -> 0 | H22: =IF(B22="","",O21) | I22: =IF(B22="","",SUMIF(REPLAY!$B$2:$EF22,B22,REPLAY!$F$2:$F$13)) | J22: =IF(B22="","",SUMIF(REPLAY!$B$2:$E$13,B22,REPLAY!$E$2:$E$13)) | K22: =IF(B22="","",MIN(J22,H22)) | L22: =IF(B22="","",MAX(J22-K22,0)) | M22: =IFERROR(IF(B22="","",F22-L22+I22),0) | N22: =IFERROR(IF(B22="","",(M22*$B$2)/360),0) | O22: =IFERROR(IF(B22="","",H22-K22+(N22*D22)),0) | P22: =IF(K22<>"",ROW(),0) -> 0
A23: 11 | B23: =IF(A23>$B$7,"",IF(A23=$B$7,EOMONTH($B$5,-1),REPLAY!B12)) | C23: =IFERROR(IF(MONTH(B23)<MONTH(B24),EOMONTH(B23,0),B24),B23) | D23: =IF(B23="","",IF(B24="",1,(B24-B23))) | E23: =IFERROR(DAY(B23),"") | F23: =IF(B23="","",M22) | G23: =IFERROR(IF(OR($B$13="",A23<>1),0,((F23*$B$2)/360)*D22),0) -> 0 | H23: =IF(B23="","",O22) | I23: =IF(B23="","",SUMIF(REPLAY!$B$2:$EF23,B23,REPLAY!$F$2:$F$13)) | J23: =IF(B23="","",SUMIF(REPLAY!$B$2:$E$13,B23,REPLAY!$E$2:$E$13)) | K23: =IF(B23="","",MIN(J23,H23)) | L23: =IF(B23="","",MAX(J23-K23,0)) | M23: =IFERROR(IF(B23="","",F23-L23+I23),0) | N23: =IFERROR(IF(B23="","",(M23*$B$2)/360),0) | O23: =IFERROR(IF(B23="","",H23-K23+(N23*D23)),0) | P23: =IF(K23<>"",ROW(),0) -> 0
A24: 12 | B24: =IF(A24>$B$7,"",IF(A24=$B$7,EOMONTH($B$5,-1),REPLAY!B13)) | C24: =IFERROR(IF(MONTH(B24)<MONTH(B25),EOMONTH(B24,0),B25),B24) | D24: =IF(B24="","",IF(B25="",1,(B25-B24))) | E24: =IFERROR(DAY(B24),"") | F24: =IF(B24="","",M23) | G24: =IFERROR(IF(OR($B$13="",A24<>1),0,((F24*$B$2)/360)*D23),0) -> 0 | H24: =IF(B24="","",O23) | I24: =IF(B24="","",SUMIF(REPLAY!$B$2:$EF24,B24,REPLAY!$F$2:$F$13)) | J24: =IF(B24="","",SUMIF(REPLAY!$B$2:$E$13,B24,REPLAY!$E$2:$E$13)) | K24: =IF(B24="","",MIN(J24,H24)) | L24: =IF(B24="","",MAX(J24-K24,0)) | M24: =IFERROR(IF(B24="","",F24-L24+I24),0) | N24: =IFERROR(IF(B24="","",(M24*$B$2)/360),0) | O24: =IFERROR(IF(B24="","",H24-K24+(N24*D24)),0) | P24: =IF(K24<>"",ROW(),0) -> 0
K25: =IF( MAX(P13:P24) = 0, 0, INDEX(K13:K24, MATCH(MAX(P13:P24), P13:P24, 0)) ) -> 0 | L25: =IF( MAX(P13:P24) = 0, 0, INDEX(L13:L24, MATCH(MAX(P13:P24), P13:P24, 0)) ) -> 0 | M25: =IF( MAX(P13:P24) = 0, 0, INDEX(M13:M24, MATCH(MAX(P13:P24), P13:P24, 0)) ) -> 0 | O25: =IF( MAX(P13:P24) = 0, 0, INDEX(O13:O24, MATCH(MAX(P13:P24), P13:P24, 0)) ) -> 0
A26: Metric | B26: Current | C26: After Replay | D26: Adjutment
A27: UPB | B27: =IF(M25=0,0,EOD!F2) -> 0 | C27: =M25 -> 0 | D27: =C27-B27 -> 0
A28: AIR | B28: =IF(O25=0,0,EOD!G2) -> 0 | C28: =O25 -> 0 | D28: =C28-B28 -> 0
A31: IN ORDER
A32: S.No | B32: Effective Date | C32: Accrual Break Date | D32: Accrual Break Days | E32: Effective End Days | F32: Beg UPB | G32: Beg AIR | H32: Draw | I32: Final Remit | J32: Interest Paid | K32: Principal Paid | L32: Principal Adj | M32: Interest Adj | N32: End UPB | O32: Accrual | P32: Total Accrual | Q32: End AIR | R32: Helper Column | S32: Helper Column 2 | T32: Helper Column 3 | V32: Order | W32: Payment Helper
A33: 0 | B33: =IFERROR(IF(A33=0,EOMONTH($B$5,-1)+1,IF(A33>$B$7,"",IF(TRANX!$B$2="",CALCULATION!$B$5,VLOOKUP(A33,$V$33:$W$44,2,FALSE)))),"") | C33: =IFERROR(IF(OR(A33=$B$7,W33=""),EOMONTH(B33,0),B34),"") | D33: =IF(B33="","",IF(C33=EOMONTH(C33,0),C33-B33+1,C33-B33)) | E33: =IFERROR(DAY(B33),"") | F33: =IFERROR(IF(B33="","",VLOOKUP(B5,EOD!$B$2:$G$15,5,FALSE)),"") | G33: =IFERROR(IF(B33="","",VLOOKUP(B5,EOD!$B$2:$G$15,6,FALSE)),"") | H33: =IF(B33="","",SUMIF(TRANX!$B$2:$F$13,B33,TRANX!$F$2:$F$13)) | I33: =IF(B33="","",SUMIF(TRANX!$B$2:$E$13,B33,TRANX!$E$2:$E$13)) | J33: =IF(B33="","",MIN(I33,G33)) | K33: =IF(B33="","",MAX(I33-J33,0)) | L33: =IF(C33=$B$5,$D$27,0) -> 0 | M33: =IF(C33=$B$5,$D$28,0) -> 0 | N33: =IFERROR(IF(B33="","",F33-K33+H33+L33),0) | O33: =IFERROR(IF(B33="","",(N33*$B$2)/360),0) | P33: =IFERROR(IF(B33="","",O33*D33),0) | Q33: =IFERROR(IF(B33="","",G33-J33+M33+(O33*D33)),0) | R33: =IF(J33<>"",ROW(),0) -> 0 | S33: =IF(OR(J33=0,J33=""),0,1) -> 0 | T33: =IF(S33=0,0,B33) -> 0 | V33: =IF(W33="","",COUNTIF($W$33:$W$44,"<"&W33)+1) | W33: =IF(TRANX!B2="","",IF(TRANX!B2>EOMONTH($B$5,-1)+1,TRANX!B2,""))
A34: 1 | B34: =IFERROR(IF(A34=0,EOMONTH($B$5,-1)+1,IF(A34>$B$7,"",IF(TRANX!$B$2="",CALCULATION!$B$5,VLOOKUP(A34,$V$33:$W$44,2,FALSE)))),"") | C34: =IFERROR(IF(OR(A34=$B$7,W34=""),EOMONTH(B34,0),B35),"") | D34: =IF(B34="","",IF(C34=EOMONTH(C34,0),C34-B34+1,C34-B34)) | E34: =IFERROR(DAY(B34),"") | F34: =IF(B34="","",N33) | G34: =IF(B34="","",Q33) | H34: =IF(B34="","",SUMIF(TRANX!$B$2:$F$13,B34,TRANX!$F$2:$F$13)) | I34: =IF(B34="","",SUMIF(TRANX!$B$2:$E$13,B34,TRANX!$E$2:$E$13)) | J34: =IF(B34="","",MIN(I34,G34)) | K34: =IF(B34="","",MAX(I34-J34,0)) | L34: =IF(C34=$B$5,$D$27,0) -> 0 | M34: =IF(C34=$B$5,$D$28,0) -> 0 | N34: =IFERROR(IF(B34="","",F34-K34+H34+L34),0) | O34: =IFERROR(IF(B34="","",(N34*$B$2)/360),0) | P34: =IFERROR(IF(B34="","",O34*D34),0) | Q34: =IFERROR(IF(B34="","",G34-J34+M34+(O34*D34)),0) | R34: =IF(J34<>"",ROW(),0) -> 0 | S34: =IF(OR(J34=0,J34=""),0,1) -> 0 | T34: =IF(S34=0,0,B34) -> 0 | V34: =IF(W34="","",COUNTIF($W$33:$W$44,"<"&W34)+1) | W34: =IF(TRANX!B3="","",IF(TRANX!B3>EOMONTH($B$5,-1)+1,TRANX!B3,""))
A35: 2 | B35: =IFERROR(IF(A35=0,EOMONTH($B$5,-1)+1,IF(A35>$B$7,"",IF(TRANX!$B$2="",CALCULATION!$B$5,VLOOKUP(A35,$V$33:$W$44,2,FALSE)))),"") | C35: =IFERROR(IF(OR(A35=$B$7,W35=""),EOMONTH(B35,0),B36),"") | D35: =IF(B35="","",IF(C35=EOMONTH(C35,0),C35-B35+1,C35-B35)) | E35: =IFERROR(DAY(B35),"") | F35: =IF(B35="","",N34) | G35: =IF(B35="","",Q34) | H35: =IF(B35="","",SUMIF(TRANX!$B$2:$F$13,B35,TRANX!$F$2:$F$13)) | I35: =IF(B35="","",SUMIF(TRANX!$B$2:$E$13,B35,TRANX!$E$2:$E$13)) | J35: =IF(B35="","",MIN(I35,G35)) | K35: =IF(B35="","",MAX(I35-J35,0)) | L35: =IF(C35=$B$5,$D$27,0) -> 0 | M35: =IF(C35=$B$5,$D$28,0) -> 0 | N35: =IFERROR(IF(B35="","",F35-K35+H35+L35),0) | O35: =IFERROR(IF(B35="","",(N35*$B$2)/360),0) | P35: =IFERROR(IF(B35="","",O35*D35),0) | Q35: =IFERROR(IF(B35="","",G35-J35+M35+(O35*D35)),0) | R35: =IF(J35<>"",ROW(),0) -> 0 | S35: =IF(OR(J35=0,J35=""),0,1) -> 0 | T35: =IF(S35=0,0,B35) -> 0 | V35: =IF(W35="","",COUNTIF($W$33:$W$44,"<"&W35)+1) | W35: =IF(TRANX!B4="","",IF(TRANX!B4>EOMONTH($B$5,-1)+1,TRANX!B4,""))
A36: 3 | B36: =IFERROR(IF(A36=0,EOMONTH($B$5,-1)+1,IF(A36>$B$7,"",IF(TRANX!$B$2="",CALCULATION!$B$5,VLOOKUP(A36,$V$33:$W$44,2,FALSE)))),"") | C36: =IFERROR(IF(OR(A36=$B$7,W36=""),EOMONTH(B36,0),B37),"") | D36: =IF(B36="","",IF(C36=EOMONTH(C36,0),C36-B36+1,C36-B36)) | E36: =IFERROR(DAY(B36),"") | F36: =IF(B36="","",N35) | G36: =IF(B36="","",Q35) | H36: =IF(B36="","",SUMIF(TRANX!$B$2:$F$13,B36,TRANX!$F$2:$F$13)) | I36: =IF(B36="","",SUMIF(TRANX!$B$2:$E$13,B36,TRANX!$E$2:$E$13)) | J36: =IF(B36="","",MIN(I36,G36)) | K36: =IF(B36="","",MAX(I36-J36,0)) | L36: =IF(C36=$B$5,$D$27,0) -> 0 | M36: =IF(C36=$B$5,$D$28,0) -> 0 | N36: =IFERROR(IF(B36="","",F36-K36+H36+L36),0) | O36: =IFERROR(IF(B36="","",(N36*$B$2)/360),0) | Q36: =IFERROR(IF(B36="","",G36-J36+M36+(O36*D36)),0) | R36: =IF(J36<>"",ROW(),0) -> 0 | S36: =IF(OR(J36=0,J36=""),0,1) -> 0 | T36: =IF(S36=0,0,B36) -> 0 | V36: =IF(W36="","",COUNTIF($W$33:$W$44,"<"&W36)+1) | W36: =IF(TRANX!B5="","",IF(TRANX!B5>EOMONTH($B$5,-1)+1,TRANX!B5,""))
A37: 4 | B37: =IFERROR(IF(A37=0,EOMONTH($B$5,-1)+1,IF(A37>$B$7,"",IF(TRANX!$B$2="",CALCULATION!$B$5,VLOOKUP(A37,$V$33:$W$44,2,FALSE)))),"") | C37: =IFERROR(IF(OR(A37=$B$7,W37=""),EOMONTH(B37,0),B38),"") | D37: =IF(B37="","",IF(C37=EOMONTH(C37,0),C37-B37+1,C37-B37)) | E37: =IFERROR(DAY(B37),"") | F37: =IF(B37="","",N36) | G37: =IF(B37="","",Q36) | H37: =IF(B37="","",SUMIF(TRANX!$B$2:$F$13,B37,TRANX!$F$2:$F$13)) | I37: =IF(B37="","",SUMIF(TRANX!$B$2:$E$13,B37,TRANX!$E$2:$E$13)) | J37: =IF(B37="","",MIN(I37,G37)) | K37: =IF(B37="","",MAX(I37-J37,0)) | L37: =IF(C37=$B$5,$D$27,0) -> 0 | M37: =IF(C37=$B$5,$D$28,0) -> 0 | N37: =IFERROR(IF(B37="","",F37-K37+H37+L37),0) | O37: =IFERROR(IF(B37="","",(N37*$B$2)/360),0) | Q37: =IFERROR(IF(B37="","",G37-J37+M37+(O37*D37)),0) | R37: =IF(J37<>"",ROW(),0) -> 0 | S37: =IF(OR(J37=0,J37=""),0,1) -> 0 | T37: =IF(S37=0,0,B37) -> 0 | V37: =IF(W37="","",COUNTIF($W$33:$W$44,"<"&W37)+1) | W37: =IF(TRANX!B6="","",IF(TRANX!B6>EOMONTH($B$5,-1)+1,TRANX!B6,""))
A38: 5 | B38: =IFERROR(IF(A38=0,EOMONTH($B$5,-1)+1,IF(A38>$B$7,"",IF(TRANX!$B$2="",CALCULATION!$B$5,VLOOKUP(A38,$V$33:$W$44,2,FALSE)))),"") | C38: =IFERROR(IF(OR(A38=$B$7,W38=""),EOMONTH(B38,0),B39),"") | D38: =IF(B38="","",IF(C38=EOMONTH(C38,0),C38-B38+1,C38-B38)) | E38: =IFERROR(DAY(B38),"") | F38: =IF(B38="","",N37) | G38: =IF(B38="","",Q37) | H38: =IF(B38="","",SUMIF(TRANX!$B$2:$F$13,B38,TRANX!$F$2:$F$13)) | I38: =IF(B38="","",SUMIF(TRANX!$B$2:$E$13,B38,TRANX!$E$2:$E$13)) | J38: =IF(B38="","",MIN(I38,G38)) | K38: =IF(B38="","",MAX(I38-J38,0)) | L38: =IF(C38=$B$5,$D$27,0) -> 0 | M38: =IF(C38=$B$5,$D$28,0) -> 0 | N38: =IFERROR(IF(B38="","",F38-K38+H38+L38),0) | O38: =IFERROR(IF(B38="","",(N38*$B$2)/360),0) | Q38: =IFERROR(IF(B38="","",G38-J38+M38+(O38*D38)),0) | R38: =IF(J38<>"",ROW(),0) -> 0 | S38: =IF(OR(J38=0,J38=""),0,1) -> 0 | T38: =IF(S38=0,0,B38) -> 0 | V38: =IF(W38="","",COUNTIF($W$33:$W$44,"<"&W38)+1) | W38: =IF(TRANX!B7="","",IF(TRANX!B7>EOMONTH($B$5,-1)+1,TRANX!B7,""))
A39: 6 | B39: =IFERROR(IF(A39=0,EOMONTH($B$5,-1)+1,IF(A39>$B$7,"",IF(TRANX!$B$2="",CALCULATION!$B$5,VLOOKUP(A39,$V$33:$W$44,2,FALSE)))),"") | C39: =IFERROR(IF(OR(A39=$B$7,W39=""),EOMONTH(B39,0),B40),"") | D39: =IF(B39="","",IF(C39=EOMONTH(C39,0),C39-B39+1,C39-B39)) | E39: =IFERROR(DAY(B39),"") | F39: =IF(B39="","",N38) | G39: =IF(B39="","",Q38) | H39: =IF(B39="","",SUMIF(TRANX!$B$2:$F$13,B39,TRANX!$F$2:$F$13)) | I39: =IF(B39="","",SUMIF(TRANX!$B$2:$E$13,B39,TRANX!$E$2:$E$13)) | J39: =IF(B39="","",MIN(I39,G39)) | K39: =IF(B39="","",MAX(I39-J39,0)) | L39: =IF(C39=$B$5,$D$27,0) -> 0 | M39: =IF(C39=$B$5,$D$28,0) -> 0 | N39: =IFERROR(IF(B39="","",F39-K39+H39+L39),0) | O39: =IFERROR(IF(B39="","",(N39*$B$2)/360),0) | Q39: =IFERROR(IF(B39="","",G39-J39+M39+(O39*D39)),0) | R39: =IF(J39<>"",ROW(),0) -> 0 | S39: =IF(OR(J39=0,J39=""),0,1) -> 0 | T39: =IF(S39=0,0,B39) -> 0 | V39: =IF(W39="","",COUNTIF($W$33:$W$44,"<"&W39)+1) | W39: =IF(TRANX!B8="","",IF(TRANX!B8>EOMONTH($B$5,-1)+1,TRANX!B8,""))
A40: 7 | B40: =IFERROR(IF(A40=0,EOMONTH($B$5,-1)+1,IF(A40>$B$7,"",IF(TRANX!$B$2="",CALCULATION!$B$5,VLOOKUP(A40,$V$33:$W$44,2,FALSE)))),"") | C40: =IFERROR(IF(OR(A40=$B$7,W40=""),EOMONTH(B40,0),B41),"") | D40: =IF(B40="","",IF(C40=EOMONTH(C40,0),C40-B40+1,C40-B40)) | E40: =IFERROR(DAY(B40),"") | F40: =IF(B40="","",N39) | G40: =IF(B40="","",Q39) | H40: =IF(B40="","",SUMIF(TRANX!$B$2:$F$13,B40,TRANX!$F$2:$F$13)) | I40: =IF(B40="","",SUMIF(TRANX!$B$2:$E$13,B40,TRANX!$E$2:$E$13)) | J40: =IF(B40="","",MIN(I40,G40)) | K40: =IF(B40="","",MAX(I40-J40,0)) | L40: =IF(C40=$B$5,$D$27,0) -> 0 | M40: =IF(C40=$B$5,$D$28,0) -> 0 | N40: =IFERROR(IF(B40="","",F40-K40+H40+L40),0) | O40: =IFERROR(IF(B40="","",(N40*$B$2)/360),0) | Q40: =IFERROR(IF(B40="","",G40-J40+M40+(O40*D40)),0) | R40: =IF(J40<>"",ROW(),0) -> 0 | S40: =IF(OR(J40=0,J40=""),0,1) -> 0 | T40: =IF(S40=0,0,B40) -> 0 | V40: =IF(W40="","",COUNTIF($W$33:$W$44,"<"&W40)+1) | W40: =IF(TRANX!B9="","",IF(TRANX!B9>EOMONTH($B$5,-1)+1,TRANX!B9,""))
A41: 8 | B41: =IFERROR(IF(A41=0,EOMONTH($B$5,-1)+1,IF(A41>$B$7,"",IF(TRANX!$B$2="",CALCULATION!$B$5,VLOOKUP(A41,$V$33:$W$44,2,FALSE)))),"") | C41: =IFERROR(IF(OR(A41=$B$7,W41=""),EOMONTH(B41,0),B42),"") | D41: =IF(B41="","",IF(C41=EOMONTH(C41,0),C41-B41+1,C41-B41)) | E41: =IFERROR(DAY(B41),"") | F41: =IF(B41="","",N40) | G41: =IF(B41="","",Q40) | H41: =IF(B41="","",SUMIF(TRANX!$B$2:$F$13,B41,TRANX!$F$2:$F$13)) | I41: =IF(B41="","",SUMIF(TRANX!$B$2:$E$13,B41,TRANX!$E$2:$E$13)) | J41: =IF(B41="","",MIN(I41,G41)) | K41: =IF(B41="","",MAX(I41-J41,0)) | L41: =IF(C41=$B$5,$D$27,0) -> 0 | M41: =IF(C41=$B$5,$D$28,0) -> 0 | N41: =IFERROR(IF(B41="","",F41-K41+H41+L41),0) | O41: =IFERROR(IF(B41="","",(N41*$B$2)/360),0) | Q41: =IFERROR(IF(B41="","",G41-J41+M41+(O41*D41)),0) | R41: =IF(J41<>"",ROW(),0) -> 0 | S41: =IF(OR(J41=0,J41=""),0,1) -> 0 | T41: =IF(S41=0,0,B41) -> 0 | V41: =IF(W41="","",COUNTIF($W$33:$W$44,"<"&W41)+1) | W41: =IF(TRANX!B10="","",IF(TRANX!B10>EOMONTH($B$5,-1)+1,TRANX!B10,""))
A42: 9 | B42: =IFERROR(IF(A42=0,EOMONTH($B$5,-1)+1,IF(A42>$B$7,"",IF(TRANX!$B$2="",CALCULATION!$B$5,VLOOKUP(A42,$V$33:$W$44,2,FALSE)))),"") | C42: =IFERROR(IF(OR(A42=$B$7,W42=""),EOMONTH(B42,0),B43),"") | D42: =IF(B42="","",IF(C42=EOMONTH(C42,0),C42-B42+1,C42-B42)) | E42: =IFERROR(DAY(B42),"") | F42: =IF(B42="","",N41) | G42: =IF(B42="","",Q41) | H42: =IF(B42="","",SUMIF(TRANX!$B$2:$F$13,B42,TRANX!$F$2:$F$13)) | I42: =IF(B42="","",SUMIF(TRANX!$B$2:$E$13,B42,TRANX!$E$2:$E$13)) | J42: =IF(B42="","",MIN(I42,G42)) | K42: =IF(B42="","",MAX(I42-J42,0)) | L42: =IF(C42=$B$5,$D$27,0) -> 0 | M42: =IF(C42=$B$5,$D$28,0) -> 0 | N42: =IFERROR(IF(B42="","",F42-K42+H42+L42),0) | O42: =IFERROR(IF(B42="","",(N42*$B$2)/360),0) | Q42: =IFERROR(IF(B42="","",G42-J42+M42+(O42*D42)),0) | R42: =IF(J42<>"",ROW(),0) -> 0 | S42: =IF(OR(J42=0,J42=""),0,1) -> 0 | T42: =IF(S42=0,0,B42) -> 0 | V42: =IF(W42="","",COUNTIF($W$33:$W$44,"<"&W42)+1) | W42: =IF(TRANX!B11="","",IF(TRANX!B11>EOMONTH($B$5,-1)+1,TRANX!B11,""))
A43: 10 | B43: =IFERROR(IF(A43=0,EOMONTH($B$5,-1)+1,IF(A43>$B$7,"",IF(TRANX!$B$2="",CALCULATION!$B$5,VLOOKUP(A43,$V$33:$W$44,2,FALSE)))),"") | C43: =IFERROR(IF(OR(A43=$B$7,W43=""),EOMONTH(B43,0),B44),"") | D43: =IF(B43="","",IF(C43=EOMONTH(C43,0),C43-B43+1,C43-B43)) | E43: =IFERROR(DAY(B43),"") | F43: =IF(B43="","",N42) | G43: =IF(B43="","",Q42) | H43: =IF(B43="","",SUMIF(TRANX!$B$2:$F$13,B43,TRANX!$F$2:$F$13)) | I43: =IF(B43="","",SUMIF(TRANX!$B$2:$E$13,B43,TRANX!$E$2:$E$13)) | J43: =IF(B43="","",MIN(I43,G43)) | K43: =IF(B43="","",MAX(I43-J43,0)) | L43: =IF(C43=$B$5,$D$27,0) -> 0 | M43: =IF(C43=$B$5,$D$28,0) -> 0 | N43: =IFERROR(IF(B43="","",F43-K43+H43+L43),0) | O43: =IFERROR(IF(B43="","",(N43*$B$2)/360),0) | Q43: =IFERROR(IF(B43="","",G43-J43+M43+(O43*D43)),0) | R43: =IF(J43<>"",ROW(),0) -> 0 | S43: =IF(OR(J43=0,J43=""),0,1) -> 0 | T43: =IF(S43=0,0,B43) -> 0 | V43: =IF(W43="","",COUNTIF($W$33:$W$44,"<"&W43)+1) | W43: =IF(TRANX!B12="","",IF(TRANX!B12>EOMONTH($B$5,-1)+1,TRANX!B12,""))
...

Sheet o_Transaction
A1: PostingDate | B1: TransactionDate | C1: InstrumentId | D1: TransactionName | E1: Amount | F1: AttributeId
A2: =CALCULATION!A50 | B2: =CALCULATION!B50 | C2: =CALCULATION!C50 | D2: =CALCULATION!D50 | E2: =IF(D2="","",CALCULATION!E50) | F2: =CALCULATION!F50
A3: =CALCULATION!A51 | B3: =CALCULATION!B51 | C3: =CALCULATION!C51 | D3: =CALCULATION!D51 | E3: =IF(D3="","",CALCULATION!E51) | F3: =CALCULATION!F51
A4: =CALCULATION!A52 | B4: =CALCULATION!B52 | C4: =CALCULATION!C52 | D4: =CALCULATION!D52 | E4: =IF(D4="","",CALCULATION!E52) | F4: =CALCULATION!F52
A5: =CALCULATION!A53 | B5: =CALCULATION!B53 | C5: =CALCULATION!C53 | D5: =CALCULATION!D53 | E5: =IF(D5="","",CALCULATION!E53) | F5: =CALCULATION!F53
A6: =CALCULATION!A54 | B6: =CALCULATION!B54 | C6: =CALCULATION!C54 | D6: =CALCULATION!D54 | E6: =IF(D6="","",CALCULATION!E54) | F6: =CALCULATION!F54

Sheet Scenario2
A1: Transactions | H1: Balances | M1: Monthly NR | N1: =10/1200 -> 0.0083333333 | P1: 10 | Q1: =P1/100 -> 0.1 | R1: =Q1/360 -> 0.00027777778
A2: PD | B2: ED | C2: Transaction | D2: Component | E2: Amount | F2: Entry | G2: Days | H2: UPB | I2: AIR | M2: Daily NR | N2: =R1 -> 0.00027777778
A3: 44592 | B3: =A3 -> 44592 | C3: Purchase | D3: UPB | E3: 100000 | F3: New | H3: =E3 -> 100000 | I3: 0 | K3: =ROUND(E3,4) -> 100000
A4: 44592 | B4: =A4 -> 44592 | C4: Purchase | D4: Interest | E4: 100 | F4: New | H4: =E3 -> 100000 | I4: =E4 -> 100 | K4: =ROUND(E4,4) -> 100
A5: 44620 | B5: 44606 | C5: accrual | D5: Interest | E5: =H4*N2*G5 -> 388.88889 | F5: New | G5: 14 | H5: =H4 -> 100000 | I5: =I4+E5 -> 488.88889 | K5: =ROUND(E5,4) -> 388.8889
A6: 44620 | B6: 44607 | C6: Draw | D6: UPB | E6: 5000 | H6: =H4+E6 -> 105000 | I6: =I5 -> 488.88889 | K6: =ROUND(E6,4) -> 5000
A7: 44620 | B7: 44620 | C7: accrual | D7: Interest | E7: =H7*$N$2*G7 -> 408.33333 | F7: New | G7: 14 | H7: =H6 -> 105000 | I7: =I6+E7 -> 897.22222 | K7: =ROUND(E7,4) -> 408.3333
A8: 44651 | B8: 44634 | C8: accrual | D8: Interest | E8: =H8*$N$2*G8 -> 408.33333 | F8: New | G8: =B8-B7 -> 14 | H8: =H7 -> 105000 | I8: =I7+E8 -> 1305.5556 | K8: =ROUND(E8,4) -> 408.3333
A9: 44651 | B9: 44635 | C9: Remit | E9: 1500 | F9: New | H9: =H8 -> 105000 | I9: =I8 -> 1305.5556 | K9: =ROUND(E9,4) -> 1500
A10: 44651 | B10: 44635 | C10: Payment | D10: UPB | E10: =-(E11+E9) -> -194.44444 | F10: New | H10: =H9+E10 -> 104805.56 | I10: =I9 -> 1305.5556 | K10: =ROUND(E10,4) -> -194.4444
A11: 44651 | B11: 44635 | C11: Payment | D11: Interest | E11: =-MIN(I9,E9) -> -1305.5556 | F11: New | H11: =H10 -> 104805.56 | I11: =I10+E11 -> 0 | K11: =ROUND(E11,4) -> -1305.5556
A12: 44651 | B12: 44644 | C12: accrual | D12: Interest | E12: =H12*$N$2*G12 -> 291.12654 | F12: New | G12: =B13-B11 -> 10 | H12: =H11 -> 104805.56 | I12: =E12+I11 -> 291.12654 | K12: =ROUND(E12,4) -> 291.1265
A13: 44651 | B13: 44645 | C13: Draw | D13: UPB | E13: 7000 | F13: New | H13: =H12+E13 -> 111805.56 | I13: =I12 -> 291.12654 | K13: =ROUND(E13,4) -> 7000
A14: 44651 | B14: 44651 | C14: accrual | D14: Interest | E14: =H14*N2*G14 -> 217.39969 | F14: New | G14: =B14-B13+1 -> 7 | H14: =H13 -> 111805.56 | I14: =E14+I13 -> 508.52623 | K14: =ROUND(E14,4) -> 217.3997
A15: 44681 | B15: 44670 | C15: accrual | D15: Interest | E15: =H15*N2*G15 -> 590.08488 | F15: New | G15: =B15-B14 -> 19 | H15: =H14 -> 111805.56 | I15: =I14+E15 -> 1098.6111 | K15: =ROUND(E15,4) -> 590.0849
A16: 44681 | B16: 44671 | C16: Remit | E16: 2000 | F16: New | H16: =H15 -> 111805.56 | I16: =I15 -> 1098.6111 | K16: =ROUND(E16,4) -> 2000
A17: 44681 | B17: 44671 | C17: Payment | D17: UPB | E17: =-(E18+E16) -> -901.38889 | F17: New | H17: =H16+E17 -> 110904.17 | I17: =I16 -> 1098.6111 | K17: =ROUND(E17,4) -> -901.3889
A18: 44681 | B18: 44671 | C18: Payment | D18: Interest | E18: =-I17 -> -1098.6111 | F18: New | H18: =H17 -> 110904.17 | I18: =I17+E18 -> 0 | K18: =ROUND(E18,4) -> -1098.6111
A19: 44681 | B19: 44681 | C19: accrual | D19: Interest | E19: =H19*N2*G19 -> 338.87384 | F19: New | G19: 11 | H19: =H18 -> 110904.17 | I19: =I18+E19 -> 338.87384 | K19: =ROUND(E19,4) -> 338.8738
A20: 44712 | B20: =B5 -> 44606 | C20: accrual | D20: Interest | E20: =E5 -> 388.88889 | H20: =H4 -> 100000 | I20: =I4+E20 -> 488.88889 | K20: =ROUND(E20,4) -> 388.8889
A21: 44712 | B21: =B6 -> 44607 | C21: Draw | D21: UPB | E21: =E6 -> 5000 | H21: =H20+E21 -> 105000 | I21: =I20 -> 488.88889 | K21: =ROUND(E21,4) -> 5000
A22: 44712 | B22: 44613 | C22: accrual | D22: Interest | E22: =H22*N2*G22 -> 204.16667 | G22: 7 | H22: =H21 -> 105000 | I22: =I21+E22 -> 693.05556 | K22: =ROUND(E22,4) -> 204.1667
A23: 44712 | B23: 44614 | C23: Remit | E23: 400 | F23: New | G23: 22 | H23: =H7 -> 105000 | I23: =I22 -> 693.05556 | K23: =ROUND(E23,4) -> 400
A24: 44712 | B24: 44614 | C24: Payment | D24: UPB | E24: 0 | F24: New | H24: =H23 -> 105000 | I24: =I23 -> 693.05556 | K24: =ROUND(E24,4) -> 0
A25: 44712 | B25: 44614 | C25: Payment | D25: Interest | E25: =-MIN(E23,I23) -> -400 | F25: New | H25: =H24 -> 105000 | I25: =I23+E25 -> 293.05556 | K25: =ROUND(E25,4) -> -400
A26: 44712 | B26: 44620 | C26: accrual | D26: Interest | E26: =H26*N2*G26 -> 204.16667 | F26: New | G26: 7 | H26: =H25 -> 105000 | I26: =I25+E26 -> 497.22222 | K26: =ROUND(E26,4) -> 204.1667
A27: 44712 | B27: 44634 | C27: accrual | D27: Interest | E27: =H27*$N$2*G27 -> 408.33333 | G27: 14 | H27: =H26 -> 105000 | I27: =I26+E27 -> 905.55556 | K27: =ROUND(E27,4) -> 408.3333
A28: 44712 | B28: 44635 | C28: Remit | E28: =E9 -> 1500 | H28: =H27 -> 105000 | I28: =I27 -> 905.55556 | K28: =ROUND(E28,4) -> 1500
A29: 44712 | B29: 44635 | C29: Payment | D29: UPB | E29: =-(E30+E28) -> -594.44444 | H29: =H28+E29 -> 104405.56 | I29: =I28 -> 905.55556 | K29: =ROUND(E29,4) -> -594.4444
A30: 44712 | B30: 44635 | C30: Payment | D30: Interest | E30: =-I29 -> -905.55556 | H30: =H29 -> 104405.56 | I30: =I29+E30 -> 0 | K30: =ROUND(E30,4) -> -905.5556
A31: 44712 | B31: 44644 | C31: accrual | D31: Interest | E31: =H31*$N$2*G31 -> 290.01543 | G31: 10 | H31: =H30 -> 104405.56 | I31: =I30+E31 -> 290.01543 | K31: =ROUND(E31,4) -> 290.0154
A32: 44712 | B32: 44645 | C32: Draw | D32: UPB | E32: =E13 -> 7000 | H32: =H31+E32 -> 111405.56 | I32: =I31 -> 290.01543 | K32: =ROUND(E32,4) -> 7000
A33: 44712 | B33: 44651 | C33: accrual | D33: Interest | E33: =H33*$N$2*G33 -> 216.62191 | G33: 7 | H33: =H32 -> 111405.56 | I33: =I32+E33 -> 506.63735 | K33: =ROUND(E33,4) -> 216.6219
A34: 44712 | B34: 44670 | C34: accrual | D34: Interest | E34: =H34*$N$2*G34 -> 587.97377 | G34: 19 | H34: =H33 -> 111405.56 | I34: =I33+E34 -> 1094.6111 | K34: =ROUND(E34,4) -> 587.9738
A35: 44712 | B35: 44671 | C35: Remit | E35: =E16 -> 2000 | H35: =H34 -> 111405.56 | I35: =I34 -> 1094.6111 | K35: =ROUND(E35,4) -> 2000
A36: 44712 | B36: 44671 | C36: Payment | D36: UPB | E36: =-(E37+E35) -> -905.38889 | H36: =H35+E36 -> 110500.17 | I36: =I35 -> 1094.6111 | K36: =ROUND(E36,4) -> -905.3889
A37: 44712 | B37: 44671 | C37: Payment | D37: Interest | E37: =-I35 -> -1094.6111 | H37: =H36 -> 110500.17 | I37: =I36+E37 -> 0 | K37: =ROUND(E37,4) -> -1094.6111
A38: 44712 | B38: 44681 | C38: accrual | D38: Interest | E38: =H38*$N$2*G38 -> 337.6394 | G38: 11 | H38: =H37 -> 110500.17 | I38: =I37+E38 -> 337.6394 | K38: =ROUND(E38,4) -> 337.6394
A39: 44712 | B39: 44712 | C39: accrual | D39: Interest | E39: =H39*$N$2*G39 -> 951.52921 | G39: =B39-B38 -> 31 | H39: =H38 -> 110500.17 | I39: =I38+E39 -> 1289.1686 | K39: =ROUND(E39,4) -> 951.5292
A40: 44712 | B40: 44712 | C40: Adjustment | D40: UPB | E40: =H39-H19 -> -404 | K40: =ROUND(E40,4) -> -404
...

Sheet EXPECTED2
A1: INPUT
A3: REPLAY EVENT
A5: Posting Date | B5: Effective Date | C5: InstrumentId | D5: AttributeId | E5: TRANSACTIONS_AMOUNT_REMIT | F5: TRANSACTIONS_AMOUNT_DRAW | G5: BALANCES_BEGINNINGBALANCE_Unpaid_Principal_Balance | H5: BALANCES_BEGINNINGBALANCE_Accrued_Interest_Receivable
A6: 44712 | B6: 44607 | C6: L1 | D6: 1 | F6: 5000 | G6: 100000 | H6: 100
A7: 44712 | B7: 44614 | C7: L1 | D7: 1 | E7: 400
A8: 44712 | B8: 44635 | C8: L1 | D8: 1 | E8: 1500
A9: 44712 | B9: 44645 | C9: L1 | D9: 1 | F9: 7000
A10: 44712 | B10: 44671 | C10: L1 | D10: 1 | E10: 2000
A11: 44712 | B11: 44712 | C11: L1 | D11: 1
A13: PMT
A15: Posting Date | B15: Effective Date | C15: InstrumentId | D15: AttributeId | E15: TRANSACTIONS_AMOUNT_REMIT | F15: TRANSACTIONS_AMOUNT_DRAW
A16: 44620 | B16: 44607 | C16: L1 | D16: 1 | F16: 5000
A17: 44651 | B17: 44635 | C17: L1 | D17: 1 | E17: 1500
A18: 44651 | B18: 44645 | C18: L1 | D18: 1 | F18: 7000
A19: 44681 | B19: 44671 | C19: L1 | D19: 1 | E19: 2000
A20: 44712 | B20: 44614 | C20: L1 | D20: 1 | E20: 400
A22: INT_ACC
A24: Posting Date | B24: Effective Date | C24: InstrumentId | D24: AttributeId | E24: ATTRIBUTE_INTEREST_RATE_CURRENT | F24: BALANCES_BEGINNINGBALANCE_Unpaid_Principal_Balance | G24: BALANCES_BEGINNINGBALANCE_Accrued_Interest_Receivable
A25: 44620 | B25: 44620 | C25: L1 | D25: 1 | E25: 10 | F25: 100000 | G25: 100
A26: 44651 | B26: 44651 | C26: L1 | D26: 1 | E26: 10 | F26: 105000 | G26: 897.22222
A27: 44681 | B27: 44681 | C27: L1 | D27: 1 | E27: 10 | F27: 111805.56 | G27: 508.52623
A28: 44712 | B28: 44712 | C28: L1 | D28: 1 | E28: 10 | F28: 110904.17 | G28: 338.87384
A31: OUTPUT
A34: PostingDate | B34: TransactionDate | C34: InstrumentId | D34: TransactionName | E34: Amount | F34: AttributeId
A35: 20220131 | B35: 20220131 | C35: ARWK-RAAM | D35: PURCHASE_INTEREST | E35: 100 | F35: 1
A36: 20220131 | B36: 20220131 | C36: ARWK-RAAM | D36: PURCHASE_UPB | E36: 100000 | F36: 1
A37: 20220228 | B37: 20220215 | C37: ARWK-RAAM | D37: DRAW | E37: 5000 | F37: 1
A38: 20220228 | B38: 20220228 | C38: ARWK-RAAM | D38: SERVICING_INTEREST_ACCRUAL | E38: 797.2222 | F38: 1
A39: 20220331 | B39: 20220325 | C39: ARWK-RAAM | D39: DRAW | E39: 7000 | F39: 1
A40: 20220331 | B40: 20220315 | C40: ARWK-RAAM | D40: PAYMENT_INTEREST | E40: -1305.5556 | F40: 1
A41: 20220331 | B41: 20220315 | C41: ARWK-RAAM | D41: PAYMENT_UPB | E41: -194.4444 | F41: 1
A42: 20220331 | B42: 20220315 | C42: ARWK-RAAM | D42: REMIT | E42: 1500 | F42: 1
A43: 20220331 | B43: 20220331 | C43: ARWK-RAAM | D43: SERVICING_INTEREST_ACCRUAL | E43: 916.8595 | F43: 1
A44: 20220430 | B44: 20220420 | C44: ARWK-RAAM | D44: PAYMENT_INTEREST | E44: -1098.6111 | F44: 1
A45: 20220430 | B45: 20220420 | C45: ARWK-RAAM | D45: PAYMENT_UPB | E45: -901.3889 | F45: 1
A46: 20220430 | B46: 20220420 | C46: ARWK-RAAM | D46: REMIT | E46: 1500 | F46: 1
... A51: 20220531 | B51: 20220531 | C51: ARWK-RAAM | D51: SERVICING_INTEREST_ACCRUAL | E51: 951.5292 | F51: 1

Sheet Check
A1: Transactions | H1: Balances | M1: Monthly NR | N1: =10/1200 -> 0.0083333333 | P1: 10 | Q1: =P1/100 -> 0.1 | R1: =Q1/360 -> 0.00027777778
A2: PD | B2: ED | C2: Transaction | D2: Component | E2: Amount | F2: Entry | G2: Days | H2: UPB | I2: AIR | M2: Daily NR | N2: =R1 -> 0.00027777778
A3: 44592 | B3: =A3 -> 44592 | C3: Purchase | D3: UPB | E3: 100000 | F3: New | H3: =E3 -> 100000 | I3: 0
A4: 44592 | B4: =A4 -> 44592 | C4: Purchase | D4: Interest | E4: 100 | F4: New | H4: =E3 -> 100000 | I4: =E4 -> 100
A5: 44620 | B5: 44613 | C5: accrual | D5: Interest | E5: =H5*N2*G5 -> 583.33333 | F5: New | G5: 21 | H5: =H4 -> 100000 | I5: =E5+I4 -> 683.33333
A6: 44620 | B6: 44614 | C6: Remit | E6: 400 | F6: New | H6: =H5 -> 100000 | I6: =I5 -> 683.33333
A7: 44651 | B7: 44614 | C7: Payment | D7: Interest | E7: -400 | H7: =H6 -> 100000 | I7: =I6+E7 -> 283.33333
A8: 44620 | B8: 44620 | C8: accrual | D8: Interest | E8: =H8*$N$2*G8 -> 194.44444 | F8: New | G8: 7 | H8: =H4 -> 100000 | I8: =E8+I7 -> 477.77778
A9: 44651 | B9: 44634 | C9: accrual | D9: Interest | E9: =H9*$N$2*G9 -> 388.88889 | F9: New | G9: =B9-B8 -> 14 | H9: =H8 -> 100000 | I9: =I8+E9 -> 866.66667
A10: 44651 | B10: 44635 | C10: Remit | E10: 1500 | F10: New | H10: =H8 -> 100000 | I10: =I9 -> 866.66667
A11: 44651 | B11: 44635 | C11: Payment | D11: UPB | E11: =-(E12+E10) -> -633.33333 | F11: New | H11: =H10+E11 -> 99366.667 | I11: =I10 -> 866.66667
A12: 44651 | B12: 44635 | C12: Payment | D12: Interest | E12: =-MIN(I10,E10) -> -866.66667 | F12: New | H12: =H11 -> 99366.667 | I12: =I11+E12 -> 0
A13: 44651 | B13: 44644 | C13: accrual | D13: Interest | E13: =H13*$N$2*G13 -> 276.01852 | F13: New | G13: =B14-B12 -> 10 | H13: =H12 -> 99366.667 | I13: =E13+I12 -> 276.01852
A14: 44651 | B14: 44645 | C14: Draw | D14: UPB | E14: 7000 | F14: New | H14: =H13+E14 -> 106366.67 | I14: =I13 -> 276.01852
A15: 44651 | B15: 44651 | C15: accrual | D15: Interest | E15: =H15*N2*G15 -> 206.82407 | F15: New | G15: =B15-B14+1 -> 7 | H15: =H14 -> 106366.67 | I15: =E15+I14 -> 482.84259
A16: 44681 | B16: 44670 | C16: accrual | D16: Interest | E16: =H16*N2*G16 -> 561.37963 | F16: New | G16: =B16-B15 -> 19 | H16: =H15 -> 106366.67 | I16: =I15+E16 -> 1044.2222
A17: 44681 | B17: 44671 | C17: Remit | E17: 2000 | F17: New | H17: =H16 -> 106366.67 | I17: =I16 -> 1044.2222
A18: 44681 | B18: 44671 | C18: Payment | D18: UPB | E18: =-(E19+E17) -> -955.77778 | F18: New | H18: =H17+E18 -> 105410.89 | I18: =I17 -> 1044.2222
A19: 44681 | B19: 44671 | C19: Payment | D19: Interest | E19: =-I18 -> -1044.2222 | F19: New | H19: =H18 -> 105410.89 | I19: =I18+E19 -> 0
A20: 44681 | B20: 44681 | C20: accrual | D20: Interest | E20: =H20*N2*G20 -> 322.08883 | F20: New | G20: 11 | H20: =H19 -> 105410.89 | I20: =I19+E20 -> 322.08883
A21: 44712 | B21: 44712 | C21: accrual | D21: Interest | E21: =H21*N2*31 -> 907.70488 | F21: =F20 -> New | H21: =H20 -> 105410.89 | I21: =E21+I20 -> 1229.7937
