Workbook

Sheet Scenario
A1: Transactions | H1: Balances | M1: Monthly NR | N1: =10/1200 -> 0.0083333333 | P1: 10 | Q1: =P1/100 -> 0.1 | R1: =Q1/360 -> 0.00027777778
A2: PD | B2: ED | C2: Transaction | D2: Component | E2: Amount | F2: Entry | H2: UPB | I2: AIR | M2: Daily NR | N2: =R1 -> 0.00027777778
A3: 44592 | B3: =A3 -> 44592 | C3: Purchase | D3: UPB | E3: 100000 | F3: New | H3: =E3 -> 100000 | I3: 0
A4: 44592 | B4: =A4 -> 44592 | C4: Purchase | D4: Interest | E4: 100 | F4: New | H4: =E3 -> 100000 | I4: =E4 -> 100
A5: 44593 | B5: 44593 | C5: accrual | D5: Interest | E5: =H5*$N$2 -> 27.777778 | F5: New | H5: =H4 -> 100000 | I5: =I4+E5 -> 127.77778
A6: 44594 | B6: 44594 | C6: accrual | D6: Interest | E6: =H6*$N$2 -> 27.777778 | F6: New | H6: =H5 -> 100000 | I6: =I5+E6 -> 155.55556
A7: 44595 | B7: 44595 | C7: Remit | E7: 80 | F7: New | H7: =H6 -> 100000 | I7: =I6 -> 155.55556
A8: 44595 | B8: 44595 | C8: Payment | D8: UPB | E8: 0 | F8: New | H8: =H7+E8 -> 100000 | I8: =I7 -> 155.55556
A9: 44595 | B9: 44595 | C9: Payment | D9: Interest | E9: =-E7 -> -80 | F9: New | H9: =H7+E8 -> 100000 | I9: =I8+E9 -> 75.555556
A10: 44595 | B10: 44595 | C10: accrual | D10: Interest | E10: =H10*$N$2 -> 27.777778 | F10: New | H10: =H9 -> 100000 | I10: =E10+I9 -> 103.33333
A11: 44596 | B11: 44596 | C11: accrual | D11: Interest | E11: =ROUND(H10*N2,4) -> 27.7778 | F11: New | H11: =H10 -> 100000 | I11: =I10+E11 -> 131.11113
A12: 44597 | B12: 44597 | C12: Remit | E12: 275 | F12: New | H12: =H11 -> 100000 | I12: =I11 -> 131.11113
A13: 44597 | B13: 44597 | C13: Payment | D13: UPB | E13: =-(E12-I12) -> -143.88887 | F13: New | H13: =H12+E13 -> 99856.111 | I13: =I12 -> 131.11113
A14: 44597 | B14: 44597 | C14: Payment | D14: Interest | E14: =-I12 -> -131.11113 | F14: New | H14: =H13 -> 99856.111 | I14: =I13+E14 -> 0
A15: 44597 | B15: 44597 | C15: accrual | D15: Interest | E15: =H15*$N$2 -> 27.737809 | F15: New | H15: =H14 -> 99856.111 | I15: =E15 -> 27.737809
A16: 44598 | B16: 44598 | C16: Remit | E16: 350 | F16: New | H16: =H15 -> 99856.111 | I16: =I15 -> 27.737809
A17: 44598 | B17: 44598 | C17: Payment | D17: UPB | E17: =-(E16-I16) -> -322.26219 | F17: New | H17: =H16+E17 -> 99533.849 | I17: =I16 -> 27.737809
A18: 44598 | B18: 44598 | C18: Payment | D18: Interest | E18: =-I16 -> -27.737809 | F18: New | H18: =H17 -> 99533.849 | I18: =E18+I17 -> 0
A19: 44598 | B19: 44598 | C19: accrual | D19: Interest | E19: =H19*$N$2 -> 27.648291 | F19: New | H19: =H18 -> 99533.849 | I19: =E19 -> 27.648291
A20: 44599 | B20: 44599 | C20: accrual | D20: Interest | E20: =ROUND(H19*N2,4) -> 27.6483 | F20: New | H20: =H19 -> 99533.849 | I20: =I19+E20 -> 55.296591
A21: 44600 | B21: 44600 | C21: accrual | D21: Interest | E21: =E20 -> 27.6483 | F21: New | H21: =H20 -> 99533.849 | I21: =I20+E21 -> 82.944891
A22: 44601 | B22: 44595 | C22: accrual | D22: Interest | E22: =-E10 -> -27.777778 | F22: Reversal
A23: 44601 | B23: 44595 | C23: Remit | E23: =-E7 -> -80 | F23: Reversal
A24: 44601 | B24: 44595 | C24: Remit Reversal | E24: 30 | F24: New
A25: 44601 | B25: 44595 | C25: Payment | D25: UPB | E25: =-E8 -> 0 | F25: Reversal
A26: 44601 | B26: 44595 | C26: Payment | D26: Interest | E26: =-E9 -> 80 | F26: Reversal
A27: 44601 | B27: 44596 | C27: accrual | D27: Interest | E27: =-E11 -> -27.7778 | F27: Reversal
A28: 44601 | B28: 44597 | C28: accrual | D28: Interest | E28: =-E15 -> -27.737809 | F28: Reversal
A29: =A28 -> 44601 | B29: 44597 | C29: Remit | E29: =-E12 -> -275 | F29: Reversal
A30: =A29 -> 44601 | B30: 44597 | C30: Payment | D30: UPB | E30: =-E13 -> 143.88887 | F30: Reversal
A31: =A30 -> 44601 | B31: 44597 | C31: Payment | D31: Interest | E31: =-E14 -> 131.11113 | F31: Reversal
A32: 44601 | B32: 44598 | C32: accrual | D32: Interest | E32: =-E19 -> -27.648291 | F32: Reversal
A33: 44601 | B33: 44598 | C33: Remit | E33: =-E16 -> -350 | F33: Reversal
A34: 44601 | B34: 44598 | C34: Payment | D34: UPB | E34: =-E17 -> 322.26219 | F34: Reversal
A35: 44601 | B35: 44598 | C35: Payment | D35: Interest | E35: =-E18 -> 27.737809 | F35: Reversal
A36: 44601 | B36: 44599 | C36: accrual | D36: Interest | E36: =-E20 -> -27.6483 | F36: Reversal
A37: 44601 | B37: 44600 | C37: accrual | D37: Interest | E37: =-E21 -> -27.6483 | F37: Reversal | H37: =H21+E25+E34+E30 -> 100000 | I37: =I21+E26+E27+E28+E32+E35+E36+E37+E31+E22 -> 155.55556
A38: 44601 | B38: 44595 | C38: Payment | D38: Interest | E38: -50 | F38: Rebook | H38: =H37 -> 100000 | I38: =I37+E38 -> 105.55556
A39: 44601 | B39: 44595 | C39: accrual | D39: Interest | E39: =E40 -> 27.777778 | F39: Rebook | H39: =H37 -> 100000 | I39: =I38+E39 -> 133.33333
A40: 44601 | B40: 44596 | C40: accrual | D40: Interest | E40: =H37*N2 -> 27.777778 | F40: Rebook | H40: =H39 -> 100000 | I40: =I39+E40 -> 161.11111
...

Sheet PMT
A1: PostingDate | B1: EffectiveDate | C1: InstrumentId | D1: AttributeId | E1: TRANSACTIONS.AMOUNT.REMIT

Sheet INT_ACC
A1: PostingDate | B1: EffectiveDate | C1: InstrumentId | D1: AttributeId | E1: ATTRIBUTES.INTEREST_RATE.CURRENT | F1: BALANCES.BEGINNINGBALANCE.Unpaid_Principal_Balance | G1: BALANCES.BEGINNINGBALANCE.Accrued_Interest_Receivable | H1: BALANCES.BEGINNINGBALANCE.Servicing_Interest_Accrual

Sheet PMT_RP
A1: PostingDate | B1: EffectiveDate | C1: InstrumentId | D1: AttributeId | E1: TRANSACTIONS.AMOUNT.REMIT | F1: BALANCES.BEGINNINGBALANCE.Payment_UPB | G1: BALANCES.BEGINNINGBALANCE.Servicing_Interest_Accrual

Sheet Sample Data
A1: Replay Scenario | J1: PostingDate | K1: TransactionDate | L1: InstrumentId | M1: Transactiontype | N1: Amount | O1: AttributeId
A2: PMT_RP
A3: 45697 | B3: 45691 | C3: IDHJ-EGNY | D3: 1 | E3: 50 | F3: 0 | G3: 27.777778 | J3: 45697 | K3: 45697 | L3: IDHJ-EGNY | M3: Servicing_Interest_Accrual | N3: 27.6483 | O3: 1
A4: 45697 | B4: 45693 | C4: IDHJ-EGNY | D4: 1 | E4: 275 | F4: -143.88889 | G4: 27.737809 | J4: 45697 | K4: 45697 | L4: IDHJ-EGNY | M4: Interest_Adjustment | N4: 0.0333 | O4: 1
A5: 45697 | B5: 45694 | C5: IDHJ-EGNY | D5: 1 | E5: 350 | F5: -322.26219 | G5: 27.648291 | J5: 45697 | K5: 45697 | L5: IDHJ-EGNY | M5: Principal_Adjustment | N5: 30.0083 | O5: 1
A6: 45697 | B6: 45697 | C6: IDHJ-EGNY | D6: 1 | E6: 0 | F6: 0 | G6: 27.648291
A9: INT_ACC
A10: 45697 | B10: 45697 | C10: IDHJ-EGNY | D10: 1 | E10: 10 | F10: 99533.849 | G10: 82.944874 | H10: 321.79379
A13: PMT
A14: 45697 | B14: 45691 | C14: IDHJ-EGNY | D14: 1 | E14: -30
A16: OUT OF ORDER
A17: PMT_RP
A18: 45697 | B18: 45691 | C18: IDHJ-EGNY | D18: 1 | E18: 50 | F18: 0 | G18: 27.777778 | J18: 45697 | K18: 45697 | L18: IDHJ-EGNY | M18: Servicing_Interest_Accrual | N18: 27.7778 | O18: 1
A19: 45697 | B19: 45697 | C19: IDHJ-EGNY | D19: 1 | E19: 0 | F19: 0 | G19: 27.777778 | J19: 45697 | K19: 45697 | L19: IDHJ-EGNY | M19: Interest_Adjustment | N19: -50 | O19: 1
A22: INT_ACC
A23: 45697 | B23: 45697 | C23: IDHJ-EGNY | D23: 1 | E23: 10 | F23: 100000 | G23: 322.22222 | H23: 322.22222
A26: PMT
A27: 45697 | B27: 45691 | C27: IDHJ-EGNY | D27: 1 | E27: 50
A30: IN ORDER
A33: INT_ACC
A34: 45697 | B34: 45697 | C34: IDHJ-EGNY | D34: 1 | E34: 10 | F34: 100000 | G34: 322.22222 | H34: 322.22222 | J34: 45697 | K34: 45697 | L34: IDHJ-EGNY | M34: Servicing_Interest_Accrual | N34: 27.7562 | O34: 1
J36: 45697 | K36: 45697 | L36: IDHJ-EGNY | M36: Payment_Interest | N36: -322.2222 | O36: 1
A37: PMT | J37: 45697 | K37: 45697 | L37: IDHJ-EGNY | M37: Payment_UPB | N37: -77.7778 | O37: 1
A38: 45697 | B38: 45697 | C38: IDHJ-EGNY | D38: 1 | E38: 400

Sheet CALCULATION
A1: PAYMENT CALC
A2: Interest Rate | B2: =INT_ACC!E2/100 -> 0
A3: InstrumentId | B3: =INT_ACC!C2 -> 0
A4: PostingDate | B4: =IF(INT_ACC!A2="","",INT_ACC!A2)
A5: ReplayDate | B5: =IF(OR(MIN(PMT!$B$2:$B$13)=B4,MIN(PMT!$B$2:$B$13)=0),"",MIN(PMT!$B$2:$B$13))
A6: Beginning UPB Calc Replay | B6: =IF(B5<>"",C27-SUM(PMT_RP!$F$2:$F$13),"")
A7: Beginning AIR Calc Replay | B7: =IF(B5<>"",INT_ACC!$H$2-CALCULATION!D22,"")
A9: S.No | B9: Effective Date | C9: Days | D9: Beg Interest Calc | E9: Beg UPB | F9: Beg AIR | G9: Days | H9: Final Remit | I9: Interest Paid | J9: Principal Paid | K9: End UPB | L9: Accrual | M9: End AIR
A10: 1 | B10: =IFERROR(IF(AND(A10=$B$6,B9<>$B$4),$B$4,IF(MATCH(PMT!B2,PMT!B$2:'PMT'!B$100,0)=ROW(PMT!B2)-ROW(PMT!B$2)+1,PMT!B2,"")),"") | C10: =IF(B10="","",IF(B10=$B$4,0,B11-B10)) | D10: =IF(B10="","",VLOOKUP(B10,PMT_RP!$B$2:$G$13,6,FALSE)*C10) | E10: =IFERROR(IF(B10="","",IF(B5="",VLOOKUP(B10,INT_ACC!$B$2:$G$5,5,FALSE),$B$6)),"") | F10: =IFERROR(IF(B10="","",IF(B5="",VLOOKUP(B10,INT_ACC!$B$2:$G$5,6,FALSE),$B$7)),"") | G10: =IF(B10="","",IF(B11="",0,(B11-B10)-1)) | H10: =IF(B10="","",IF($B$5="",SUMIF(PMT!$B$2:$E$13,CALCULATION!B10,PMT!$E$2:$E$13),SUMIF(PMT_RP!$B$2:$E$10,CALCULATION!B10,PMT_RP!$E$2:$E$10))) | I10: =IF(B10="","",IF(H10<F10,H10,F10)) | J10: =IF(B10="","",H10-I10) | K10: =IFERROR(IF(B10="","",E10-J10),0) | L10: =IFERROR(IF(B10="","",(K10*$B$2)/360),0) | M10: =IFERROR(IF(B10="","",F10-I10+L10),0)
A11: 2 | B11: =IFERROR(IF(AND(A11=$B$6,B10<>$B$4),$B$4,IF(MATCH(PMT_RP!B3,PMT_RP!B$2:'PMT_RP'!B$97,0)=ROW(PMT_RP!B3)-ROW(PMT_RP!B$2)+1,PMT_RP!B3,"")),"") | C11: =IF(B11="","",IF(B11=$B$4,0,B12-B11)) | D11: =IF(B11="","",VLOOKUP(B11,PMT_RP!$B$2:$G$13,6,FALSE)*C11) | E11: =IF(B11="","",K10) | F11: =IF(B11="","",M10+(L10*G10)) | G11: =IF(B11="","",IF(B12="",0,(B12-B11)-1)) | H11: =IF(B11="","",IF($B$5="",SUMIF(PMT!$B$2:$E$13,CALCULATION!B11,PMT!$E$2:$E$13),SUMIF(PMT_RP!$B$2:$E$10,CALCULATION!B11,PMT_RP!$E$2:$E$10))) | I11: =IF(B11="","",IF(H11<F11,H11,F11)) | J11: =IF(B11="","",H11-I11) | K11: =IFERROR(IF(B11="","",E11-J11),0) | L11: =IFERROR(IF(B11="","",(K11*$B$2)/360),0) | M11: =IFERROR(IF(B11="","",F11-I11+L11),0)
A12: 3 | B12: =IFERROR(IF(AND(A12=$B$6,B11<>$B$4),$B$4,IF(MATCH(PMT_RP!B4,PMT_RP!B$2:'PMT_RP'!B$97,0)=ROW(PMT_RP!B4)-ROW(PMT_RP!B$2)+1,PMT_RP!B4,"")),"") | C12: =IF(B12="","",IF(B12=$B$4,0,B13-B12)) | D12: =IF(B12="","",VLOOKUP(B12,PMT_RP!$B$2:$G$13,6,FALSE)*C12) | E12: =IF(B12="","",K11) | F12: =IF(B12="","",M11+(L11*G11)) | G12: =IF(B12="","",IF(B13="",0,(B13-B12)-1)) | H12: =IF(B12="","",IF($B$5="",SUMIF(PMT!$B$2:$E$13,CALCULATION!B12,PMT!$E$2:$E$13),SUMIF(PMT_RP!$B$2:$E$10,CALCULATION!B12,PMT_RP!$E$2:$E$10))) | I12: =IF(B12="","",IF(H12<F12,H12,F12)) | J12: =IF(B12="","",H12-I12) | K12: =IFERROR(IF(B12="","",E12-J12),0) | L12: =IFERROR(IF(B12="","",(K12*$B$2)/360),0) | M12: =IFERROR(IF(B12="","",F12-I12+L12),0)
A13: 4 | B13: =IFERROR(IF(AND(A13=$B$6,B12<>$B$4),$B$4,IF(MATCH(PMT_RP!B5,PMT_RP!B$2:'PMT_RP'!B$97,0)=ROW(PMT_RP!B5)-ROW(PMT_RP!B$2)+1,PMT_RP!B5,"")),"") | C13: =IF(B13="","",IF(B13=$B$4,0,B14-B13)) | D13: =IF(B13="","",VLOOKUP(B13,PMT_RP!$B$2:$G$13,6,FALSE)*C13) | E13: =IF(B13="","",K12) | F13: =IF(B13="","",M12+(L12*G12)) | G13: =IF(B13="","",IF(B14="",0,(B14-B13)-1)) | H13: =IF(B13="","",IF($B$5="",SUMIF(PMT!$B$2:$E$13,CALCULATION!B13,PMT!$E$2:$E$13),SUMIF(PMT_RP!$B$2:$E$10,CALCULATION!B13,PMT_RP!$E$2:$E$10))) | I13: =IF(B13="","",IF(H13<F13,H13,F13)) | J13: =IF(B13="","",H13-I13) | K13: =IFERROR(IF(B13="","",E13-J13),0) | L13: =IFERROR(IF(B13="","",(K13*$B$2)/360),0) | M13: =IFERROR(IF(B13="","",F13-I13+L13),0)
A14: 5 | B14: =IFERROR(IF(AND(A14=$B$6,B13<>$B$4),$B$4,IF(MATCH(PMT_RP!B6,PMT_RP!B$2:'PMT_RP'!B$97,0)=ROW(PMT_RP!B6)-ROW(PMT_RP!B$2)+1,PMT_RP!B6,"")),"") | C14: =IF(B14="","",IF(B14=$B$4,0,B15-B14)) | D14: =IF(B14="","",VLOOKUP(B14,PMT_RP!$B$2:$G$13,6,FALSE)*C14) | E14: =IF(B14="","",K13) | F14: =IF(B14="","",M13+(L13*G13)) | G14: =IF(B14="","",IF(B15="",0,(B15-B14)-1)) | H14: =IF(B14="","",IF($B$5="",SUMIF(PMT!$B$2:$E$13,CALCULATION!B14,PMT!$E$2:$E$13),SUMIF(PMT_RP!$B$2:$E$10,CALCULATION!B14,PMT_RP!$E$2:$E$10))) | I14: =IF(B14="","",IF(H14<F14,H14,F14)) | J14: =IF(B14="","",H14-I14) | K14: =IFERROR(IF(B14="","",E14-J14),0) | L14: =IFERROR(IF(B14="","",(K14*$B$2)/360),0) | M14: =IFERROR(IF(B14="","",F14-I14+L14),0)
A15: 6 | B15: =IFERROR(IF(AND(A15=$B$6,B14<>$B$4),$B$4,IF(MATCH(PMT_RP!B7,PMT_RP!B$2:'PMT_RP'!B$97,0)=ROW(PMT_RP!B7)-ROW(PMT_RP!B$2)+1,PMT_RP!B7,"")),"") | C15: =IF(B15="","",IF(B15=$B$4,0,B16-B15)) | D15: =IF(B15="","",VLOOKUP(B15,PMT_RP!$B$2:$G$13,6,FALSE)*C15) | E15: =IF(B15="","",K14) | F15: =IF(B15="","",M14+(L14*G14)) | G15: =IF(B15="","",IF(B16="",0,(B16-B15)-1)) | H15: =IF(B15="","",IF($B$5="",SUMIF(PMT!$B$2:$E$13,CALCULATION!B15,PMT!$E$2:$E$13),SUMIF(PMT_RP!$B$2:$E$10,CALCULATION!B15,PMT_RP!$E$2:$E$10))) | I15: =IF(B15="","",IF(H15<F15,H15,F15)) | J15: =IF(B15="","",H15-I15) | K15: =IFERROR(IF(B15="","",E15-J15),0) | L15: =IFERROR(IF(B15="","",(K15*$B$2)/360),0) | M15: =IFERROR(IF(B15="","",F15-I15+L15),0)
A16: 7 | B16: =IFERROR(IF(AND(A16=$B$6,B15<>$B$4),$B$4,IF(MATCH(PMT_RP!B8,PMT_RP!B$2:'PMT_RP'!B$97,0)=ROW(PMT_RP!B8)-ROW(PMT_RP!B$2)+1,PMT_RP!B8,"")),"") | C16: =IF(B16="","",IF(B16=$B$4,0,B17-B16)) | D16: =IF(B16="","",VLOOKUP(B16,PMT_RP!$B$2:$G$13,6,FALSE)*C16) | E16: =IF(B16="","",K15) | F16: =IF(B16="","",M15+(L15*G15)) | G16: =IF(B16="","",IF(B17="",0,(B17-B16)-1)) | H16: =IF(B16="","",IF($B$5="",SUMIF(PMT!$B$2:$E$13,CALCULATION!B16,PMT!$E$2:$E$13),SUMIF(PMT_RP!$B$2:$E$10,CALCULATION!B16,PMT_RP!$E$2:$E$10))) | I16: =IF(B16="","",IF(H16<F16,H16,F16)) | J16: =IF(B16="","",H16-I16) | K16: =IFERROR(IF(B16="","",E16-J16),0) | L16: =IFERROR(IF(B16="","",(K16*$B$2)/360),0) | M16: =IFERROR(IF(B16="","",F16-I16+L16),0)
A17: 8 | B17: =IFERROR(IF(AND(A17=$B$6,B16<>$B$4),$B$4,IF(MATCH(PMT_RP!B9,PMT_RP!B$2:'PMT_RP'!B$97,0)=ROW(PMT_RP!B9)-ROW(PMT_RP!B$2)+1,PMT_RP!B9,"")),"") | C17: =IF(B17="","",IF(B17=$B$4,0,B18-B17)) | D17: =IF(B17="","",VLOOKUP(B17,PMT_RP!$B$2:$G$13,6,FALSE)*C17) | E17: =IF(B17="","",K16) | F17: =IF(B17="","",M16+(L16*G16)) | G17: =IF(B17="","",IF(B18="",0,(B18-B17)-1)) | H17: =IF(B17="","",IF($B$5="",SUMIF(PMT!$B$2:$E$13,CALCULATION!B17,PMT!$E$2:$E$13),SUMIF(PMT_RP!$B$2:$E$10,CALCULATION!B17,PMT_RP!$E$2:$E$10))) | I17: =IF(B17="","",IF(H17<F17,H17,F17)) | J17: =IF(B17="","",H17-I17) | K17: =IFERROR(IF(B17="","",E17-J17),0) | L17: =IFERROR(IF(B17="","",(K17*$B$2)/360),0) | M17: =IFERROR(IF(B17="","",F17-I17+L17),0) | O17: =IFERROR(IF(AND(A17=$B$6,B16<>$B$4),$B$4,IF(MATCH(PMT!B9,PMT!B$2:'PMT'!B$100,0)=ROW(PMT!B9)-ROW(PMT!B$2)+1,PMT!B9,"")),"") | P17: =IFERROR(SMALL($O$10:$O$13,A17),"")
A18: 9 | B18: =IFERROR(IF(AND(A18=$B$6,B17<>$B$4),$B$4,IF(MATCH(PMT_RP!B10,PMT_RP!B$2:'PMT_RP'!B$97,0)=ROW(PMT_RP!B10)-ROW(PMT_RP!B$2)+1,PMT_RP!B10,"")),"") | C18: =IF(B18="","",IF(B18=$B$4,0,B19-B18)) | D18: =IF(B18="","",VLOOKUP(B18,PMT_RP!$B$2:$G$13,6,FALSE)*C18) | E18: =IF(B18="","",K17) | F18: =IF(B18="","",M17+(L17*G17)) | G18: =IF(B18="","",IF(B19="",0,(B19-B18)-1)) | H18: =IF(B18="","",IF($B$5="",SUMIF(PMT!$B$2:$E$13,CALCULATION!B18,PMT!$E$2:$E$13),SUMIF(PMT_RP!$B$2:$E$10,CALCULATION!B18,PMT_RP!$E$2:$E$10))) | I18: =IF(B18="","",IF(H18<F18,H18,F18)) | J18: =IF(B18="","",H18-I18) | K18: =IFERROR(IF(B18="","",E18-J18),0) | L18: =IFERROR(IF(B18="","",(K18*$B$2)/360),0) | M18: =IFERROR(IF(B18="","",F18-I18+L18),0) | O18: =IFERROR(IF(AND(A18=$B$6,B17<>$B$4),$B$4,IF(MATCH(PMT!B10,PMT!B$2:'PMT'!B$100,0)=ROW(PMT!B10)-ROW(PMT!B$2)+1,PMT!B10,"")),"") | P18: =IFERROR(SMALL($O$10:$O$13,A18),"")
A19: 10 | B19: =IFERROR(IF(AND(A19=$B$6,B18<>$B$4),$B$4,IF(MATCH(PMT_RP!B11,PMT_RP!B$2:'PMT_RP'!B$97,0)=ROW(PMT_RP!B11)-ROW(PMT_RP!B$2)+1,PMT_RP!B11,"")),"") | C19: =IF(B19="","",IF(B19=$B$4,0,B20-B19)) | D19: =IF(B19="","",VLOOKUP(B19,PMT_RP!$B$2:$G$13,6,FALSE)*C19) | E19: =IF(B19="","",K18) | F19: =IF(B19="","",M18+(L18*G18)) | G19: =IF(B19="","",IF(B20="",0,(B20-B19)-1)) | H19: =IF(B19="","",IF($B$5="",SUMIF(PMT!$B$2:$E$13,CALCULATION!B19,PMT!$E$2:$E$13),SUMIF(PMT_RP!$B$2:$E$10,CALCULATION!B19,PMT_RP!$E$2:$E$10))) | I19: =IF(B19="","",IF(H19<F19,H19,F19)) | J19: =IF(B19="","",H19-I19) | K19: =IFERROR(IF(B19="","",E19-J19),0) | L19: =IFERROR(IF(B19="","",(K19*$B$2)/360),0) | M19: =IFERROR(IF(B19="","",F19-I19+L19),0) | O19: =IFERROR(IF(AND(A19=$B$6,B18<>$B$4),$B$4,IF(MATCH(PMT!B11,PMT!B$2:'PMT'!B$100,0)=ROW(PMT!B11)-ROW(PMT!B$2)+1,PMT!B11,"")),"") | P19: =IFERROR(SMALL($O$10:$O$13,A19),"")
A20: 11 | B20: =IFERROR(IF(AND(A20=$B$6,B19<>$B$4),$B$4,IF(MATCH(PMT_RP!B12,PMT_RP!B$2:'PMT_RP'!B$97,0)=ROW(PMT_RP!B12)-ROW(PMT_RP!B$2)+1,PMT_RP!B12,"")),"") | C20: =IF(B20="","",IF(B20=$B$4,0,B21-B20)) | D20: =IF(B20="","",VLOOKUP(B20,PMT_RP!$B$2:$G$13,6,FALSE)*C20) | E20: =IF(B20="","",K19) | F20: =IF(B20="","",M19+(L19*G19)) | G20: =IF(B20="","",IF(B21="",0,(B21-B20)-1)) | H20: =IF(B20="","",IF($B$5="",SUMIF(PMT!$B$2:$E$13,CALCULATION!B20,PMT!$E$2:$E$13),SUMIF(PMT_RP!$B$2:$E$10,CALCULATION!B20,PMT_RP!$E$2:$E$10))) | I20: =IF(B20="","",IF(H20<F20,H20,F20)) | J20: =IF(B20="","",H20-I20) | K20: =IFERROR(IF(B20="","",E20-J20),0) | L20: =IFERROR(IF(B20="","",(K20*$B$2)/360),0) | M20: =IFERROR(IF(B20="","",F20-I20+L20),0) | O20: =IFERROR(IF(AND(A20=$B$6,B19<>$B$4),$B$4,IF(MATCH(PMT!B12,PMT!B$2:'PMT'!B$100,0)=ROW(PMT!B12)-ROW(PMT!B$2)+1,PMT!B12,"")),"") | P20: =IFERROR(SMALL($O$10:$O$13,A20),"")
A21: 12 | B21: =IFERROR(IF(AND(A21=$B$6,B20<>$B$4),$B$4,IF(MATCH(PMT_RP!B13,PMT_RP!B$2:'PMT_RP'!B$97,0)=ROW(PMT_RP!B13)-ROW(PMT_RP!B$2)+1,PMT_RP!B13,"")),"") | C21: =IF(B21="","",IF(B21=$B$4,0,B22-B21)) | D21: =IF(B21="","",VLOOKUP(B21,PMT_RP!$B$2:$G$13,6,FALSE)*C21) | E21: =IF(B21="","",K20) | F21: =IF(B21="","",M20+(L20*G20)) | G21: =IF(B21="","",IF(B22="",0,(B22-B21)-1)) | H21: =IF(B21="","",IF($B$5="",SUMIF(PMT!$B$2:$E$13,CALCULATION!B21,PMT!$E$2:$E$13),SUMIF(PMT_RP!$B$2:$E$10,CALCULATION!B21,PMT_RP!$E$2:$E$10))) | I21: =IF(B21="","",IF(H21<F21,H21,F21)) | J21: =IF(B21="","",H21-I21) | K21: =IFERROR(IF(B21="","",E21-J21),0) | L21: =IFERROR(IF(B21="","",(K21*$B$2)/360),0) | M21: =IFERROR(IF(B21="","",F21-I21+L21),0) | O21: =IFERROR(IF(AND(A21=$B$6,B20<>$B$4),$B$4,IF(MATCH(PMT!B13,PMT!B$2:'PMT'!B$100,0)=ROW(PMT!B13)-ROW(PMT!B$2)+1,PMT!B13,"")),"") | P21: =IFERROR(SMALL($O$10:$O$13,A21),"")
D22: =IFERROR(SUM(D10:D21),"") -> 0 | H22: {=IFERROR(LOOKUP(2, 1/(I10:I21<>""), I10:I21),0)} -> 0 | I22: {=IFERROR(LOOKUP(2, 1/(J10:J21<>""), J10:J21),0)} -> 0 | J22: {=IFERROR(LOOKUP(2,1/(K10:K21<>""),K10:K21),0)} -> 0 | L22: {=IFERROR(LOOKUP(2, 1/(M10:M21<>""), M10:M21),0)} -> 0
A25: ACCRUAL CALC
A26: S.No | B26: Effective Date | C26: Beg UPB | D26: Beg AIR | E26: Days | F26: Final Remit | G26: Interest Paid | H26: Principal Paid | I26: End UPB | J26: Accrual | K26: End AIR
A27: 1 | B27: =IF(INT_ACC!B2="","",INT_ACC!B2) | C27: =INT_ACC!F2 -> 0 | D27: =INT_ACC!G2 -> 0 | E27: =IF(B27="","",IF(B28="",0,(B28-B27)-1)) | F27: 0 | G27: =H22 -> 0 | H27: =I22 -> 0 | I27: =C27-H27 -> 0 | J27: =IF(B27="",0,(I27*$B$2)/360) -> 0 | K27: =D27+J27-G27 -> 0
A29: AIR Transactions
A30: Interest Accrual | B30: =J27 -> 0
A31: Interest Adjustment | B31: =IF(E10="",0,L22-K27) -> 0
A32: Interest Payment | B32: =H22 -> 0
A35: UPB Transactions
A36: Principal Payment | B36: =I22 -> 0
A37: Principal Adjustment | B37: =IF(E10="",0,J22-I27) -> 0
A39: Transactions
A40: PostingDate | B40: TransactionDate | C40: InstrumentId | D40: Transactiontype | E40: Amount | F40: AttributeId
A41: =B4 | B41: =A41 | C41: =IF(A41="","",$B$3) | D41: =IF(A41="","","Servicing_Interest_Accrual") | E41: =IF(A41="","",ROUND(B30,4)) | F41: =IF(A41="","","1")
A42: =IF(ROUND(B31,4)=0,"",$B$4) | B42: =IF(A42="","",A42) | C42: =IF(A42="","",$B$3) | D42: =IF(A42="","","Interest_Adjustment") | E42: =IF(A42="","",ROUND(B31,4)) | F42: =IF(A42="","","1")
A43: =IF(ROUND(B32,4)=0,"",$B$4) | B43: =IF(A43="","",A43) | C43: =IF(A43="","",$B$3) | D43: =IF(A43="","","Payment_Interest") | E43: =IF(A43="","",ROUND(B32,4)*-1) | F43: =IF(A43="","","1")
A44: =IF(ROUND(B36,4)=0,"",$B$4) | B44: =IF(A44="","",A44) | C44: =IF(A44="","",$B$3) | D44: =IF(A44="","","Payment_UPB") | E44: =IF(A44="","",ROUND(B36,4)*-1) | F44: =IF(A44="","","1")
A45: =IF(ROUND(B37,4)=0,"",$B$4) | B45: =IF(A45="","",A45) | C45: =IF(A45="","",$B$3) | D45: =IF(A45="","","Principal_Adjustment") | E45: =IF(A45="","",ROUND(B37,4)) | F45: =IF(A45="","","1")

Sheet Events
A1: INT_ACC
A3: Trigger Type
A4: ON MODEL EXECUTION
A6: Source Mapping
A7: Balances | B7: BEGINNINGBALANCE | C7: UPB,AIR,ACCRUAL
A8: Attribute | B8: NoteRate | C8: Current
A11: PMT
A13: Trigger Type | B13: Trigger Source
A14: ON TRANSACTION POST | B14: Remit
A17: Source Mapping
A18: Transactions | B18: Amount | C18: Remit
A20: PMT_RP
A21: Trigger Type | B21: Trigger Source
A22: ON REPLAY | B22: Remit
A24: Source Mapping
A25: Transactions | B25: Amount | C25: Remit, Payment-UPB,Servicing-Accrued-Interest

Sheet o_Transaction
A1: PostingDate | B1: TransactionDate | C1: InstrumentId | D1: Transactiontype | E1: Amount | F1: AttributeId
A2: =CALCULATION!A41 | B2: =CALCULATION!B41 | C2: =CALCULATION!C41 | D2: =CALCULATION!D41 | E2: =CALCULATION!E41 | F2: =CALCULATION!F41
A3: =CALCULATION!A42 | B3: =CALCULATION!B42 | C3: =CALCULATION!C42 | D3: =CALCULATION!D42 | E3: =CALCULATION!E42 | F3: =CALCULATION!F42
A4: =CALCULATION!A43 | B4: =CALCULATION!B43 | C4: =CALCULATION!C43 | D4: =CALCULATION!D43 | E4: =CALCULATION!E43 | F4: =CALCULATION!F43
A5: =CALCULATION!A44 | B5: =CALCULATION!B44 | C5: =CALCULATION!C44 | D5: =CALCULATION!D44 | E5: =CALCULATION!E44 | F5: =CALCULATION!F44
A6: =CALCULATION!A45 | B6: =CALCULATION!B45 | C6: =CALCULATION!C45 | D6: =CALCULATION!D45 | E6: =CALCULATION!E45 | F6: =CALCULATION!F45

Sheet Example_worsheet_check
Q1: 0.1
A5: Principal | H5: Interest | P5: Principal | W5: Interest
A6: PostingDate | B6: Metric | C6: BeginningBalance | D6: Remit | E6: Activity | F6: EndingBalance | H6: PostingDate | I6: Metric | J6: BeginningBalance | K6: Activity | L6: Interest Payment | M6: EndingBalance | P6: PostingDate | Q6: Metric | R6: BeginningBalance | S6: Remit | T6: Activity | U6: EndingBalance | W6: PostingDate | X6: Metric | Y6: BeginningBalance | Z6: Activity | AA6: Interest Payment | AB6: EndingBalance
A7: 44592 | B7: UPB | C7: 0 | E7: 100000 | F7: =E7 -> 100000 | H7: 44592 | I7: AIR | J7: 0 | K7: 100 | M7: 100 | P7: 44592 | Q7: UPB | R7: 0 | T7: 100000 | U7: =T7 -> 100000 | W7: 44592 | X7: AIR | Y7: 0 | Z7: 100 | AB7: 100
A8: 44593 | B8: UPB | C8: =F7 -> 100000 | E8: 0 | F8: =F7 -> 100000 | H8: 44593 | I8: AIR | J8: =M7 -> 100 | K8: =(F8*$Q$1)/360 -> 27.777778 | M8: =J8+K8 -> 127.77778 | P8: 44593 | Q8: UPB | R8: =U7 -> 100000 | T8: 0 | U8: =U7 -> 100000 | W8: 44593 | X8: AIR | Y8: =AB7 -> 100 | Z8: =(U8*$Q$1)/360 -> 27.777778 | AB8: =Y8+Z8 -> 127.77778
A9: 44594 | B9: UPB | C9: =F8 -> 100000 | E9: 0 | F9: =C9+E9 -> 100000 | H9: 44594 | I9: AIR | J9: =M8 -> 127.77778 | K9: =(F9*$Q$1)/360 -> 27.777778 | M9: =J9+K9 -> 155.55556 | P9: 44594 | Q9: UPB | R9: =U8 -> 100000 | T9: 0 | U9: =R9+T9 -> 100000 | W9: 44594 | X9: AIR | Y9: =AB8 -> 127.77778 | Z9: =(U9*$Q$1)/360 -> 27.777778 | AB9: =Y9+Z9 -> 155.55556
A10: 44595 | B10: UPB | C10: =F9 -> 100000 | E10: 0 | F10: =C10+E10 -> 100000 | H10: 44595 | I10: AIR | J10: =M9 -> 155.55556 | K10: =+(F10*$Q$1/360) -> 27.777778 | L10: 0 | M10: =J10+K10+L10 -> 183.33333 | P10: 44595 | Q10: UPB | R10: =U9 -> 100000 | S10: 50 | T10: 0 | U10: =R10+T10 -> 100000 | W10: 44595 | X10: AIR | Y10: =AB9 -> 155.55556 | Z10: =(U10*$Q$1/360) -> 27.777778 | AA10: =-S10 -> -50 | AB10: =Y10+Z10+AA10 -> 133.33333
A11: 44596 | B11: UPB | C11: =F10 -> 100000 | E11: 0 | F11: =C11+E11 -> 100000 | H11: 44596 | I11: AIR | J11: =M10 -> 183.33333 | K11: =(F11*$Q$1)/360 -> 27.777778 | M11: =J11+K11+L11 -> 211.11111 | P11: 44596 | Q11: UPB | R11: =U10 -> 100000 | T11: 0 | U11: =R11+T11 -> 100000 | W11: 44596 | X11: AIR | Y11: =AB10 -> 133.33333 | Z11: =(U11*$Q$1)/360 -> 27.777778 | AB11: =Y11+Z11+AA11 -> 161.11111
A12: 44597 | B12: UPB | C12: =F11 -> 100000 | E12: 0 | F12: =C12+E12 -> 100000 | H12: 44597 | I12: AIR | J12: =M11 -> 211.11111 | K12: =+(F12*$Q$1/360) -> 27.777778 | L12: 0 | M12: =J12+K12+L12 -> 238.88889 | P12: 44597 | Q12: UPB | R12: =U11 -> 100000 | S12: 0 | T12: 0 | U12: =R12+T12 -> 100000 | W12: 44597 | X12: AIR | Y12: =AB11 -> 161.11111 | Z12: =+(U12*$Q$1/360) -> 27.777778 | AA12: 0 | AB12: =Y12+Z12+AA12 -> 188.88889
A13: 44598 | B13: UPB | C13: =F12 -> 100000 | E13: 0 | F13: =C13+E13 -> 100000 | H13: 44598 | I13: AIR | J13: =M12 -> 238.88889 | K13: =(F13*$Q$1/360) -> 27.777778 | L13: 0 | M13: =J13+K13+L13 -> 266.66667 | P13: 44598 | Q13: UPB | R13: =U12 -> 100000 | S13: 0 | T13: 0 | U13: =R13+T13 -> 100000 | W13: 44598 | X13: AIR | Y13: =AB12 -> 188.88889 | Z13: =(U13*$Q$1/360) -> 27.777778 | AA13: 0 | AB13: =Y13+Z13+AA13 -> 216.66667
A14: 44599 | B14: UPB | C14: =F13 -> 100000 | E14: 0 | F14: =C14+E14 -> 100000 | H14: 44599 | I14: AIR | J14: =M13 -> 266.66667 | K14: =(F14*$Q$1)/360 -> 27.777778 | M14: =J14+K14+L14 -> 294.44444 | P14: 44599 | Q14: UPB | R14: =U13 -> 100000 | T14: 0 | U14: =R14+T14 -> 100000 | W14: 44599 | X14: AIR | Y14: =AB13 -> 216.66667 | Z14: =(U14*$Q$1)/360 -> 27.777778 | AB14: =Y14+Z14+AA14 -> 244.44444
A15: 44600 | B15: UPB | C15: =F14 -> 100000 | E15: 0 | F15: =C15+E15 -> 100000 | H15: 44600 | I15: AIR | J15: =M14 -> 294.44444 | K15: =(F15*$Q$1)/360 -> 27.777778 | M15: =J15+K15+L15 -> 322.22222 | P15: 44600 | Q15: UPB | R15: =U14 -> 100000 | T15: 0 | U15: =R15+T15 -> 100000 | W15: 44600 | X15: AIR | Y15: =AB14 -> 244.44444 | Z15: =(U15*$Q$1)/360 -> 27.777778 | AB15: =Y15+Z15+AA15 -> 272.22222
A16: 44601 | B16: UPB | C16: =F15 -> 100000 | E16: 0 | F16: =C16+E16 -> 100000 | H16: 44601 | I16: AIR | J16: =M15 -> 322.22222 | K16: 0 | M16: =J16+K16+L16 -> 322.22222 | P16: 44601 | Q16: UPB | R16: =U15 -> 100000 | S16: 0 | T16: 0 | U16: =R16+T16 -> 100000 | W16: 44601 | X16: AIR | Y16: =AB15 -> 272.22222 | Z16: =(U16*$Q$1)/360 -> 27.777778 | AA16: 0 | AB16: =Y16+Z16+AA16 -> 300
AB17: 0
AA18: 0
Z19: 0
Z20: 0
Z21: 0
