Workbook

Sheet Instructions
A5: Fixed Asset and Depreciation Schedule: Instructions
A6: This worksheet is intended to assist in tracking an organization's fixed assets and annual depreciation estimates. Note: the template assumes that all assets are depreciated on a straight-line basis. For simplicity, an asset's depreciation estimate for its first and last years in service will be calculated at a half-year's rate regardless of how many months the asset was actually in service.
A8: Category | B8: Instructions | C8: Cell / Column / Row
A9: INPUTS
A10: Current Fiscal Year | B10: Enter the current fiscal year in YYYY format (e.g. 2022). | C10: Cell E4
A11: Asset | B11: Enter the name of the individual asset or group of assets being depreciated (e.g. van, copier, computers). Note: use the "+" buttons in the left-hand margin of the template to open additional rows as needed. | C11: Column A
A12: Cost | B12: Enter the acquisition cost of the asset or group of assets. | C12: Column B
A13: Fiscal Year Put Into Service (YYYY) | B13: Enter the fiscal year in which the asset or group of assets was put into service, in YYYY format (e.g. 2017). | C13: Column C
A14: Useful Life (in years) | B14: Enter the estimated useful life of the asset or group of assets in years (between 2 and 50). (For "Land," leave blank.) | C14: Column D
A15: Salvage Value (if other than $0) | B15: Enter the salvage value of the asset or group of assets (in other words, the estimated amount that can be obtained for the asset after its useful life has ended). In most cases, salvage value is assumed to be $0, in which case this cell may be left blank. | C15: Column E
A17: OUTPUTS
A18: Fixed Assets, at Cost | B18: Calculates the total value (cost basis) of all fixed assets on the schedule. | C18: Cell E5
A19: Accumulated Depreciation, as of Fiscal Year End (FYE) | B19: Calculates the total accumulated depreciation of all fixed assets on the schedule as of the end of the current fiscal year (entered in cell E4). | C19: Cell E6
A20: Fixed Assets, net of depreciation, as of FYE | B20: Calculates the current book value of the organization's fixed assets (original cost minus accumulated depreciation) as of the end of the current fiscal year. | C20: Cell E7
A21: Depreciation Amount by Fiscal Year | B21: Calculates annual depreciation estimates for each individual asset or group of assets in columns H and following. Additionally, the template will calculate the organization's total annual depreciation estimate on row 67, columns H and following. | C21: Columns H - AT

Sheet EOD
A1: PostingDate | B1: EffectiveDate | C1: InstrumentId | D1: AttributeId | E1: BALANCES_ENDINGBALANCE_ASSETCOST | F1: ATTRIBUTE_ASSET_NAME_CURRENT | G1: ATTRIBUTE_ACQUISITION_YEAR_CURRENT | H1: ATTRIBUTE_USEFUL_LIFE_CURRENT | I1: ATTRIBUTE_SALVAGE_VALUE_CURRENT

Sheet Depreciation Schedule
E2: Fixed Asset and Depreciation Schedule | M2: Enter input to yellow cells only
G4: Current Fiscal Year | H4: =IF(EOD!$A$2="","",YEAR(EOD!$A$2))
G5: Fixed Assets, at cost | H5: =SUM(E11:E70) -> 0
G6: Accumulated Depreciation as of FYE | H6: =(SUMIF(J10:AW10,"<="&H4,J71:AW71))+I71 -> 0
G7: Fixed Assets, net of depreciation, as of FYE | H7: =H5-H6 -> 0
A9: Asset | E9: Cost | F9: Fiscal Year put into service (yyyy) | G9: Useful Life (in years) | H9: Salvage Value (if other than $0) | K9: Depreciation Amount by Fiscal Year | AY9: Transaction
B10: InstrumentID | C10: PostingDate | D10: AtrributeID | I10: Prior | J10: 2023 | K10: 2023 | L10: 2024 | M10: 2024 | N10: 2025 | O10: 2025 | P10: 2026 | Q10: 2026 | R10: 2027 | S10: 2027 | T10: 2028 | U10: 2028 | V10: 2029 | W10: 2029 | X10: 2030 | Y10: 2030 | Z10: 2031 | AA10: 2031 | AB10: 2032 | AC10: 2032 | AD10: 2033 | AE10: 2033 | AF10: 2034 | AG10: 2034 | AH10: 2035 | AI10: 2035 | AJ10: 2036 | AK10: 2036 | AL10: 2037 | AM10: 2037 | AN10: 2038 | AO10: 2038 | AP10: 2039 | AQ10: 2039 | AR10: 2040 | AS10: 2040 | AT10: 2041 | AU10: 2041 | AV10: 2042 | AW10: 2042 | AY10: PostingDate | AZ10: EffectiveDate | BA10: InstrumentID | BB10: AttributeID | BC10: TransactionName | BD10: Amount
A11: =IF(EOD!$F2="","",EOD!$F2) | B11: =IF(EOD!$C2="","",EOD!$C2) | C11: =IF(EOD!$A2="","",EOD!$A2) | D11: =IF(EOD!$D2="","",EOD!$D2) | E11: =IF(EOD!E2="","",EOD!E2) | F11: =IF(EOD!G2="","",EOD!G2) | G11: =IF(EOD!H2="","",EOD!H2) | H11: =IF(EOD!I2="","",EOD!I2) | I11: =IFERROR(IF(F11<$K$10,(($K$10-F11-1)*((E11-H11)/G11)+(((E11-H11)/G11)/2)),0),0) -> 0 | J11: =IF($F11+$G11=J$10,($E11-$H11)/$G11/2,(IF($F11=J$10,($E11-$H11)/$G11/2,0))) -> #VALUE! | K11: =IFERROR(IF($F11+$G11=K$10,J11,(IF($F11=K$10,J11,(IF($F11>K$10," ",IF(K$10<$G11+$F11,SLN($E11,$H11,$G11)," "))))))," ") | L11: =IF($F11+$G11=L$10,($E11-$H11)/$G11/2,(IF($F11=L$10,($E11-$H11)/$G11/2,0))) -> #VALUE! | M11: =IFERROR(IF($F11+$G11=M$10,L11,(IF($F11=M$10,L11,(IF($F11>M$10," ",IF(M$10<$G11+$F11,SLN($E11,$H11,$G11)," "))))))," ") | N11: =IF($F11+$G11=N$10,($E11-$H11)/$G11/2,(IF($F11=N$10,($E11-$H11)/$G11/2,0))) -> #VALUE! | O11: =IFERROR(IF($F11+$G11=O$10,N11,(IF($F11=O$10,N11,(IF($F11>O$10," ",IF(O$10<$G11+$F11,SLN($E11,$H11,$G11)," "))))))," ") | P11: =IF($F11+$G11=P$10,($E11-$H11)/$G11/2,(IF($F11=P$10,($E11-$H11)/$G11/2,0))) -> #VALUE! | Q11: =IFERROR(IF($F11+$G11=Q$10,P11,(IF($F11=Q$10,P11,(IF($F11>Q$10," ",IF(Q$10<$G11+$F11,SLN($E11,$H11,$G11)," "))))))," ") | R11: =IF($F11+$G11=R$10,($E11-$H11)/$G11/2,(IF($F11=R$10,($E11-$H11)/$G11/2,0))) -> #VALUE! | S11: =IFERROR(IF($F11+$G11=S$10,R11,(IF($F11=S$10,R11,(IF($F11>S$10," ",IF(S$10<$G11+$F11,SLN($E11,$H11,$G11)," "))))))," ") | T11: =IF($F11+$G11=T$10,($E11-$H11)/$G11/2,(IF($F11=T$10,($E11-$H11)/$G11/2,0))) -> #VALUE! | U11: =IFERROR(IF($F11+$G11=U$10,T11,(IF($F11=U$10,T11,(IF($F11>U$10," ",IF(U$10<$G11+$F11,SLN($E11,$H11,$G11)," "))))))," ") | V11: =IF($F11+$G11=V$10,($E11-$H11)/$G11/2,(IF($F11=V$10,($E11-$H11)/$G11/2,0))) -> #VALUE! | W11: =IFERROR(IF($F11+$G11=W$10,V11,(IF($F11=W$10,V11,(IF($F11>W$10," ",IF(W$10<$G11+$F11,SLN($E11,$H11,$G11)," "))))))," ") | X11: =IF($F11+$G11=X$10,($E11-$H11)/$G11/2,(IF($F11=X$10,($E11-$H11)/$G11/2,0))) -> #VALUE! | Y11: =IFERROR(IF($F11+$G11=Y$10,X11,(IF($F11=Y$10,X11,(IF($F11>Y$10," ",IF(Y$10<$G11+$F11,SLN($E11,$H11,$G11)," "))))))," ") | Z11: =IF($F11+$G11=Z$10,($E11-$H11)/$G11/2,(IF($F11=Z$10,($E11-$H11)/$G11/2,0))) -> #VALUE! | AA11: =IFERROR(IF($F11+$G11=AA$10,Z11,(IF($F11=AA$10,Z11,(IF($F11>AA$10," ",IF(AA$10<$G11+$F11,SLN($E11,$H11,$G11)," "))))))," ") | AB11: =IF($F11+$G11=AB$10,($E11-$H11)/$G11/2,(IF($F11=AB$10,($E11-$H11)/$G11/2,0))) -> #VALUE! | AC11: =IFERROR(IF($F11+$G11=AC$10,AB11,(IF($F11=AC$10,AB11,(IF($F11>AC$10," ",IF(AC$10<$G11+$F11,SLN($E11,$H11,$G11)," "))))))," ") | AD11: =IF($F11+$G11=AD$10,($E11-$H11)/$G11/2,(IF($F11=AD$10,($E11-$H11)/$G11/2,0))) -> #VALUE! | AE11: =IFERROR(IF($F11+$G11=AE$10,AD11,(IF($F11=AE$10,AD11,(IF($F11>AE$10," ",IF(AE$10<$G11+$F11,SLN($E11,$H11,$G11)," "))))))," ") | AF11: =IF($F11+$G11=AF$10,($E11-$H11)/$G11/2,(IF($F11=AF$10,($E11-$H11)/$G11/2,0))) -> #VALUE! | AG11: =IFERROR(IF($F11+$G11=AG$10,AF11,(IF($F11=AG$10,AF11,(IF($F11>AG$10," ",IF(AG$10<$G11+$F11,SLN($E11,$H11,$G11)," "))))))," ") | AH11: =IF($F11+$G11=AH$10,($E11-$H11)/$G11/2,(IF($F11=AH$10,($E11-$H11)/$G11/2,0))) -> #VALUE! | AI11: =IFERROR(IF($F11+$G11=AI$10,AH11,(IF($F11=AI$10,AH11,(IF($F11>AI$10," ",IF(AI$10<$G11+$F11,SLN($E11,$H11,$G11)," "))))))," ") | AJ11: =IF($F11+$G11=AJ$10,($E11-$H11)/$G11/2,(IF($F11=AJ$10,($E11-$H11)/$G11/2,0))) -> #VALUE! | AK11: =IFERROR(IF($F11+$G11=AK$10,AJ11,(IF($F11=AK$10,AJ11,(IF($F11>AK$10," ",IF(AK$10<$G11+$F11,SLN($E11,$H11,$G11)," "))))))," ") | AL11: =IF($F11+$G11=AL$10,($E11-$H11)/$G11/2,(IF($F11=AL$10,($E11-$H11)/$G11/2,0))) -> #VALUE! | AM11: =IFERROR(IF($F11+$G11=AM$10,AL11,(IF($F11=AM$10,AL11,(IF($F11>AM$10," ",IF(AM$10<$G11+$F11,SLN($E11,$H11,$G11)," "))))))," ") | AN11: =IF($F11+$G11=AN$10,($E11-$H11)/$G11/2,(IF($F11=AN$10,($E11-$H11)/$G11/2,0))) -> #VALUE! | AO11: =IFERROR(IF($F11+$G11=AO$10,AN11,(IF($F11=AO$10,AN11,(IF($F11>AO$10," ",IF(AO$10<$G11+$F11,SLN($E11,$H11,$G11)," "))))))," ") | AP11: =IF($F11+$G11=AP$10,($E11-$H11)/$G11/2,(IF($F11=AP$10,($E11-$H11)/$G11/2,0))) -> #VALUE! | AQ11: =IFERROR(IF($F11+$G11=AQ$10,AP11,(IF($F11=AQ$10,AP11,(IF($F11>AQ$10," ",IF(AQ$10<$G11+$F11,SLN($E11,$H11,$G11)," "))))))," ") | AR11: =IF($F11+$G11=AR$10,($E11-$H11)/$G11/2,(IF($F11=AR$10,($E11-$H11)/$G11/2,0))) -> #VALUE! | AS11: =IFERROR(IF($F11+$G11=AS$10,AR11,(IF($F11=AS$10,AR11,(IF($F11>AS$10," ",IF(AS$10<$G11+$F11,SLN($E11,$H11,$G11)," "))))))," ") | AT11: =IF($F11+$G11=AT$10,($E11-$H11)/$G11/2,(IF($F11=AT$10,($E11-$H11)/$G11/2,0))) -> #VALUE! | AU11: =IFERROR(IF($F11+$G11=AU$10,AT11,(IF($F11=AU$10,AT11,(IF($F11>AU$10," ",IF(AU$10<$G11+$F11,SLN($E11,$H11,$G11)," "))))))," ") | AV11: =IF($F11+$G11=AV$10,($E11-$H11)/$G11/2,(IF($F11=AV$10,($E11-$H11)/$G11/2,0))) -> #VALUE! | AW11: =IFERROR(IF($F11+$G11=AW$10,AV11,(IF($F11=AW$10,AV11,(IF($F11>AW$10," ",IF(AW$10<$G11+$F11,SLN($E11,$H11,$G11)," "))))))," ") | AY11: =C11 | AZ11: =AY11 | BA11: =B11 | BB11: =D11 | BC11: =IF(BB11="","","Depreciation_Expense") | BD11: =INDEX($K$10:$BD$55, MATCH(BB11, $D$10:$D$55, 0), MATCH($H$4, $K$10:$BD$10, 1)) -> #N/A
A12: =IF(EOD!$F3="","",EOD!$F3) | B12: =IF(EOD!$C3="","",EOD!$C3) | C12: =IF(EOD!$A3="","",EOD!$A3) | D12: =IF(EOD!$D3="","",EOD!$D3) | E12: =IF(EOD!E3="","",EOD!E3) | F12: =IF(EOD!G3="","",EOD!G3) | G12: =IF(EOD!H3="","",EOD!H3) | H12: =IF(EOD!I3="","",EOD!I3) | I12: =IFERROR(IF(F12<$K$10,(($K$10-F12-1)*((E12-H12)/G12)+(((E12-H12)/G12)/2)),0),0) -> 0 | J12: =IF($F12+$G12=J$10,($E12-$H12)/$G12/2,(IF($F12=J$10,($E12-$H12)/$G12/2,0))) -> #VALUE! | K12: =IFERROR(IF($F12+$G12=K$10,J12,(IF($F12=K$10,J12,(IF($F12>K$10," ",IF(K$10<$G12+$F12,SLN($E12,$H12,$G12)," "))))))," ") | L12: =IF($F12+$G12=L$10,($E12-$H12)/$G12/2,(IF($F12=L$10,($E12-$H12)/$G12/2,0))) -> #VALUE! | M12: =IFERROR(IF($F12+$G12=M$10,L12,(IF($F12=M$10,L12,(IF($F12>M$10," ",IF(M$10<$G12+$F12,SLN($E12,$H12,$G12)," "))))))," ") | N12: =IF($F12+$G12=N$10,($E12-$H12)/$G12/2,(IF($F12=N$10,($E12-$H12)/$G12/2,0))) -> #VALUE! | O12: =IFERROR(IF($F12+$G12=O$10,N12,(IF($F12=O$10,N12,(IF($F12>O$10," ",IF(O$10<$G12+$F12,SLN($E12,$H12,$G12)," "))))))," ") | P12: =IF($F12+$G12=P$10,($E12-$H12)/$G12/2,(IF($F12=P$10,($E12-$H12)/$G12/2,0))) -> #VALUE! | Q12: =IFERROR(IF($F12+$G12=Q$10,P12,(IF($F12=Q$10,P12,(IF($F12>Q$10," ",IF(Q$10<$G12+$F12,SLN($E12,$H12,$G12)," "))))))," ") | R12: =IF($F12+$G12=R$10,($E12-$H12)/$G12/2,(IF($F12=R$10,($E12-$H12)/$G12/2,0))) -> #VALUE! | S12: =IFERROR(IF($F12+$G12=S$10,R12,(IF($F12=S$10,R12,(IF($F12>S$10," ",IF(S$10<$G12+$F12,SLN($E12,$H12,$G12)," "))))))," ") | T12: =IF($F12+$G12=T$10,($E12-$H12)/$G12/2,(IF($F12=T$10,($E12-$H12)/$G12/2,0))) -> #VALUE! | U12: =IFERROR(IF($F12+$G12=U$10,T12,(IF($F12=U$10,T12,(IF($F12>U$10," ",IF(U$10<$G12+$F12,SLN($E12,$H12,$G12)," "))))))," ") | V12: =IF($F12+$G12=V$10,($E12-$H12)/$G12/2,(IF($F12=V$10,($E12-$H12)/$G12/2,0))) -> #VALUE! | W12: =IFERROR(IF($F12+$G12=W$10,V12,(IF($F12=W$10,V12,(IF($F12>W$10," ",IF(W$10<$G12+$F12,SLN($E12,$H12,$G12)," "))))))," ") | X12: =IF($F12+$G12=X$10,($E12-$H12)/$G12/2,(IF($F12=X$10,($E12-$H12)/$G12/2,0))) -> #VALUE! | Y12: =IFERROR(IF($F12+$G12=Y$10,X12,(IF($F12=Y$10,X12,(IF($F12>Y$10," ",IF(Y$10<$G12+$F12,SLN($E12,$H12,$G12)," "))))))," ") | Z12: =IF($F12+$G12=Z$10,($E12-$H12)/$G12/2,(IF($F12=Z$10,($E12-$H12)/$G12/2,0))) -> #VALUE! | AA12: =IFERROR(IF($F12+$G12=AA$10,Z12,(IF($F12=AA$10,Z12,(IF($F12>AA$10," ",IF(AA$10<$G12+$F12,SLN($E12,$H12,$G12)," "))))))," ") | AB12: =IF($F12+$G12=AB$10,($E12-$H12)/$G12/2,(IF($F12=AB$10,($E12-$H12)/$G12/2,0))) -> #VALUE! | AC12: =IFERROR(IF($F12+$G12=AC$10,AB12,(IF($F12=AC$10,AB12,(IF($F12>AC$10," ",IF(AC$10<$G12+$F12,SLN($E12,$H12,$G12)," "))))))," ") | AD12: =IF($F12+$G12=AD$10,($E12-$H12)/$G12/2,(IF($F12=AD$10,($E12-$H12)/$G12/2,0))) -> #VALUE! | AE12: =IFERROR(IF($F12+$G12=AE$10,AD12,(IF($F12=AE$10,AD12,(IF($F12>AE$10," ",IF(AE$10<$G12+$F12,SLN($E12,$H12,$G12)," "))))))," ") | AF12: =IF($F12+$G12=AF$10,($E12-$H12)/$G12/2,(IF($F12=AF$10,($E12-$H12)/$G12/2,0))) -> #VALUE! | AG12: =IFERROR(IF($F12+$G12=AG$10,AF12,(IF($F12=AG$10,AF12,(IF($F12>AG$10," ",IF(AG$10<$G12+$F12,SLN($E12,$H12,$G12)," "))))))," ") | AH12: =IF($F12+$G12=AH$10,($E12-$H12)/$G12/2,(IF($F12=AH$10,($E12-$H12)/$G12/2,0))) -> #VALUE! | AI12: =IFERROR(IF($F12+$G12=AI$10,AH12,(IF($F12=AI$10,AH12,(IF($F12>AI$10," ",IF(AI$10<$G12+$F12,SLN($E12,$H12,$G12)," "))))))," ") | AJ12: =IF($F12+$G12=AJ$10,($E12-$H12)/$G12/2,(IF($F12=AJ$10,($E12-$H12)/$G12/2,0))) -> #VALUE! | AK12: =IFERROR(IF($F12+$G12=AK$10,AJ12,(IF($F12=AK$10,AJ12,(IF($F12>AK$10," ",IF(AK$10<$G12+$F12,SLN($E12,$H12,$G12)," "))))))," ") | AL12: =IF($F12+$G12=AL$10,($E12-$H12)/$G12/2,(IF($F12=AL$10,($E12-$H12)/$G12/2,0))) -> #VALUE! | AM12: =IFERROR(IF($F12+$G12=AM$10,AL12,(IF($F12=AM$10,AL12,(IF($F12>AM$10," ",IF(AM$10<$G12+$F12,SLN($E12,$H12,$G12)," "))))))," ") | AN12: =IF($F12+$G12=AN$10,($E12-$H12)/$G12/2,(IF($F12=AN$10,($E12-$H12)/$G12/2,0))) -> #VALUE! | AO12: =IFERROR(IF($F12+$G12=AO$10,AN12,(IF($F12=AO$10,AN12,(IF($F12>AO$10," ",IF(AO$10<$G12+$F12,SLN($E12,$H12,$G12)," "))))))," ") | AP12: =IF($F12+$G12=AP$10,($E12-$H12)/$G12/2,(IF($F12=AP$10,($E12-$H12)/$G12/2,0))) -> #VALUE! | AQ12: =IFERROR(IF($F12+$G12=AQ$10,AP12,(IF($F12=AQ$10,AP12,(IF($F12>AQ$10," ",IF(AQ$10<$G12+$F12,SLN($E12,$H12,$G12)," "))))))," ") | AR12: =IF($F12+$G12=AR$10,($E12-$H12)/$G12/2,(IF($F12=AR$10,($E12-$H12)/$G12/2,0))) -> #VALUE! | AS12: =IFERROR(IF($F12+$G12=AS$10,AR12,(IF($F12=AS$10,AR12,(IF($F12>AS$10," ",IF(AS$10<$G12+$F12,SLN($E12,$H12,$G12)," "))))))," ") | AT12: =IF($F12+$G12=AT$10,($E12-$H12)/$G12/2,(IF($F12=AT$10,($E12-$H12)/$G12/2,0))) -> #VALUE! | AU12: =IFERROR(IF($F12+$G12=AU$10,AT12,(IF($F12=AU$10,AT12,(IF($F12>AU$10," ",IF(AU$10<$G12+$F12,SLN($E12,$H12,$G12)," "))))))," ") | AV12: =IF($F12+$G12=AV$10,($E12-$H12)/$G12/2,(IF($F12=AV$10,($E12-$H12)/$G12/2,0))) -> #VALUE! | AW12: =IFERROR(IF($F12+$G12=AW$10,AV12,(IF($F12=AW$10,AV12,(IF($F12>AW$10," ",IF(AW$10<$G12+$F12,SLN($E12,$H12,$G12)," "))))))," ") | AY12: =C12 | AZ12: =AY12 | BA12: =B12 | BB12: =D12 | BC12: =IF(BB12="","","Depreciation_Expense") | BD12: =INDEX($K$10:$BD$55, MATCH(BB12, $D$10:$D$55, 0), MATCH($H$4, $K$10:$BD$10, 1)) -> #N/A
A13: =IF(EOD!$F4="","",EOD!$F4) | B13: =IF(EOD!$C4="","",EOD!$C4) | C13: =IF(EOD!$A4="","",EOD!$A4) | D13: =IF(EOD!$D4="","",EOD!$D4) | E13: =IF(EOD!E4="","",EOD!E4) | F13: =IF(EOD!G4="","",EOD!G4) | G13: =IF(EOD!H4="","",EOD!H4) | H13: =IF(EOD!I4="","",EOD!I4) | I13: =IFERROR(IF(F13<$K$10,(($K$10-F13-1)*((E13-H13)/G13)+(((E13-H13)/G13)/2)),0),0) -> 0 | J13: =IF($F13+$G13=J$10,($E13-$H13)/$G13/2,(IF($F13=J$10,($E13-$H13)/$G13/2,0))) -> #VALUE! | K13: =IFERROR(IF($F13+$G13=K$10,J13,(IF($F13=K$10,J13,(IF($F13>K$10," ",IF(K$10<$G13+$F13,SLN($E13,$H13,$G13)," "))))))," ") | L13: =IF($F13+$G13=L$10,($E13-$H13)/$G13/2,(IF($F13=L$10,($E13-$H13)/$G13/2,0))) -> #VALUE! | M13: =IFERROR(IF($F13+$G13=M$10,L13,(IF($F13=M$10,L13,(IF($F13>M$10," ",IF(M$10<$G13+$F13,SLN($E13,$H13,$G13)," "))))))," ") | N13: =IF($F13+$G13=N$10,($E13-$H13)/$G13/2,(IF($F13=N$10,($E13-$H13)/$G13/2,0))) -> #VALUE! | O13: =IFERROR(IF($F13+$G13=O$10,N13,(IF($F13=O$10,N13,(IF($F13>O$10," ",IF(O$10<$G13+$F13,SLN($E13,$H13,$G13)," "))))))," ") | P13: =IF($F13+$G13=P$10,($E13-$H13)/$G13/2,(IF($F13=P$10,($E13-$H13)/$G13/2,0))) -> #VALUE! | Q13: =IFERROR(IF($F13+$G13=Q$10,P13,(IF($F13=Q$10,P13,(IF($F13>Q$10," ",IF(Q$10<$G13+$F13,SLN($E13,$H13,$G13)," "))))))," ") | R13: =IF($F13+$G13=R$10,($E13-$H13)/$G13/2,(IF($F13=R$10,($E13-$H13)/$G13/2,0))) -> #VALUE! | S13: =IFERROR(IF($F13+$G13=S$10,R13,(IF($F13=S$10,R13,(IF($F13>S$10," ",IF(S$10<$G13+$F13,SLN($E13,$H13,$G13)," "))))))," ") | T13: =IF($F13+$G13=T$10,($E13-$H13)/$G13/2,(IF($F13=T$10,($E13-$H13)/$G13/2,0))) -> #VALUE! | U13: =IFERROR(IF($F13+$G13=U$10,T13,(IF($F13=U$10,T13,(IF($F13>U$10," ",IF(U$10<$G13+$F13,SLN($E13,$H13,$G13)," "))))))," ") | V13: =IF($F13+$G13=V$10,($E13-$H13)/$G13/2,(IF($F13=V$10,($E13-$H13)/$G13/2,0))) -> #VALUE! | W13: =IFERROR(IF($F13+$G13=W$10,V13,(IF($F13=W$10,V13,(IF($F13>W$10," ",IF(W$10<$G13+$F13,SLN($E13,$H13,$G13)," "))))))," ") | X13: =IF($F13+$G13=X$10,($E13-$H13)/$G13/2,(IF($F13=X$10,($E13-$H13)/$G13/2,0))) -> #VALUE! | Y13: =IFERROR(IF($F13+$G13=Y$10,X13,(IF($F13=Y$10,X13,(IF($F13>Y$10," ",IF(Y$10<$G13+$F13,SLN($E13,$H13,$G13)," "))))))," ") | Z13: =IF($F13+$G13=Z$10,($E13-$H13)/$G13/2,(IF($F13=Z$10,($E13-$H13)/$G13/2,0))) -> #VALUE! | AA13: =IFERROR(IF($F13+$G13=AA$10,Z13,(IF($F13=AA$10,Z13,(IF($F13>AA$10," ",IF(AA$10<$G13+$F13,SLN($E13,$H13,$G13)," "))))))," ") | AB13: =IF($F13+$G13=AB$10,($E13-$H13)/$G13/2,(IF($F13=AB$10,($E13-$H13)/$G13/2,0))) -> #VALUE! | AC13: =IFERROR(IF($F13+$G13=AC$10,AB13,(IF($F13=AC$10,AB13,(IF($F13>AC$10," ",IF(AC$10<$G13+$F13,SLN($E13,$H13,$G13)," "))))))," ") | AD13: =IF($F13+$G13=AD$10,($E13-$H13)/$G13/2,(IF($F13=AD$10,($E13-$H13)/$G13/2,0))) -> #VALUE! | AE13: =IFERROR(IF($F13+$G13=AE$10,AD13,(IF($F13=AE$10,AD13,(IF($F13>AE$10," ",IF(AE$10<$G13+$F13,SLN($E13,$H13,$G13)," "))))))," ") | AF13: =IF($F13+$G13=AF$10,($E13-$H13)/$G13/2,(IF($F13=AF$10,($E13-$H13)/$G13/2,0))) -> #VALUE! | AG13: =IFERROR(IF($F13+$G13=AG$10,AF13,(IF($F13=AG$10,AF13,(IF($F13>AG$10," ",IF(AG$10<$G13+$F13,SLN($E13,$H13,$G13)," "))))))," ") | AH13: =IF($F13+$G13=AH$10,($E13-$H13)/$G13/2,(IF($F13=AH$10,($E13-$H13)/$G13/2,0))) -> #VALUE! | AI13: =IFERROR(IF($F13+$G13=AI$10,AH13,(IF($F13=AI$10,AH13,(IF($F13>AI$10," ",IF(AI$10<$G13+$F13,SLN($E13,$H13,$G13)," "))))))," ") | AJ13: =IF($F13+$G13=AJ$10,($E13-$H13)/$G13/2,(IF($F13=AJ$10,($E13-$H13)/$G13/2,0))) -> #VALUE! | AK13: =IFERROR(IF($F13+$G13=AK$10,AJ13,(IF($F13=AK$10,AJ13,(IF($F13>AK$10," ",IF(AK$10<$G13+$F13,SLN($E13,$H13,$G13)," "))))))," ") | AL13: =IF($F13+$G13=AL$10,($E13-$H13)/$G13/2,(IF($F13=AL$10,($E13-$H13)/$G13/2,0))) -> #VALUE! | AM13: =IFERROR(IF($F13+$G13=AM$10,AL13,(IF($F13=AM$10,AL13,(IF($F13>AM$10," ",IF(AM$10<$G13+$F13,SLN($E13,$H13,$G13)," "))))))," ") | AN13: =IF($F13+$G13=AN$10,($E13-$H13)/$G13/2,(IF($F13=AN$10,($E13-$H13)/$G13/2,0))) -> #VALUE! | AO13: =IFERROR(IF($F13+$G13=AO$10,AN13,(IF($F13=AO$10,AN13,(IF($F13>AO$10," ",IF(AO$10<$G13+$F13,SLN($E13,$H13,$G13)," "))))))," ") | AP13: =IF($F13+$G13=AP$10,($E13-$H13)/$G13/2,(IF($F13=AP$10,($E13-$H13)/$G13/2,0))) -> #VALUE! | AQ13: =IFERROR(IF($F13+$G13=AQ$10,AP13,(IF($F13=AQ$10,AP13,(IF($F13>AQ$10," ",IF(AQ$10<$G13+$F13,SLN($E13,$H13,$G13)," "))))))," ") | AR13: =IF($F13+$G13=AR$10,($E13-$H13)/$G13/2,(IF($F13=AR$10,($E13-$H13)/$G13/2,0))) -> #VALUE! | AS13: =IFERROR(IF($F13+$G13=AS$10,AR13,(IF($F13=AS$10,AR13,(IF($F13>AS$10," ",IF(AS$10<$G13+$F13,SLN($E13,$H13,$G13)," "))))))," ") | AT13: =IF($F13+$G13=AT$10,($E13-$H13)/$G13/2,(IF($F13=AT$10,($E13-$H13)/$G13/2,0))) -> #VALUE! | AU13: =IFERROR(IF($F13+$G13=AU$10,AT13,(IF($F13=AU$10,AT13,(IF($F13>AU$10," ",IF(AU$10<$G13+$F13,SLN($E13,$H13,$G13)," "))))))," ") | AV13: =IF($F13+$G13=AV$10,($E13-$H13)/$G13/2,(IF($F13=AV$10,($E13-$H13)/$G13/2,0))) -> #VALUE! | AW13: =IFERROR(IF($F13+$G13=AW$10,AV13,(IF($F13=AW$10,AV13,(IF($F13>AW$10," ",IF(AW$10<$G13+$F13,SLN($E13,$H13,$G13)," "))))))," ") | AY13: =C13 | AZ13: =AY13 | BA13: =B13 | BB13: =D13 | BC13: =IF(BB13="","","Depreciation_Expense") | BD13: =INDEX($K$10:$BD$55, MATCH(BB13, $D$10:$D$55, 0), MATCH($H$4, $K$10:$BD$10, 1)) -> #N/A
A14: =IF(EOD!$F5="","",EOD!$F5) | B14: =IF(EOD!$C5="","",EOD!$C5) | C14: =IF(EOD!$A5="","",EOD!$A5) | D14: =IF(EOD!$D5="","",EOD!$D5) | E14: =IF(EOD!E5="","",EOD!E5) | F14: =IF(EOD!G5="","",EOD!G5) | G14: =IF(EOD!H5="","",EOD!H5) | H14: =IF(EOD!I5="","",EOD!I5) | I14: =IFERROR(IF(F14<$K$10,(($K$10-F14-1)*((E14-H14)/G14)+(((E14-H14)/G14)/2)),0),0) -> 0 | J14: =IF($F14+$G14=J$10,($E14-$H14)/$G14/2,(IF($F14=J$10,($E14-$H14)/$G14/2,0))) -> #VALUE! | K14: =IFERROR(IF($F14+$G14=K$10,J14,(IF($F14=K$10,J14,(IF($F14>K$10," ",IF(K$10<$G14+$F14,SLN($E14,$H14,$G14)," "))))))," ") | L14: =IF($F14+$G14=L$10,($E14-$H14)/$G14/2,(IF($F14=L$10,($E14-$H14)/$G14/2,0))) -> #VALUE! | M14: =IFERROR(IF($F14+$G14=M$10,L14,(IF($F14=M$10,L14,(IF($F14>M$10," ",IF(M$10<$G14+$F14,SLN($E14,$H14,$G14)," "))))))," ") | N14: =IF($F14+$G14=N$10,($E14-$H14)/$G14/2,(IF($F14=N$10,($E14-$H14)/$G14/2,0))) -> #VALUE! | O14: =IFERROR(IF($F14+$G14=O$10,N14,(IF($F14=O$10,N14,(IF($F14>O$10," ",IF(O$10<$G14+$F14,SLN($E14,$H14,$G14)," "))))))," ") | P14: =IF($F14+$G14=P$10,($E14-$H14)/$G14/2,(IF($F14=P$10,($E14-$H14)/$G14/2,0))) -> #VALUE! | Q14: =IFERROR(IF($F14+$G14=Q$10,P14,(IF($F14=Q$10,P14,(IF($F14>Q$10," ",IF(Q$10<$G14+$F14,SLN($E14,$H14,$G14)," "))))))," ") | R14: =IF($F14+$G14=R$10,($E14-$H14)/$G14/2,(IF($F14=R$10,($E14-$H14)/$G14/2,0))) -> #VALUE! | S14: =IFERROR(IF($F14+$G14=S$10,R14,(IF($F14=S$10,R14,(IF($F14>S$10," ",IF(S$10<$G14+$F14,SLN($E14,$H14,$G14)," "))))))," ") | T14: =IF($F14+$G14=T$10,($E14-$H14)/$G14/2,(IF($F14=T$10,($E14-$H14)/$G14/2,0))) -> #VALUE! | U14: =IFERROR(IF($F14+$G14=U$10,T14,(IF($F14=U$10,T14,(IF($F14>U$10," ",IF(U$10<$G14+$F14,SLN($E14,$H14,$G14)," "))))))," ") | V14: =IF($F14+$G14=V$10,($E14-$H14)/$G14/2,(IF($F14=V$10,($E14-$H14)/$G14/2,0))) -> #VALUE! | W14: =IFERROR(IF($F14+$G14=W$10,V14,(IF($F14=W$10,V14,(IF($F14>W$10," ",IF(W$10<$G14+$F14,SLN($E14,$H14,$G14)," "))))))," ") | X14: =IF($F14+$G14=X$10,($E14-$H14)/$G14/2,(IF($F14=X$10,($E14-$H14)/$G14/2,0))) -> #VALUE! | Y14: =IFERROR(IF($F14+$G14=Y$10,X14,(IF($F14=Y$10,X14,(IF($F14>Y$10," ",IF(Y$10<$G14+$F14,SLN($E14,$H14,$G14)," "))))))," ") | Z14: =IF($F14+$G14=Z$10,($E14-$H14)/$G14/2,(IF($F14=Z$10,($E14-$H14)/$G14/2,0))) -> #VALUE! | AA14: =IFERROR(IF($F14+$G14=AA$10,Z14,(IF($F14=AA$10,Z14,(IF($F14>AA$10," ",IF(AA$10<$G14+$F14,SLN($E14,$H14,$G14)," "))))))," ") | AB14: =IF($F14+$G14=AB$10,($E14-$H14)/$G14/2,(IF($F14=AB$10,($E14-$H14)/$G14/2,0))) -> #VALUE! | AC14: =IFERROR(IF($F14+$G14=AC$10,AB14,(IF($F14=AC$10,AB14,(IF($F14>AC$10," ",IF(AC$10<$G14+$F14,SLN($E14,$H14,$G14)," "))))))," ") | AD14: =IF($F14+$G14=AD$10,($E14-$H14)/$G14/2,(IF($F14=AD$10,($E14-$H14)/$G14/2,0))) -> #VALUE! | AE14: =IFERROR(IF($F14+$G14=AE$10,AD14,(IF($F14=AE$10,AD14,(IF($F14>AE$10," ",IF(AE$10<$G14+$F14,SLN($E14,$H14,$G14)," "))))))," ") | AF14: =IF($F14+$G14=AF$10,($E14-$H14)/$G14/2,(IF($F14=AF$10,($E14-$H14)/$G14/2,0))) -> #VALUE! | AG14: =IFERROR(IF($F14+$G14=AG$10,AF14,(IF($F14=AG$10,AF14,(IF($F14>AG$10," ",IF(AG$10<$G14+$F14,SLN($E14,$H14,$G14)," "))))))," ") | AH14: =IF($F14+$G14=AH$10,($E14-$H14)/$G14/2,(IF($F14=AH$10,($E14-$H14)/$G14/2,0))) -> #VALUE! | AI14: =IFERROR(IF($F14+$G14=AI$10,AH14,(IF($F14=AI$10,AH14,(IF($F14>AI$10," ",IF(AI$10<$G14+$F14,SLN($E14,$H14,$G14)," "))))))," ") | AJ14: =IF($F14+$G14=AJ$10,($E14-$H14)/$G14/2,(IF($F14=AJ$10,($E14-$H14)/$G14/2,0))) -> #VALUE! | AK14: =IFERROR(IF($F14+$G14=AK$10,AJ14,(IF($F14=AK$10,AJ14,(IF($F14>AK$10," ",IF(AK$10<$G14+$F14,SLN($E14,$H14,$G14)," "))))))," ") | AL14: =IF($F14+$G14=AL$10,($E14-$H14)/$G14/2,(IF($F14=AL$10,($E14-$H14)/$G14/2,0))) -> #VALUE! | AM14: =IFERROR(IF($F14+$G14=AM$10,AL14,(IF($F14=AM$10,AL14,(IF($F14>AM$10," ",IF(AM$10<$G14+$F14,SLN($E14,$H14,$G14)," "))))))," ") | AN14: =IF($F14+$G14=AN$10,($E14-$H14)/$G14/2,(IF($F14=AN$10,($E14-$H14)/$G14/2,0))) -> #VALUE! | AO14: =IFERROR(IF($F14+$G14=AO$10,AN14,(IF($F14=AO$10,AN14,(IF($F14>AO$10," ",IF(AO$10<$G14+$F14,SLN($E14,$H14,$G14)," "))))))," ") | AP14: =IF($F14+$G14=AP$10,($E14-$H14)/$G14/2,(IF($F14=AP$10,($E14-$H14)/$G14/2,0))) -> #VALUE! | AQ14: =IFERROR(IF($F14+$G14=AQ$10,AP14,(IF($F14=AQ$10,AP14,(IF($F14>AQ$10," ",IF(AQ$10<$G14+$F14,SLN($E14,$H14,$G14)," "))))))," ") | AR14: =IF($F14+$G14=AR$10,($E14-$H14)/$G14/2,(IF($F14=AR$10,($E14-$H14)/$G14/2,0))) -> #VALUE! | AS14: =IFERROR(IF($F14+$G14=AS$10,AR14,(IF($F14=AS$10,AR14,(IF($F14>AS$10," ",IF(AS$10<$G14+$F14,SLN($E14,$H14,$G14)," "))))))," ") | AT14: =IF($F14+$G14=AT$10,($E14-$H14)/$G14/2,(IF($F14=AT$10,($E14-$H14)/$G14/2,0))) -> #VALUE! | AU14: =IFERROR(IF($F14+$G14=AU$10,AT14,(IF($F14=AU$10,AT14,(IF($F14>AU$10," ",IF(AU$10<$G14+$F14,SLN($E14,$H14,$G14)," "))))))," ") | AV14: =IF($F14+$G14=AV$10,($E14-$H14)/$G14/2,(IF($F14=AV$10,($E14-$H14)/$G14/2,0))) -> #VALUE! | AW14: =IFERROR(IF($F14+$G14=AW$10,AV14,(IF($F14=AW$10,AV14,(IF($F14>AW$10," ",IF(AW$10<$G14+$F14,SLN($E14,$H14,$G14)," "))))))," ") | AY14: =C14 | AZ14: =AY14 | BA14: =B14 | BB14: =D14 | BC14: =IF(BB14="","","Depreciation_Expense") | BD14: =INDEX($K$10:$BD$55, MATCH(BB14, $D$10:$D$55, 0), MATCH($H$4, $K$10:$BD$10, 1)) -> #N/A
A15: =IF(EOD!$F6="","",EOD!$F6) | B15: =IF(EOD!$C6="","",EOD!$C6) | C15: =IF(EOD!$A6="","",EOD!$A6) | D15: =IF(EOD!$D6="","",EOD!$D6) | E15: =IF(EOD!E6="","",EOD!E6) | F15: =IF(EOD!G6="","",EOD!G6) | G15: =IF(EOD!H6="","",EOD!H6) | H15: =IF(EOD!I6="","",EOD!I6) | I15: =IFERROR(IF(F15<$K$10,(($K$10-F15-1)*((E15-H15)/G15)+(((E15-H15)/G15)/2)),0),0) -> 0 | J15: =IF($F15+$G15=J$10,($E15-$H15)/$G15/2,(IF($F15=J$10,($E15-$H15)/$G15/2,0))) -> #VALUE! | K15: =IFERROR(IF($F15+$G15=K$10,J15,(IF($F15=K$10,J15,(IF($F15>K$10," ",IF(K$10<$G15+$F15,SLN($E15,$H15,$G15)," "))))))," ") | L15: =IF($F15+$G15=L$10,($E15-$H15)/$G15/2,(IF($F15=L$10,($E15-$H15)/$G15/2,0))) -> #VALUE! | M15: =IFERROR(IF($F15+$G15=M$10,L15,(IF($F15=M$10,L15,(IF($F15>M$10," ",IF(M$10<$G15+$F15,SLN($E15,$H15,$G15)," "))))))," ") | N15: =IF($F15+$G15=N$10,($E15-$H15)/$G15/2,(IF($F15=N$10,($E15-$H15)/$G15/2,0))) -> #VALUE! | O15: =IFERROR(IF($F15+$G15=O$10,N15,(IF($F15=O$10,N15,(IF($F15>O$10," ",IF(O$10<$G15+$F15,SLN($E15,$H15,$G15)," "))))))," ") | P15: =IF($F15+$G15=P$10,($E15-$H15)/$G15/2,(IF($F15=P$10,($E15-$H15)/$G15/2,0))) -> #VALUE! | Q15: =IFERROR(IF($F15+$G15=Q$10,P15,(IF($F15=Q$10,P15,(IF($F15>Q$10," ",IF(Q$10<$G15+$F15,SLN($E15,$H15,$G15)," "))))))," ") | R15: =IF($F15+$G15=R$10,($E15-$H15)/$G15/2,(IF($F15=R$10,($E15-$H15)/$G15/2,0))) -> #VALUE! | S15: =IFERROR(IF($F15+$G15=S$10,R15,(IF($F15=S$10,R15,(IF($F15>S$10," ",IF(S$10<$G15+$F15,SLN($E15,$H15,$G15)," "))))))," ") | T15: =IF($F15+$G15=T$10,($E15-$H15)/$G15/2,(IF($F15=T$10,($E15-$H15)/$G15/2,0))) -> #VALUE! | U15: =IFERROR(IF($F15+$G15=U$10,T15,(IF($F15=U$10,T15,(IF($F15>U$10," ",IF(U$10<$G15+$F15,SLN($E15,$H15,$G15)," "))))))," ") | V15: =IF($F15+$G15=V$10,($E15-$H15)/$G15/2,(IF($F15=V$10,($E15-$H15)/$G15/2,0))) -> #VALUE! | W15: =IFERROR(IF($F15+$G15=W$10,V15,(IF($F15=W$10,V15,(IF($F15>W$10," ",IF(W$10<$G15+$F15,SLN($E15,$H15,$G15)," "))))))," ") | X15: =IF($F15+$G15=X$10,($E15-$H15)/$G15/2,(IF($F15=X$10,($E15-$H15)/$G15/2,0))) -> #VALUE! | Y15: =IFERROR(IF($F15+$G15=Y$10,X15,(IF($F15=Y$10,X15,(IF($F15>Y$10," ",IF(Y$10<$G15+$F15,SLN($E15,$H15,$G15)," "))))))," ") | Z15: =IF($F15+$G15=Z$10,($E15-$H15)/$G15/2,(IF($F15=Z$10,($E15-$H15)/$G15/2,0))) -> #VALUE! | AA15: =IFERROR(IF($F15+$G15=AA$10,Z15,(IF($F15=AA$10,Z15,(IF($F15>AA$10," ",IF(AA$10<$G15+$F15,SLN($E15,$H15,$G15)," "))))))," ") | AB15: =IF($F15+$G15=AB$10,($E15-$H15)/$G15/2,(IF($F15=AB$10,($E15-$H15)/$G15/2,0))) -> #VALUE! | AC15: =IFERROR(IF($F15+$G15=AC$10,AB15,(IF($F15=AC$10,AB15,(IF($F15>AC$10," ",IF(AC$10<$G15+$F15,SLN($E15,$H15,$G15)," "))))))," ") | AD15: =IF($F15+$G15=AD$10,($E15-$H15)/$G15/2,(IF($F15=AD$10,($E15-$H15)/$G15/2,0))) -> #VALUE! | AE15: =IFERROR(IF($F15+$G15=AE$10,AD15,(IF($F15=AE$10,AD15,(IF($F15>AE$10," ",IF(AE$10<$G15+$F15,SLN($E15,$H15,$G15)," "))))))," ") | AF15: =IF($F15+$G15=AF$10,($E15-$H15)/$G15/2,(IF($F15=AF$10,($E15-$H15)/$G15/2,0))) -> #VALUE! | AG15: =IFERROR(IF($F15+$G15=AG$10,AF15,(IF($F15=AG$10,AF15,(IF($F15>AG$10," ",IF(AG$10<$G15+$F15,SLN($E15,$H15,$G15)," "))))))," ") | AH15: =IF($F15+$G15=AH$10,($E15-$H15)/$G15/2,(IF($F15=AH$10,($E15-$H15)/$G15/2,0))) -> #VALUE! | AI15: =IFERROR(IF($F15+$G15=AI$10,AH15,(IF($F15=AI$10,AH15,(IF($F15>AI$10," ",IF(AI$10<$G15+$F15,SLN($E15,$H15,$G15)," "))))))," ") | AJ15: =IF($F15+$G15=AJ$10,($E15-$H15)/$G15/2,(IF($F15=AJ$10,($E15-$H15)/$G15/2,0))) -> #VALUE! | AK15: =IFERROR(IF($F15+$G15=AK$10,AJ15,(IF($F15=AK$10,AJ15,(IF($F15>AK$10," ",IF(AK$10<$G15+$F15,SLN($E15,$H15,$G15)," "))))))," ") | AL15: =IF($F15+$G15=AL$10,($E15-$H15)/$G15/2,(IF($F15=AL$10,($E15-$H15)/$G15/2,0))) -> #VALUE! | AM15: =IFERROR(IF($F15+$G15=AM$10,AL15,(IF($F15=AM$10,AL15,(IF($F15>AM$10," ",IF(AM$10<$G15+$F15,SLN($E15,$H15,$G15)," "))))))," ") | AN15: =IF($F15+$G15=AN$10,($E15-$H15)/$G15/2,(IF($F15=AN$10,($E15-$H15)/$G15/2,0))) -> #VALUE! | AO15: =IFERROR(IF($F15+$G15=AO$10,AN15,(IF($F15=AO$10,AN15,(IF($F15>AO$10," ",IF(AO$10<$G15+$F15,SLN($E15,$H15,$G15)," "))))))," ") | AP15: =IF($F15+$G15=AP$10,($E15-$H15)/$G15/2,(IF($F15=AP$10,($E15-$H15)/$G15/2,0))) -> #VALUE! | AQ15: =IFERROR(IF($F15+$G15=AQ$10,AP15,(IF($F15=AQ$10,AP15,(IF($F15>AQ$10," ",IF(AQ$10<$G15+$F15,SLN($E15,$H15,$G15)," "))))))," ") | AR15: =IF($F15+$G15=AR$10,($E15-$H15)/$G15/2,(IF($F15=AR$10,($E15-$H15)/$G15/2,0))) -> #VALUE! | AS15: =IFERROR(IF($F15+$G15=AS$10,AR15,(IF($F15=AS$10,AR15,(IF($F15>AS$10," ",IF(AS$10<$G15+$F15,SLN($E15,$H15,$G15)," "))))))," ") | AT15: =IF($F15+$G15=AT$10,($E15-$H15)/$G15/2,(IF($F15=AT$10,($E15-$H15)/$G15/2,0))) -> #VALUE! | AU15: =IFERROR(IF($F15+$G15=AU$10,AT15,(IF($F15=AU$10,AT15,(IF($F15>AU$10," ",IF(AU$10<$G15+$F15,SLN($E15,$H15,$G15)," "))))))," ") | AV15: =IF($F15+$G15=AV$10,($E15-$H15)/$G15/2,(IF($F15=AV$10,($E15-$H15)/$G15/2,0))) -> #VALUE! | AW15: =IFERROR(IF($F15+$G15=AW$10,AV15,(IF($F15=AW$10,AV15,(IF($F15>AW$10," ",IF(AW$10<$G15+$F15,SLN($E15,$H15,$G15)," "))))))," ") | AY15: =C15 | AZ15: =AY15 | BA15: =B15 | BB15: =D15 | BC15: =IF(BB15="","","Depreciation_Expense") | BD15: =INDEX($K$10:$BD$55, MATCH(BB15, $D$10:$D$55, 0), MATCH($H$4, $K$10:$BD$10, 1)) -> #N/A
A16: =IF(EOD!$F7="","",EOD!$F7) | B16: =IF(EOD!$C7="","",EOD!$C7) | C16: =IF(EOD!$A7="","",EOD!$A7) | D16: =IF(EOD!$D7="","",EOD!$D7) | E16: =IF(EOD!E7="","",EOD!E7) | F16: =IF(EOD!G7="","",EOD!G7) | G16: =IF(EOD!H7="","",EOD!H7) | H16: =IF(EOD!I7="","",EOD!I7) | I16: =IFERROR(IF(F16<$K$10,(($K$10-F16-1)*((E16-H16)/G16)+(((E16-H16)/G16)/2)),0),0) -> 0 | J16: =IF($F16+$G16=J$10,($E16-$H16)/$G16/2,(IF($F16=J$10,($E16-$H16)/$G16/2,0))) -> #VALUE! | K16: =IFERROR(IF($F16+$G16=K$10,J16,(IF($F16=K$10,J16,(IF($F16>K$10," ",IF(K$10<$G16+$F16,SLN($E16,$H16,$G16)," "))))))," ") | L16: =IF($F16+$G16=L$10,($E16-$H16)/$G16/2,(IF($F16=L$10,($E16-$H16)/$G16/2,0))) -> #VALUE! | M16: =IFERROR(IF($F16+$G16=M$10,L16,(IF($F16=M$10,L16,(IF($F16>M$10," ",IF(M$10<$G16+$F16,SLN($E16,$H16,$G16)," "))))))," ") | N16: =IF($F16+$G16=N$10,($E16-$H16)/$G16/2,(IF($F16=N$10,($E16-$H16)/$G16/2,0))) -> #VALUE! | O16: =IFERROR(IF($F16+$G16=O$10,N16,(IF($F16=O$10,N16,(IF($F16>O$10," ",IF(O$10<$G16+$F16,SLN($E16,$H16,$G16)," "))))))," ") | P16: =IF($F16+$G16=P$10,($E16-$H16)/$G16/2,(IF($F16=P$10,($E16-$H16)/$G16/2,0))) -> #VALUE! | Q16: =IFERROR(IF($F16+$G16=Q$10,P16,(IF($F16=Q$10,P16,(IF($F16>Q$10," ",IF(Q$10<$G16+$F16,SLN($E16,$H16,$G16)," "))))))," ") | R16: =IF($F16+$G16=R$10,($E16-$H16)/$G16/2,(IF($F16=R$10,($E16-$H16)/$G16/2,0))) -> #VALUE! | S16: =IFERROR(IF($F16+$G16=S$10,R16,(IF($F16=S$10,R16,(IF($F16>S$10," ",IF(S$10<$G16+$F16,SLN($E16,$H16,$G16)," "))))))," ") | T16: =IF($F16+$G16=T$10,($E16-$H16)/$G16/2,(IF($F16=T$10,($E16-$H16)/$G16/2,0))) -> #VALUE! | U16: =IFERROR(IF($F16+$G16=U$10,T16,(IF($F16=U$10,T16,(IF($F16>U$10," ",IF(U$10<$G16+$F16,SLN($E16,$H16,$G16)," "))))))," ") | V16: =IF($F16+$G16=V$10,($E16-$H16)/$G16/2,(IF($F16=V$10,($E16-$H16)/$G16/2,0))) -> #VALUE! | W16: =IFERROR(IF($F16+$G16=W$10,V16,(IF($F16=W$10,V16,(IF($F16>W$10," ",IF(W$10<$G16+$F16,SLN($E16,$H16,$G16)," "))))))," ") | X16: =IF($F16+$G16=X$10,($E16-$H16)/$G16/2,(IF($F16=X$10,($E16-$H16)/$G16/2,0))) -> #VALUE! | Y16: =IFERROR(IF($F16+$G16=Y$10,X16,(IF($F16=Y$10,X16,(IF($F16>Y$10," ",IF(Y$10<$G16+$F16,SLN($E16,$H16,$G16)," "))))))," ") | Z16: =IF($F16+$G16=Z$10,($E16-$H16)/$G16/2,(IF($F16=Z$10,($E16-$H16)/$G16/2,0))) -> #VALUE! | AA16: =IFERROR(IF($F16+$G16=AA$10,Z16,(IF($F16=AA$10,Z16,(IF($F16>AA$10," ",IF(AA$10<$G16+$F16,SLN($E16,$H16,$G16)," "))))))," ") | AB16: =IF($F16+$G16=AB$10,($E16-$H16)/$G16/2,(IF($F16=AB$10,($E16-$H16)/$G16/2,0))) -> #VALUE! | AC16: =IFERROR(IF($F16+$G16=AC$10,AB16,(IF($F16=AC$10,AB16,(IF($F16>AC$10," ",IF(AC$10<$G16+$F16,SLN($E16,$H16,$G16)," "))))))," ") | AD16: =IF($F16+$G16=AD$10,($E16-$H16)/$G16/2,(IF($F16=AD$10,($E16-$H16)/$G16/2,0))) -> #VALUE! | AE16: =IFERROR(IF($F16+$G16=AE$10,AD16,(IF($F16=AE$10,AD16,(IF($F16>AE$10," ",IF(AE$10<$G16+$F16,SLN($E16,$H16,$G16)," "))))))," ") | AF16: =IF($F16+$G16=AF$10,($E16-$H16)/$G16/2,(IF($F16=AF$10,($E16-$H16)/$G16/2,0))) -> #VALUE! | AG16: =IFERROR(IF($F16+$G16=AG$10,AF16,(IF($F16=AG$10,AF16,(IF($F16>AG$10," ",IF(AG$10<$G16+$F16,SLN($E16,$H16,$G16)," "))))))," ") | AH16: =IF($F16+$G16=AH$10,($E16-$H16)/$G16/2,(IF($F16=AH$10,($E16-$H16)/$G16/2,0))) -> #VALUE! | AI16: =IFERROR(IF($F16+$G16=AI$10,AH16,(IF($F16=AI$10,AH16,(IF($F16>AI$10," ",IF(AI$10<$G16+$F16,SLN($E16,$H16,$G16)," "))))))," ") | AJ16: =IF($F16+$G16=AJ$10,($E16-$H16)/$G16/2,(IF($F16=AJ$10,($E16-$H16)/$G16/2,0))) -> #VALUE! | AK16: =IFERROR(IF($F16+$G16=AK$10,AJ16,(IF($F16=AK$10,AJ16,(IF($F16>AK$10," ",IF(AK$10<$G16+$F16,SLN($E16,$H16,$G16)," "))))))," ") | AL16: =IF($F16+$G16=AL$10,($E16-$H16)/$G16/2,(IF($F16=AL$10,($E16-$H16)/$G16/2,0))) -> #VALUE! | AM16: =IFERROR(IF($F16+$G16=AM$10,AL16,(IF($F16=AM$10,AL16,(IF($F16>AM$10," ",IF(AM$10<$G16+$F16,SLN($E16,$H16,$G16)," "))))))," ") | AN16: =IF($F16+$G16=AN$10,($E16-$H16)/$G16/2,(IF($F16=AN$10,($E16-$H16)/$G16/2,0))) -> #VALUE! | AO16: =IFERROR(IF($F16+$G16=AO$10,AN16,(IF($F16=AO$10,AN16,(IF($F16>AO$10," ",IF(AO$10<$G16+$F16,SLN($E16,$H16,$G16)," "))))))," ") | AP16: =IF($F16+$G16=AP$10,($E16-$H16)/$G16/2,(IF($F16=AP$10,($E16-$H16)/$G16/2,0))) -> #VALUE! | AQ16: =IFERROR(IF($F16+$G16=AQ$10,AP16,(IF($F16=AQ$10,AP16,(IF($F16>AQ$10," ",IF(AQ$10<$G16+$F16,SLN($E16,$H16,$G16)," "))))))," ") | AR16: =IF($F16+$G16=AR$10,($E16-$H16)/$G16/2,(IF($F16=AR$10,($E16-$H16)/$G16/2,0))) -> #VALUE! | AS16: =IFERROR(IF($F16+$G16=AS$10,AR16,(IF($F16=AS$10,AR16,(IF($F16>AS$10," ",IF(AS$10<$G16+$F16,SLN($E16,$H16,$G16)," "))))))," ") | AT16: =IF($F16+$G16=AT$10,($E16-$H16)/$G16/2,(IF($F16=AT$10,($E16-$H16)/$G16/2,0))) -> #VALUE! | AU16: =IFERROR(IF($F16+$G16=AU$10,AT16,(IF($F16=AU$10,AT16,(IF($F16>AU$10," ",IF(AU$10<$G16+$F16,SLN($E16,$H16,$G16)," "))))))," ") | AV16: =IF($F16+$G16=AV$10,($E16-$H16)/$G16/2,(IF($F16=AV$10,($E16-$H16)/$G16/2,0))) -> #VALUE! | AW16: =IFERROR(IF($F16+$G16=AW$10,AV16,(IF($F16=AW$10,AV16,(IF($F16>AW$10," ",IF(AW$10<$G16+$F16,SLN($E16,$H16,$G16)," "))))))," ") | AY16: =C16 | AZ16: =AY16 | BA16: =B16 | BB16: =D16 | BC16: =IF(BB16="","","Depreciation_Expense") | BD16: =INDEX($K$10:$BD$55, MATCH(BB16, $D$10:$D$55, 0), MATCH($H$4, $K$10:$BD$10, 1)) -> #N/A
A17: =IF(EOD!$F8="","",EOD!$F8) | B17: =IF(EOD!$C8="","",EOD!$C8) | C17: =IF(EOD!$A8="","",EOD!$A8) | D17: =IF(EOD!$D8="","",EOD!$D8) | E17: =IF(EOD!E8="","",EOD!E8) | F17: =IF(EOD!G8="","",EOD!G8) | G17: =IF(EOD!H8="","",EOD!H8) | H17: =IF(EOD!I8="","",EOD!I8) | I17: =IFERROR(IF(F17<$K$10,(($K$10-F17-1)*((E17-H17)/G17)+(((E17-H17)/G17)/2)),0),0) -> 0 | J17: =IF($F17+$G17=J$10,($E17-$H17)/$G17/2,(IF($F17=J$10,($E17-$H17)/$G17/2,0))) -> #VALUE! | K17: =IFERROR(IF($F17+$G17=K$10,J17,(IF($F17=K$10,J17,(IF($F17>K$10," ",IF(K$10<$G17+$F17,SLN($E17,$H17,$G17)," "))))))," ") | L17: =IF($F17+$G17=L$10,($E17-$H17)/$G17/2,(IF($F17=L$10,($E17-$H17)/$G17/2,0))) -> #VALUE! | M17: =IFERROR(IF($F17+$G17=M$10,L17,(IF($F17=M$10,L17,(IF($F17>M$10," ",IF(M$10<$G17+$F17,SLN($E17,$H17,$G17)," "))))))," ") | N17: =IF($F17+$G17=N$10,($E17-$H17)/$G17/2,(IF($F17=N$10,($E17-$H17)/$G17/2,0))) -> #VALUE! | O17: =IFERROR(IF($F17+$G17=O$10,N17,(IF($F17=O$10,N17,(IF($F17>O$10," ",IF(O$10<$G17+$F17,SLN($E17,$H17,$G17)," "))))))," ") | P17: =IF($F17+$G17=P$10,($E17-$H17)/$G17/2,(IF($F17=P$10,($E17-$H17)/$G17/2,0))) -> #VALUE! | Q17: =IFERROR(IF($F17+$G17=Q$10,P17,(IF($F17=Q$10,P17,(IF($F17>Q$10," ",IF(Q$10<$G17+$F17,SLN($E17,$H17,$G17)," "))))))," ") | R17: =IF($F17+$G17=R$10,($E17-$H17)/$G17/2,(IF($F17=R$10,($E17-$H17)/$G17/2,0))) -> #VALUE! | S17: =IFERROR(IF($F17+$G17=S$10,R17,(IF($F17=S$10,R17,(IF($F17>S$10," ",IF(S$10<$G17+$F17,SLN($E17,$H17,$G17)," "))))))," ") | T17: =IF($F17+$G17=T$10,($E17-$H17)/$G17/2,(IF($F17=T$10,($E17-$H17)/$G17/2,0))) -> #VALUE! | U17: =IFERROR(IF($F17+$G17=U$10,T17,(IF($F17=U$10,T17,(IF($F17>U$10," ",IF(U$10<$G17+$F17,SLN($E17,$H17,$G17)," "))))))," ") | V17: =IF($F17+$G17=V$10,($E17-$H17)/$G17/2,(IF($F17=V$10,($E17-$H17)/$G17/2,0))) -> #VALUE! | W17: =IFERROR(IF($F17+$G17=W$10,V17,(IF($F17=W$10,V17,(IF($F17>W$10," ",IF(W$10<$G17+$F17,SLN($E17,$H17,$G17)," "))))))," ") | X17: =IF($F17+$G17=X$10,($E17-$H17)/$G17/2,(IF($F17=X$10,($E17-$H17)/$G17/2,0))) -> #VALUE! | Y17: =IFERROR(IF($F17+$G17=Y$10,X17,(IF($F17=Y$10,X17,(IF($F17>Y$10," ",IF(Y$10<$G17+$F17,SLN($E17,$H17,$G17)," "))))))," ") | Z17: =IF($F17+$G17=Z$10,($E17-$H17)/$G17/2,(IF($F17=Z$10,($E17-$H17)/$G17/2,0))) -> #VALUE! | AA17: =IFERROR(IF($F17+$G17=AA$10,Z17,(IF($F17=AA$10,Z17,(IF($F17>AA$10," ",IF(AA$10<$G17+$F17,SLN($E17,$H17,$G17)," "))))))," ") | AB17: =IF($F17+$G17=AB$10,($E17-$H17)/$G17/2,(IF($F17=AB$10,($E17-$H17)/$G17/2,0))) -> #VALUE! | AC17: =IFERROR(IF($F17+$G17=AC$10,AB17,(IF($F17=AC$10,AB17,(IF($F17>AC$10," ",IF(AC$10<$G17+$F17,SLN($E17,$H17,$G17)," "))))))," ") | AD17: =IF($F17+$G17=AD$10,($E17-$H17)/$G17/2,(IF($F17=AD$10,($E17-$H17)/$G17/2,0))) -> #VALUE! | AE17: =IFERROR(IF($F17+$G17=AE$10,AD17,(IF($F17=AE$10,AD17,(IF($F17>AE$10," ",IF(AE$10<$G17+$F17,SLN($E17,$H17,$G17)," "))))))," ") | AF17: =IF($F17+$G17=AF$10,($E17-$H17)/$G17/2,(IF($F17=AF$10,($E17-$H17)/$G17/2,0))) -> #VALUE! | AG17: =IFERROR(IF($F17+$G17=AG$10,AF17,(IF($F17=AG$10,AF17,(IF($F17>AG$10," ",IF(AG$10<$G17+$F17,SLN($E17,$H17,$G17)," "))))))," ") | AH17: =IF($F17+$G17=AH$10,($E17-$H17)/$G17/2,(IF($F17=AH$10,($E17-$H17)/$G17/2,0))) -> #VALUE! | AI17: =IFERROR(IF($F17+$G17=AI$10,AH17,(IF($F17=AI$10,AH17,(IF($F17>AI$10," ",IF(AI$10<$G17+$F17,SLN($E17,$H17,$G17)," "))))))," ") | AJ17: =IF($F17+$G17=AJ$10,($E17-$H17)/$G17/2,(IF($F17=AJ$10,($E17-$H17)/$G17/2,0))) -> #VALUE! | AK17: =IFERROR(IF($F17+$G17=AK$10,AJ17,(IF($F17=AK$10,AJ17,(IF($F17>AK$10," ",IF(AK$10<$G17+$F17,SLN($E17,$H17,$G17)," "))))))," ") | AL17: =IF($F17+$G17=AL$10,($E17-$H17)/$G17/2,(IF($F17=AL$10,($E17-$H17)/$G17/2,0))) -> #VALUE! | AM17: =IFERROR(IF($F17+$G17=AM$10,AL17,(IF($F17=AM$10,AL17,(IF($F17>AM$10," ",IF(AM$10<$G17+$F17,SLN($E17,$H17,$G17)," "))))))," ") | AN17: =IF($F17+$G17=AN$10,($E17-$H17)/$G17/2,(IF($F17=AN$10,($E17-$H17)/$G17/2,0))) -> #VALUE! | AO17: =IFERROR(IF($F17+$G17=AO$10,AN17,(IF($F17=AO$10,AN17,(IF($F17>AO$10," ",IF(AO$10<$G17+$F17,SLN($E17,$H17,$G17)," "))))))," ") | AP17: =IF($F17+$G17=AP$10,($E17-$H17)/$G17/2,(IF($F17=AP$10,($E17-$H17)/$G17/2,0))) -> #VALUE! | AQ17: =IFERROR(IF($F17+$G17=AQ$10,AP17,(IF($F17=AQ$10,AP17,(IF($F17>AQ$10," ",IF(AQ$10<$G17+$F17,SLN($E17,$H17,$G17)," "))))))," ") | AR17: =IF($F17+$G17=AR$10,($E17-$H17)/$G17/2,(IF($F17=AR$10,($E17-$H17)/$G17/2,0))) -> #VALUE! | AS17: =IFERROR(IF($F17+$G17=AS$10,AR17,(IF($F17=AS$10,AR17,(IF($F17>AS$10," ",IF(AS$10<$G17+$F17,SLN($E17,$H17,$G17)," "))))))," ") | AT17: =IF($F17+$G17=AT$10,($E17-$H17)/$G17/2,(IF($F17=AT$10,($E17-$H17)/$G17/2,0))) -> #VALUE! | AU17: =IFERROR(IF($F17+$G17=AU$10,AT17,(IF($F17=AU$10,AT17,(IF($F17>AU$10," ",IF(AU$10<$G17+$F17,SLN($E17,$H17,$G17)," "))))))," ") | AV17: =IF($F17+$G17=AV$10,($E17-$H17)/$G17/2,(IF($F17=AV$10,($E17-$H17)/$G17/2,0))) -> #VALUE! | AW17: =IFERROR(IF($F17+$G17=AW$10,AV17,(IF($F17=AW$10,AV17,(IF($F17>AW$10," ",IF(AW$10<$G17+$F17,SLN($E17,$H17,$G17)," "))))))," ") | AY17: =C17 | AZ17: =AY17 | BA17: =B17 | BB17: =D17 | BC17: =IF(BB17="","","Depreciation_Expense") | BD17: =INDEX($K$10:$BD$55, MATCH(BB17, $D$10:$D$55, 0), MATCH($H$4, $K$10:$BD$10, 1)) -> #N/A
A18: =IF(EOD!$F9="","",EOD!$F9) | B18: =IF(EOD!$C9="","",EOD!$C9) | C18: =IF(EOD!$A9="","",EOD!$A9) | D18: =IF(EOD!$D9="","",EOD!$D9) | E18: =IF(EOD!E9="","",EOD!E9) | F18: =IF(EOD!G9="","",EOD!G9) | G18: =IF(EOD!H9="","",EOD!H9) | H18: =IF(EOD!I9="","",EOD!I9) | I18: =IFERROR(IF(F18<$K$10,(($K$10-F18-1)*((E18-H18)/G18)+(((E18-H18)/G18)/2)),0),0) -> 0 | J18: =IF($F18+$G18=J$10,($E18-$H18)/$G18/2,(IF($F18=J$10,($E18-$H18)/$G18/2,0))) -> #VALUE! | K18: =IFERROR(IF($F18+$G18=K$10,J18,(IF($F18=K$10,J18,(IF($F18>K$10," ",IF(K$10<$G18+$F18,SLN($E18,$H18,$G18)," "))))))," ") | L18: =IF($F18+$G18=L$10,($E18-$H18)/$G18/2,(IF($F18=L$10,($E18-$H18)/$G18/2,0))) -> #VALUE! | M18: =IFERROR(IF($F18+$G18=M$10,L18,(IF($F18=M$10,L18,(IF($F18>M$10," ",IF(M$10<$G18+$F18,SLN($E18,$H18,$G18)," "))))))," ") | N18: =IF($F18+$G18=N$10,($E18-$H18)/$G18/2,(IF($F18=N$10,($E18-$H18)/$G18/2,0))) -> #VALUE! | O18: =IFERROR(IF($F18+$G18=O$10,N18,(IF($F18=O$10,N18,(IF($F18>O$10," ",IF(O$10<$G18+$F18,SLN($E18,$H18,$G18)," "))))))," ") | P18: =IF($F18+$G18=P$10,($E18-$H18)/$G18/2,(IF($F18=P$10,($E18-$H18)/$G18/2,0))) -> #VALUE! | Q18: =IFERROR(IF($F18+$G18=Q$10,P18,(IF($F18=Q$10,P18,(IF($F18>Q$10," ",IF(Q$10<$G18+$F18,SLN($E18,$H18,$G18)," "))))))," ") | R18: =IF($F18+$G18=R$10,($E18-$H18)/$G18/2,(IF($F18=R$10,($E18-$H18)/$G18/2,0))) -> #VALUE! | S18: =IFERROR(IF($F18+$G18=S$10,R18,(IF($F18=S$10,R18,(IF($F18>S$10," ",IF(S$10<$G18+$F18,SLN($E18,$H18,$G18)," "))))))," ") | T18: =IF($F18+$G18=T$10,($E18-$H18)/$G18/2,(IF($F18=T$10,($E18-$H18)/$G18/2,0))) -> #VALUE! | U18: =IFERROR(IF($F18+$G18=U$10,T18,(IF($F18=U$10,T18,(IF($F18>U$10," ",IF(U$10<$G18+$F18,SLN($E18,$H18,$G18)," "))))))," ") | V18: =IF($F18+$G18=V$10,($E18-$H18)/$G18/2,(IF($F18=V$10,($E18-$H18)/$G18/2,0))) -> #VALUE! | W18: =IFERROR(IF($F18+$G18=W$10,V18,(IF($F18=W$10,V18,(IF($F18>W$10," ",IF(W$10<$G18+$F18,SLN($E18,$H18,$G18)," "))))))," ") | X18: =IF($F18+$G18=X$10,($E18-$H18)/$G18/2,(IF($F18=X$10,($E18-$H18)/$G18/2,0))) -> #VALUE! | Y18: =IFERROR(IF($F18+$G18=Y$10,X18,(IF($F18=Y$10,X18,(IF($F18>Y$10," ",IF(Y$10<$G18+$F18,SLN($E18,$H18,$G18)," "))))))," ") | Z18: =IF($F18+$G18=Z$10,($E18-$H18)/$G18/2,(IF($F18=Z$10,($E18-$H18)/$G18/2,0))) -> #VALUE! | AA18: =IFERROR(IF($F18+$G18=AA$10,Z18,(IF($F18=AA$10,Z18,(IF($F18>AA$10," ",IF(AA$10<$G18+$F18,SLN($E18,$H18,$G18)," "))))))," ") | AB18: =IF($F18+$G18=AB$10,($E18-$H18)/$G18/2,(IF($F18=AB$10,($E18-$H18)/$G18/2,0))) -> #VALUE! | AC18: =IFERROR(IF($F18+$G18=AC$10,AB18,(IF($F18=AC$10,AB18,(IF($F18>AC$10," ",IF(AC$10<$G18+$F18,SLN($E18,$H18,$G18)," "))))))," ") | AD18: =IF($F18+$G18=AD$10,($E18-$H18)/$G18/2,(IF($F18=AD$10,($E18-$H18)/$G18/2,0))) -> #VALUE! | AE18: =IFERROR(IF($F18+$G18=AE$10,AD18,(IF($F18=AE$10,AD18,(IF($F18>AE$10," ",IF(AE$10<$G18+$F18,SLN($E18,$H18,$G18)," "))))))," ") | AF18: =IF($F18+$G18=AF$10,($E18-$H18)/$G18/2,(IF($F18=AF$10,($E18-$H18)/$G18/2,0))) -> #VALUE! | AG18: =IFERROR(IF($F18+$G18=AG$10,AF18,(IF($F18=AG$10,AF18,(IF($F18>AG$10," ",IF(AG$10<$G18+$F18,SLN($E18,$H18,$G18)," "))))))," ") | AH18: =IF($F18+$G18=AH$10,($E18-$H18)/$G18/2,(IF($F18=AH$10,($E18-$H18)/$G18/2,0))) -> #VALUE! | AI18: =IFERROR(IF($F18+$G18=AI$10,AH18,(IF($F18=AI$10,AH18,(IF($F18>AI$10," ",IF(AI$10<$G18+$F18,SLN($E18,$H18,$G18)," "))))))," ") | AJ18: =IF($F18+$G18=AJ$10,($E18-$H18)/$G18/2,(IF($F18=AJ$10,($E18-$H18)/$G18/2,0))) -> #VALUE! | AK18: =IFERROR(IF($F18+$G18=AK$10,AJ18,(IF($F18=AK$10,AJ18,(IF($F18>AK$10," ",IF(AK$10<$G18+$F18,SLN($E18,$H18,$G18)," "))))))," ") | AL18: =IF($F18+$G18=AL$10,($E18-$H18)/$G18/2,(IF($F18=AL$10,($E18-$H18)/$G18/2,0))) -> #VALUE! | AM18: =IFERROR(IF($F18+$G18=AM$10,AL18,(IF($F18=AM$10,AL18,(IF($F18>AM$10," ",IF(AM$10<$G18+$F18,SLN($E18,$H18,$G18)," "))))))," ") | AN18: =IF($F18+$G18=AN$10,($E18-$H18)/$G18/2,(IF($F18=AN$10,($E18-$H18)/$G18/2,0))) -> #VALUE! | AO18: =IFERROR(IF($F18+$G18=AO$10,AN18,(IF($F18=AO$10,AN18,(IF($F18>AO$10," ",IF(AO$10<$G18+$F18,SLN($E18,$H18,$G18)," "))))))," ") | AP18: =IF($F18+$G18=AP$10,($E18-$H18)/$G18/2,(IF($F18=AP$10,($E18-$H18)/$G18/2,0))) -> #VALUE! | AQ18: =IFERROR(IF($F18+$G18=AQ$10,AP18,(IF($F18=AQ$10,AP18,(IF($F18>AQ$10," ",IF(AQ$10<$G18+$F18,SLN($E18,$H18,$G18)," "))))))," ") | AR18: =IF($F18+$G18=AR$10,($E18-$H18)/$G18/2,(IF($F18=AR$10,($E18-$H18)/$G18/2,0))) -> #VALUE! | AS18: =IFERROR(IF($F18+$G18=AS$10,AR18,(IF($F18=AS$10,AR18,(IF($F18>AS$10," ",IF(AS$10<$G18+$F18,SLN($E18,$H18,$G18)," "))))))," ") | AT18: =IF($F18+$G18=AT$10,($E18-$H18)/$G18/2,(IF($F18=AT$10,($E18-$H18)/$G18/2,0))) -> #VALUE! | AU18: =IFERROR(IF($F18+$G18=AU$10,AT18,(IF($F18=AU$10,AT18,(IF($F18>AU$10," ",IF(AU$10<$G18+$F18,SLN($E18,$H18,$G18)," "))))))," ") | AV18: =IF($F18+$G18=AV$10,($E18-$H18)/$G18/2,(IF($F18=AV$10,($E18-$H18)/$G18/2,0))) -> #VALUE! | AW18: =IFERROR(IF($F18+$G18=AW$10,AV18,(IF($F18=AW$10,AV18,(IF($F18>AW$10," ",IF(AW$10<$G18+$F18,SLN($E18,$H18,$G18)," "))))))," ") | AY18: =C18 | AZ18: =AY18 | BA18: =B18 | BB18: =D18 | BC18: =IF(BB18="","","Depreciation_Expense") | BD18: =INDEX($K$10:$BD$55, MATCH(BB18, $D$10:$D$55, 0), MATCH($H$4, $K$10:$BD$10, 1)) -> #N/A
A19: =IF(EOD!$F10="","",EOD!$F10) | B19: =IF(EOD!$C10="","",EOD!$C10) | C19: =IF(EOD!$A10="","",EOD!$A10) | D19: =IF(EOD!$D10="","",EOD!$D10) | E19: =IF(EOD!E10="","",EOD!E10) | F19: =IF(EOD!G10="","",EOD!G10) | G19: =IF(EOD!H10="","",EOD!H10) | H19: =IF(EOD!I10="","",EOD!I10) | I19: =IFERROR(IF(F19<$K$10,(($K$10-F19-1)*((E19-H19)/G19)+(((E19-H19)/G19)/2)),0),0) -> 0 | J19: =IF($F19+$G19=J$10,($E19-$H19)/$G19/2,(IF($F19=J$10,($E19-$H19)/$G19/2,0))) -> #VALUE! | K19: =IFERROR(IF($F19+$G19=K$10,J19,(IF($F19=K$10,J19,(IF($F19>K$10," ",IF(K$10<$G19+$F19,SLN($E19,$H19,$G19)," "))))))," ") | L19: =IF($F19+$G19=L$10,($E19-$H19)/$G19/2,(IF($F19=L$10,($E19-$H19)/$G19/2,0))) -> #VALUE! | M19: =IFERROR(IF($F19+$G19=M$10,L19,(IF($F19=M$10,L19,(IF($F19>M$10," ",IF(M$10<$G19+$F19,SLN($E19,$H19,$G19)," "))))))," ") | N19: =IF($F19+$G19=N$10,($E19-$H19)/$G19/2,(IF($F19=N$10,($E19-$H19)/$G19/2,0))) -> #VALUE! | O19: =IFERROR(IF($F19+$G19=O$10,N19,(IF($F19=O$10,N19,(IF($F19>O$10," ",IF(O$10<$G19+$F19,SLN($E19,$H19,$G19)," "))))))," ") | P19: =IF($F19+$G19=P$10,($E19-$H19)/$G19/2,(IF($F19=P$10,($E19-$H19)/$G19/2,0))) -> #VALUE! | Q19: =IFERROR(IF($F19+$G19=Q$10,P19,(IF($F19=Q$10,P19,(IF($F19>Q$10," ",IF(Q$10<$G19+$F19,SLN($E19,$H19,$G19)," "))))))," ") | R19: =IF($F19+$G19=R$10,($E19-$H19)/$G19/2,(IF($F19=R$10,($E19-$H19)/$G19/2,0))) -> #VALUE! | S19: =IFERROR(IF($F19+$G19=S$10,R19,(IF($F19=S$10,R19,(IF($F19>S$10," ",IF(S$10<$G19+$F19,SLN($E19,$H19,$G19)," "))))))," ") | T19: =IF($F19+$G19=T$10,($E19-$H19)/$G19/2,(IF($F19=T$10,($E19-$H19)/$G19/2,0))) -> #VALUE! | U19: =IFERROR(IF($F19+$G19=U$10,T19,(IF($F19=U$10,T19,(IF($F19>U$10," ",IF(U$10<$G19+$F19,SLN($E19,$H19,$G19)," "))))))," ") | V19: =IF($F19+$G19=V$10,($E19-$H19)/$G19/2,(IF($F19=V$10,($E19-$H19)/$G19/2,0))) -> #VALUE! | W19: =IFERROR(IF($F19+$G19=W$10,V19,(IF($F19=W$10,V19,(IF($F19>W$10," ",IF(W$10<$G19+$F19,SLN($E19,$H19,$G19)," "))))))," ") | X19: =IF($F19+$G19=X$10,($E19-$H19)/$G19/2,(IF($F19=X$10,($E19-$H19)/$G19/2,0))) -> #VALUE! | Y19: =IFERROR(IF($F19+$G19=Y$10,X19,(IF($F19=Y$10,X19,(IF($F19>Y$10," ",IF(Y$10<$G19+$F19,SLN($E19,$H19,$G19)," "))))))," ") | Z19: =IF($F19+$G19=Z$10,($E19-$H19)/$G19/2,(IF($F19=Z$10,($E19-$H19)/$G19/2,0))) -> #VALUE! | AA19: =IFERROR(IF($F19+$G19=AA$10,Z19,(IF($F19=AA$10,Z19,(IF($F19>AA$10," ",IF(AA$10<$G19+$F19,SLN($E19,$H19,$G19)," "))))))," ") | AB19: =IF($F19+$G19=AB$10,($E19-$H19)/$G19/2,(IF($F19=AB$10,($E19-$H19)/$G19/2,0))) -> #VALUE! | AC19: =IFERROR(IF($F19+$G19=AC$10,AB19,(IF($F19=AC$10,AB19,(IF($F19>AC$10," ",IF(AC$10<$G19+$F19,SLN($E19,$H19,$G19)," "))))))," ") | AD19: =IF($F19+$G19=AD$10,($E19-$H19)/$G19/2,(IF($F19=AD$10,($E19-$H19)/$G19/2,0))) -> #VALUE! | AE19: =IFERROR(IF($F19+$G19=AE$10,AD19,(IF($F19=AE$10,AD19,(IF($F19>AE$10," ",IF(AE$10<$G19+$F19,SLN($E19,$H19,$G19)," "))))))," ") | AF19: =IF($F19+$G19=AF$10,($E19-$H19)/$G19/2,(IF($F19=AF$10,($E19-$H19)/$G19/2,0))) -> #VALUE! | AG19: =IFERROR(IF($F19+$G19=AG$10,AF19,(IF($F19=AG$10,AF19,(IF($F19>AG$10," ",IF(AG$10<$G19+$F19,SLN($E19,$H19,$G19)," "))))))," ") | AH19: =IF($F19+$G19=AH$10,($E19-$H19)/$G19/2,(IF($F19=AH$10,($E19-$H19)/$G19/2,0))) -> #VALUE! | AI19: =IFERROR(IF($F19+$G19=AI$10,AH19,(IF($F19=AI$10,AH19,(IF($F19>AI$10," ",IF(AI$10<$G19+$F19,SLN($E19,$H19,$G19)," "))))))," ") | AJ19: =IF($F19+$G19=AJ$10,($E19-$H19)/$G19/2,(IF($F19=AJ$10,($E19-$H19)/$G19/2,0))) -> #VALUE! | AK19: =IFERROR(IF($F19+$G19=AK$10,AJ19,(IF($F19=AK$10,AJ19,(IF($F19>AK$10," ",IF(AK$10<$G19+$F19,SLN($E19,$H19,$G19)," "))))))," ") | AL19: =IF($F19+$G19=AL$10,($E19-$H19)/$G19/2,(IF($F19=AL$10,($E19-$H19)/$G19/2,0))) -> #VALUE! | AM19: =IFERROR(IF($F19+$G19=AM$10,AL19,(IF($F19=AM$10,AL19,(IF($F19>AM$10," ",IF(AM$10<$G19+$F19,SLN($E19,$H19,$G19)," "))))))," ") | AN19: =IF($F19+$G19=AN$10,($E19-$H19)/$G19/2,(IF($F19=AN$10,($E19-$H19)/$G19/2,0))) -> #VALUE! | AO19: =IFERROR(IF($F19+$G19=AO$10,AN19,(IF($F19=AO$10,AN19,(IF($F19>AO$10," ",IF(AO$10<$G19+$F19,SLN($E19,$H19,$G19)," "))))))," ") | AP19: =IF($F19+$G19=AP$10,($E19-$H19)/$G19/2,(IF($F19=AP$10,($E19-$H19)/$G19/2,0))) -> #VALUE! | AQ19: =IFERROR(IF($F19+$G19=AQ$10,AP19,(IF($F19=AQ$10,AP19,(IF($F19>AQ$10," ",IF(AQ$10<$G19+$F19,SLN($E19,$H19,$G19)," "))))))," ") | AR19: =IF($F19+$G19=AR$10,($E19-$H19)/$G19/2,(IF($F19=AR$10,($E19-$H19)/$G19/2,0))) -> #VALUE! | AS19: =IFERROR(IF($F19+$G19=AS$10,AR19,(IF($F19=AS$10,AR19,(IF($F19>AS$10," ",IF(AS$10<$G19+$F19,SLN($E19,$H19,$G19)," "))))))," ") | AT19: =IF($F19+$G19=AT$10,($E19-$H19)/$G19/2,(IF($F19=AT$10,($E19-$H19)/$G19/2,0))) -> #VALUE! | AU19: =IFERROR(IF($F19+$G19=AU$10,AT19,(IF($F19=AU$10,AT19,(IF($F19>AU$10," ",IF(AU$10<$G19+$F19,SLN($E19,$H19,$G19)," "))))))," ") | AV19: =IF($F19+$G19=AV$10,($E19-$H19)/$G19/2,(IF($F19=AV$10,($E19-$H19)/$G19/2,0))) -> #VALUE! | AW19: =IFERROR(IF($F19+$G19=AW$10,AV19,(IF($F19=AW$10,AV19,(IF($F19>AW$10," ",IF(AW$10<$G19+$F19,SLN($E19,$H19,$G19)," "))))))," ") | AY19: =C19 | AZ19: =AY19 | BA19: =B19 | BB19: =D19 | BC19: =IF(BB19="","","Depreciation_Expense") | BD19: =INDEX($K$10:$BD$55, MATCH(BB19, $D$10:$D$55, 0), MATCH($H$4, $K$10:$BD$10, 1)) -> #N/A
A20: =IF(EOD!$F11="","",EOD!$F11) | B20: =IF(EOD!$C11="","",EOD!$C11) | C20: =IF(EOD!$A11="","",EOD!$A11) | D20: =IF(EOD!$D11="","",EOD!$D11) | E20: =IF(EOD!E11="","",EOD!E11) | F20: =IF(EOD!G11="","",EOD!G11) | G20: =IF(EOD!H11="","",EOD!H11) | H20: =IF(EOD!I11="","",EOD!I11) | I20: =IFERROR(IF(F20<$K$10,(($K$10-F20-1)*((E20-H20)/G20)+(((E20-H20)/G20)/2)),0),0) -> 0 | J20: =IF($F20+$G20=J$10,($E20-$H20)/$G20/2,(IF($F20=J$10,($E20-$H20)/$G20/2,0))) -> #VALUE! | K20: =IFERROR(IF($F20+$G20=K$10,J20,(IF($F20=K$10,J20,(IF($F20>K$10," ",IF(K$10<$G20+$F20,SLN($E20,$H20,$G20)," "))))))," ") | L20: =IF($F20+$G20=L$10,($E20-$H20)/$G20/2,(IF($F20=L$10,($E20-$H20)/$G20/2,0))) -> #VALUE! | M20: =IFERROR(IF($F20+$G20=M$10,L20,(IF($F20=M$10,L20,(IF($F20>M$10," ",IF(M$10<$G20+$F20,SLN($E20,$H20,$G20)," "))))))," ") | N20: =IF($F20+$G20=N$10,($E20-$H20)/$G20/2,(IF($F20=N$10,($E20-$H20)/$G20/2,0))) -> #VALUE! | O20: =IFERROR(IF($F20+$G20=O$10,N20,(IF($F20=O$10,N20,(IF($F20>O$10," ",IF(O$10<$G20+$F20,SLN($E20,$H20,$G20)," "))))))," ") | P20: =IF($F20+$G20=P$10,($E20-$H20)/$G20/2,(IF($F20=P$10,($E20-$H20)/$G20/2,0))) -> #VALUE! | Q20: =IFERROR(IF($F20+$G20=Q$10,P20,(IF($F20=Q$10,P20,(IF($F20>Q$10," ",IF(Q$10<$G20+$F20,SLN($E20,$H20,$G20)," "))))))," ") | R20: =IF($F20+$G20=R$10,($E20-$H20)/$G20/2,(IF($F20=R$10,($E20-$H20)/$G20/2,0))) -> #VALUE! | S20: =IFERROR(IF($F20+$G20=S$10,R20,(IF($F20=S$10,R20,(IF($F20>S$10," ",IF(S$10<$G20+$F20,SLN($E20,$H20,$G20)," "))))))," ") | T20: =IF($F20+$G20=T$10,($E20-$H20)/$G20/2,(IF($F20=T$10,($E20-$H20)/$G20/2,0))) -> #VALUE! | U20: =IFERROR(IF($F20+$G20=U$10,T20,(IF($F20=U$10,T20,(IF($F20>U$10," ",IF(U$10<$G20+$F20,SLN($E20,$H20,$G20)," "))))))," ") | V20: =IF($F20+$G20=V$10,($E20-$H20)/$G20/2,(IF($F20=V$10,($E20-$H20)/$G20/2,0))) -> #VALUE! | W20: =IFERROR(IF($F20+$G20=W$10,V20,(IF($F20=W$10,V20,(IF($F20>W$10," ",IF(W$10<$G20+$F20,SLN($E20,$H20,$G20)," "))))))," ") | X20: =IF($F20+$G20=X$10,($E20-$H20)/$G20/2,(IF($F20=X$10,($E20-$H20)/$G20/2,0))) -> #VALUE! | Y20: =IFERROR(IF($F20+$G20=Y$10,X20,(IF($F20=Y$10,X20,(IF($F20>Y$10," ",IF(Y$10<$G20+$F20,SLN($E20,$H20,$G20)," "))))))," ") | Z20: =IF($F20+$G20=Z$10,($E20-$H20)/$G20/2,(IF($F20=Z$10,($E20-$H20)/$G20/2,0))) -> #VALUE! | AA20: =IFERROR(IF($F20+$G20=AA$10,Z20,(IF($F20=AA$10,Z20,(IF($F20>AA$10," ",IF(AA$10<$G20+$F20,SLN($E20,$H20,$G20)," "))))))," ") | AB20: =IF($F20+$G20=AB$10,($E20-$H20)/$G20/2,(IF($F20=AB$10,($E20-$H20)/$G20/2,0))) -> #VALUE! | AC20: =IFERROR(IF($F20+$G20=AC$10,AB20,(IF($F20=AC$10,AB20,(IF($F20>AC$10," ",IF(AC$10<$G20+$F20,SLN($E20,$H20,$G20)," "))))))," ") | AD20: =IF($F20+$G20=AD$10,($E20-$H20)/$G20/2,(IF($F20=AD$10,($E20-$H20)/$G20/2,0))) -> #VALUE! | AE20: =IFERROR(IF($F20+$G20=AE$10,AD20,(IF($F20=AE$10,AD20,(IF($F20>AE$10," ",IF(AE$10<$G20+$F20,SLN($E20,$H20,$G20)," "))))))," ") | AF20: =IF($F20+$G20=AF$10,($E20-$H20)/$G20/2,(IF($F20=AF$10,($E20-$H20)/$G20/2,0))) -> #VALUE! | AG20: =IFERROR(IF($F20+$G20=AG$10,AF20,(IF($F20=AG$10,AF20,(IF($F20>AG$10," ",IF(AG$10<$G20+$F20,SLN($E20,$H20,$G20)," "))))))," ") | AH20: =IF($F20+$G20=AH$10,($E20-$H20)/$G20/2,(IF($F20=AH$10,($E20-$H20)/$G20/2,0))) -> #VALUE! | AI20: =IFERROR(IF($F20+$G20=AI$10,AH20,(IF($F20=AI$10,AH20,(IF($F20>AI$10," ",IF(AI$10<$G20+$F20,SLN($E20,$H20,$G20)," "))))))," ") | AJ20: =IF($F20+$G20=AJ$10,($E20-$H20)/$G20/2,(IF($F20=AJ$10,($E20-$H20)/$G20/2,0))) -> #VALUE! | AK20: =IFERROR(IF($F20+$G20=AK$10,AJ20,(IF($F20=AK$10,AJ20,(IF($F20>AK$10," ",IF(AK$10<$G20+$F20,SLN($E20,$H20,$G20)," "))))))," ") | AL20: =IF($F20+$G20=AL$10,($E20-$H20)/$G20/2,(IF($F20=AL$10,($E20-$H20)/$G20/2,0))) -> #VALUE! | AM20: =IFERROR(IF($F20+$G20=AM$10,AL20,(IF($F20=AM$10,AL20,(IF($F20>AM$10," ",IF(AM$10<$G20+$F20,SLN($E20,$H20,$G20)," "))))))," ") | AN20: =IF($F20+$G20=AN$10,($E20-$H20)/$G20/2,(IF($F20=AN$10,($E20-$H20)/$G20/2,0))) -> #VALUE! | AO20: =IFERROR(IF($F20+$G20=AO$10,AN20,(IF($F20=AO$10,AN20,(IF($F20>AO$10," ",IF(AO$10<$G20+$F20,SLN($E20,$H20,$G20)," "))))))," ") | AP20: =IF($F20+$G20=AP$10,($E20-$H20)/$G20/2,(IF($F20=AP$10,($E20-$H20)/$G20/2,0))) -> #VALUE! | AQ20: =IFERROR(IF($F20+$G20=AQ$10,AP20,(IF($F20=AQ$10,AP20,(IF($F20>AQ$10," ",IF(AQ$10<$G20+$F20,SLN($E20,$H20,$G20)," "))))))," ") | AR20: =IF($F20+$G20=AR$10,($E20-$H20)/$G20/2,(IF($F20=AR$10,($E20-$H20)/$G20/2,0))) -> #VALUE! | AS20: =IFERROR(IF($F20+$G20=AS$10,AR20,(IF($F20=AS$10,AR20,(IF($F20>AS$10," ",IF(AS$10<$G20+$F20,SLN($E20,$H20,$G20)," "))))))," ") | AT20: =IF($F20+$G20=AT$10,($E20-$H20)/$G20/2,(IF($F20=AT$10,($E20-$H20)/$G20/2,0))) -> #VALUE! | AU20: =IFERROR(IF($F20+$G20=AU$10,AT20,(IF($F20=AU$10,AT20,(IF($F20>AU$10," ",IF(AU$10<$G20+$F20,SLN($E20,$H20,$G20)," "))))))," ") | AV20: =IF($F20+$G20=AV$10,($E20-$H20)/$G20/2,(IF($F20=AV$10,($E20-$H20)/$G20/2,0))) -> #VALUE! | AW20: =IFERROR(IF($F20+$G20=AW$10,AV20,(IF($F20=AW$10,AV20,(IF($F20>AW$10," ",IF(AW$10<$G20+$F20,SLN($E20,$H20,$G20)," "))))))," ") | AY20: =C20 | AZ20: =AY20 | BA20: =B20 | BB20: =D20 | BC20: =IF(BB20="","","Depreciation_Expense") | BD20: =INDEX($K$10:$BD$55, MATCH(BB20, $D$10:$D$55, 0), MATCH($H$4, $K$10:$BD$10, 1)) -> #N/A
